INFO:     Will watch for changes in these directories: ['/workspace/EpiAPI']
INFO:     Uvicorn running on https://10.9.1.108:8000 (Press CTRL+C to quit)
INFO:     Started reloader process [20481] using statreload
ERROR:    Error loading ASGI app. Could not import module "mytest".
INFO:     Stopping reloader process [20481]
INFO:     Will watch for changes in these directories: ['/workspace/EpiAPI']
INFO:     Uvicorn running on https://10.9.1.108:8000 (Press CTRL+C to quit)
INFO:     Started reloader process [20570] using statreload
2022-05-24 19:18:28.426 WARNING tensorflow: SavedModel saved prior to TF 2.5 detected when loading Keras model. Please ensure that you are saving the model with model.save() or tf.keras.models.save_model(), *NOT* tf.saved_model.save(). To confirm, there should be a file named "keras_metadata.pb" in the SavedModel directory.
INFO:     Started server process [20572]
2022-05-24 19:18:42.793 INFO    uvicorn.error: Started server process [20572]
INFO:     Waiting for application startup.
2022-05-24 19:18:42.794 INFO    uvicorn.error: Waiting for application startup.
INFO:     Application startup complete.
2022-05-24 19:18:42.794 INFO    uvicorn.error: Application startup complete.
INFO:     47.219.194.90:57992 - "GET /docs HTTP/1.1" 200 OK
INFO:     47.219.194.90:57992 - "GET /openapi.json HTTP/1.1" 200 OK
INFO:     47.219.194.90:57996 - "GET /openapi.json HTTP/1.1" 200 OK
INFO:     47.219.194.90:57996 - "GET /favicon.ico HTTP/1.1" 404 Not Found
INFO:     Will watch for changes in these directories: ['/workspace/EpiAPI']
INFO:     Uvicorn running on https://10.9.1.108:8000 (Press CTRL+C to quit)
INFO:     Started reloader process [17253] using statreload
2022-05-25 16:24:47.923 WARNING tensorflow: SavedModel saved prior to TF 2.5 detected when loading Keras model. Please ensure that you are saving the model with model.save() or tf.keras.models.save_model(), *NOT* tf.saved_model.save(). To confirm, there should be a file named "keras_metadata.pb" in the SavedModel directory.
INFO:     Started server process [17256]
2022-05-25 16:25:01.465 INFO    uvicorn.error: Started server process [17256]
INFO:     Waiting for application startup.
2022-05-25 16:25:01.465 INFO    uvicorn.error: Waiting for application startup.
INFO:     Application startup complete.
2022-05-25 16:25:01.465 INFO    uvicorn.error: Application startup complete.
INFO:     47.219.194.90:60418 - "GET /docs HTTP/1.1" 200 OK
INFO:     47.219.194.90:60418 - "GET /openapi.json HTTP/1.1" 200 OK
INFO:     47.219.194.90:60461 - "GET /redoc HTTP/1.1" 200 OK
INFO:     47.219.194.90:60461 - "GET /openapi.json HTTP/1.1" 200 OK
INFO:     47.219.194.90:60463 - "GET /openapi.json HTTP/1.1" 200 OK
INFO:     3.89.112.196:58082 - "GET /redoc HTTP/1.1" 200 OK
INFO:     44.203.171.17:37106 - "GET /docs HTTP/1.1" 200 OK
INFO:     47.219.194.90:60500 - "GET /docs HTTP/1.1" 200 OK
INFO:     47.219.194.90:60500 - "GET /openapi.json HTTP/1.1" 200 OK
INFO:     69.250.73.75:62758 - "GET /redoc HTTP/1.1" 200 OK
INFO:     69.250.73.75:62758 - "GET /openapi.json HTTP/1.1" 200 OK
INFO:     69.250.73.75:62757 - "GET /docs HTTP/1.1" 200 OK
INFO:     69.250.73.75:62757 - "GET /openapi.json HTTP/1.1" 200 OK
INFO:     69.250.73.75:62809 - "GET /redoc HTTP/1.1" 200 OK
INFO:     69.250.73.75:62809 - "GET /openapi.json HTTP/1.1" 200 OK
INFO:     68.77.56.191:61345 - "GET /docs HTTP/1.1" 200 OK
INFO:     68.77.56.191:61345 - "GET /openapi.json HTTP/1.1" 200 OK
INFO:     75.109.198.221:60810 - "GET /docs HTTP/1.1" 200 OK
INFO:     75.109.198.221:60810 - "GET /openapi.json HTTP/1.1" 200 OK
INFO:     75.109.198.221:60845 - "GET /docs HTTP/1.1" 200 OK
INFO:     75.109.198.221:60845 - "GET /openapi.json HTTP/1.1" 200 OK
INFO:     75.109.198.221:60859 - "GET /docs HTTP/1.1" 200 OK
INFO:     75.109.198.221:60859 - "GET /openapi.json HTTP/1.1" 200 OK
INFO:     68.77.56.191:61903 - "GET /redoc HTTP/1.1" 200 OK
INFO:     68.77.56.191:61903 - "GET /openapi.json HTTP/1.1" 200 OK
INFO:     68.77.56.191:61904 - "GET /docs HTTP/1.1" 200 OK
INFO:     68.77.56.191:61904 - "GET /openapi.json HTTP/1.1" 200 OK
SEARCH TERM DID NOT MATCH TO GARD DICTIONARY. SEARCHING BY USER INPUT
Found 34 PMIDs. Gathered 0 Relevant Abstracts.
INFO:     68.77.56.191:61924 - "GET /getAbsRD/term%3Dfullen%20syndrome?max_results=50&filtering=strict HTTP/1.1" 200 OK
SEARCH TERM MATCHED TO GARD DICTIONARY. SEARCHING FOR:  ['growth restriction-aminoaciduria-cholestasis-iron overload-lactic acidosis-early death syndrome', 'growth retardation, aminoaciduria, cholestasis, iron overload, lactic acidosis and early death', 'growth delay-aminoaciduria-cholestasis-iron overload-lactic acidosis-early death syndrome', 'finnish lactic acidosis with hepatic hemosiderosis', 'finnish lethal neonatal metabolic syndrome', 'gracile syndrome', 'fellman syndrome', 'fellman disease']
Found 50 PMIDs. Gathered 11 Relevant Abstracts.
INFO:     68.77.56.191:61942 - "GET /getAbsRD/term%3Dfellman%20syndrome?max_results=50&filtering=strict HTTP/1.1" 200 OK
INFO:     68.77.56.191:61947 - "GET /getEpiAbsRD/term%3Dfellman%20syndrome?max_results=50&filtering=strict HTTP/1.1" 500 Internal Server Error
ERROR:    Exception in ASGI application
Traceback (most recent call last):
  File "/home/wzkariampuzha/anaconda3/envs/fastapi/lib/python3.6/site-packages/uvicorn/protocols/http/h11_impl.py", line 373, in run_asgi
    result = await app(self.scope, self.receive, self.send)
  File "/home/wzkariampuzha/anaconda3/envs/fastapi/lib/python3.6/site-packages/uvicorn/middleware/proxy_headers.py", line 75, in __call__
    return await self.app(scope, receive, send)
  File "/home/wzkariampuzha/anaconda3/envs/fastapi/lib/python3.6/site-packages/fastapi/applications.py", line 269, in __call__
    await super().__call__(scope, receive, send)
  File "/home/wzkariampuzha/anaconda3/envs/fastapi/lib/python3.6/site-packages/starlette/applications.py", line 124, in __call__
    await self.middleware_stack(scope, receive, send)
  File "/home/wzkariampuzha/anaconda3/envs/fastapi/lib/python3.6/site-packages/starlette/middleware/errors.py", line 184, in __call__
    raise exc
  File "/home/wzkariampuzha/anaconda3/envs/fastapi/lib/python3.6/site-packages/starlette/middleware/errors.py", line 162, in __call__
    await self.app(scope, receive, _send)
  File "/home/wzkariampuzha/anaconda3/envs/fastapi/lib/python3.6/site-packages/starlette/exceptions.py", line 93, in __call__
    raise exc
  File "/home/wzkariampuzha/anaconda3/envs/fastapi/lib/python3.6/site-packages/starlette/exceptions.py", line 82, in __call__
    await self.app(scope, receive, sender)
  File "/home/wzkariampuzha/anaconda3/envs/fastapi/lib/python3.6/site-packages/fastapi/middleware/asyncexitstack.py", line 21, in __call__
    raise e
  File "/home/wzkariampuzha/anaconda3/envs/fastapi/lib/python3.6/site-packages/fastapi/middleware/asyncexitstack.py", line 18, in __call__
    await self.app(scope, receive, send)
  File "/home/wzkariampuzha/anaconda3/envs/fastapi/lib/python3.6/site-packages/starlette/routing.py", line 670, in __call__
    await route.handle(scope, receive, send)
  File "/home/wzkariampuzha/anaconda3/envs/fastapi/lib/python3.6/site-packages/starlette/routing.py", line 266, in handle
    await self.app(scope, receive, send)
  File "/home/wzkariampuzha/anaconda3/envs/fastapi/lib/python3.6/site-packages/starlette/routing.py", line 65, in app
    response = await func(request)
  File "/home/wzkariampuzha/anaconda3/envs/fastapi/lib/python3.6/site-packages/fastapi/routing.py", line 228, in app
    dependant=dependant, values=values, is_coroutine=is_coroutine
  File "/home/wzkariampuzha/anaconda3/envs/fastapi/lib/python3.6/site-packages/fastapi/routing.py", line 160, in run_endpoint_function
    return await dependant.call(**values)
  File "./app.py", line 246, in get_rare_disease_epidemiology_abstracts
    return API_search_classification(search_term, maxResults, filtering, GARD_Search, epi_classify)
NameError: name 'maxResults' is not defined
2022-05-25 18:38:39.399 ERROR   uvicorn.error: Exception in ASGI application
Traceback (most recent call last):
  File "/home/wzkariampuzha/anaconda3/envs/fastapi/lib/python3.6/site-packages/uvicorn/protocols/http/h11_impl.py", line 373, in run_asgi
    result = await app(self.scope, self.receive, self.send)
  File "/home/wzkariampuzha/anaconda3/envs/fastapi/lib/python3.6/site-packages/uvicorn/middleware/proxy_headers.py", line 75, in __call__
    return await self.app(scope, receive, send)
  File "/home/wzkariampuzha/anaconda3/envs/fastapi/lib/python3.6/site-packages/fastapi/applications.py", line 269, in __call__
    await super().__call__(scope, receive, send)
  File "/home/wzkariampuzha/anaconda3/envs/fastapi/lib/python3.6/site-packages/starlette/applications.py", line 124, in __call__
    await self.middleware_stack(scope, receive, send)
  File "/home/wzkariampuzha/anaconda3/envs/fastapi/lib/python3.6/site-packages/starlette/middleware/errors.py", line 184, in __call__
    raise exc
  File "/home/wzkariampuzha/anaconda3/envs/fastapi/lib/python3.6/site-packages/starlette/middleware/errors.py", line 162, in __call__
    await self.app(scope, receive, _send)
  File "/home/wzkariampuzha/anaconda3/envs/fastapi/lib/python3.6/site-packages/starlette/exceptions.py", line 93, in __call__
    raise exc
  File "/home/wzkariampuzha/anaconda3/envs/fastapi/lib/python3.6/site-packages/starlette/exceptions.py", line 82, in __call__
    await self.app(scope, receive, sender)
  File "/home/wzkariampuzha/anaconda3/envs/fastapi/lib/python3.6/site-packages/fastapi/middleware/asyncexitstack.py", line 21, in __call__
    raise e
  File "/home/wzkariampuzha/anaconda3/envs/fastapi/lib/python3.6/site-packages/fastapi/middleware/asyncexitstack.py", line 18, in __call__
    await self.app(scope, receive, send)
  File "/home/wzkariampuzha/anaconda3/envs/fastapi/lib/python3.6/site-packages/starlette/routing.py", line 670, in __call__
    await route.handle(scope, receive, send)
  File "/home/wzkariampuzha/anaconda3/envs/fastapi/lib/python3.6/site-packages/starlette/routing.py", line 266, in handle
    await self.app(scope, receive, send)
  File "/home/wzkariampuzha/anaconda3/envs/fastapi/lib/python3.6/site-packages/starlette/routing.py", line 65, in app
    response = await func(request)
  File "/home/wzkariampuzha/anaconda3/envs/fastapi/lib/python3.6/site-packages/fastapi/routing.py", line 228, in app
    dependant=dependant, values=values, is_coroutine=is_coroutine
  File "/home/wzkariampuzha/anaconda3/envs/fastapi/lib/python3.6/site-packages/fastapi/routing.py", line 160, in run_endpoint_function
    return await dependant.call(**values)
  File "./app.py", line 246, in get_rare_disease_epidemiology_abstracts
    return API_search_classification(search_term, maxResults, filtering, GARD_Search, epi_classify)
NameError: name 'maxResults' is not defined
INFO:     68.77.56.191:61948 - "GET /getEpiAbsRD/term%3D1?max_results=50&filtering=lenient HTTP/1.1" 500 Internal Server Error
ERROR:    Exception in ASGI application
Traceback (most recent call last):
  File "/home/wzkariampuzha/anaconda3/envs/fastapi/lib/python3.6/site-packages/uvicorn/protocols/http/h11_impl.py", line 373, in run_asgi
    result = await app(self.scope, self.receive, self.send)
  File "/home/wzkariampuzha/anaconda3/envs/fastapi/lib/python3.6/site-packages/uvicorn/middleware/proxy_headers.py", line 75, in __call__
    return await self.app(scope, receive, send)
  File "/home/wzkariampuzha/anaconda3/envs/fastapi/lib/python3.6/site-packages/fastapi/applications.py", line 269, in __call__
    await super().__call__(scope, receive, send)
  File "/home/wzkariampuzha/anaconda3/envs/fastapi/lib/python3.6/site-packages/starlette/applications.py", line 124, in __call__
    await self.middleware_stack(scope, receive, send)
  File "/home/wzkariampuzha/anaconda3/envs/fastapi/lib/python3.6/site-packages/starlette/middleware/errors.py", line 184, in __call__
    raise exc
  File "/home/wzkariampuzha/anaconda3/envs/fastapi/lib/python3.6/site-packages/starlette/middleware/errors.py", line 162, in __call__
    await self.app(scope, receive, _send)
  File "/home/wzkariampuzha/anaconda3/envs/fastapi/lib/python3.6/site-packages/starlette/exceptions.py", line 93, in __call__
    raise exc
  File "/home/wzkariampuzha/anaconda3/envs/fastapi/lib/python3.6/site-packages/starlette/exceptions.py", line 82, in __call__
    await self.app(scope, receive, sender)
  File "/home/wzkariampuzha/anaconda3/envs/fastapi/lib/python3.6/site-packages/fastapi/middleware/asyncexitstack.py", line 21, in __call__
    raise e
  File "/home/wzkariampuzha/anaconda3/envs/fastapi/lib/python3.6/site-packages/fastapi/middleware/asyncexitstack.py", line 18, in __call__
    await self.app(scope, receive, send)
  File "/home/wzkariampuzha/anaconda3/envs/fastapi/lib/python3.6/site-packages/starlette/routing.py", line 670, in __call__
    await route.handle(scope, receive, send)
  File "/home/wzkariampuzha/anaconda3/envs/fastapi/lib/python3.6/site-packages/starlette/routing.py", line 266, in handle
    await self.app(scope, receive, send)
  File "/home/wzkariampuzha/anaconda3/envs/fastapi/lib/python3.6/site-packages/starlette/routing.py", line 65, in app
    response = await func(request)
  File "/home/wzkariampuzha/anaconda3/envs/fastapi/lib/python3.6/site-packages/fastapi/routing.py", line 228, in app
    dependant=dependant, values=values, is_coroutine=is_coroutine
  File "/home/wzkariampuzha/anaconda3/envs/fastapi/lib/python3.6/site-packages/fastapi/routing.py", line 160, in run_endpoint_function
    return await dependant.call(**values)
  File "./app.py", line 246, in get_rare_disease_epidemiology_abstracts
    return API_search_classification(search_term, maxResults, filtering, GARD_Search, epi_classify)
NameError: name 'maxResults' is not defined
2022-05-25 18:39:04.912 ERROR   uvicorn.error: Exception in ASGI application
Traceback (most recent call last):
  File "/home/wzkariampuzha/anaconda3/envs/fastapi/lib/python3.6/site-packages/uvicorn/protocols/http/h11_impl.py", line 373, in run_asgi
    result = await app(self.scope, self.receive, self.send)
  File "/home/wzkariampuzha/anaconda3/envs/fastapi/lib/python3.6/site-packages/uvicorn/middleware/proxy_headers.py", line 75, in __call__
    return await self.app(scope, receive, send)
  File "/home/wzkariampuzha/anaconda3/envs/fastapi/lib/python3.6/site-packages/fastapi/applications.py", line 269, in __call__
    await super().__call__(scope, receive, send)
  File "/home/wzkariampuzha/anaconda3/envs/fastapi/lib/python3.6/site-packages/starlette/applications.py", line 124, in __call__
    await self.middleware_stack(scope, receive, send)
  File "/home/wzkariampuzha/anaconda3/envs/fastapi/lib/python3.6/site-packages/starlette/middleware/errors.py", line 184, in __call__
    raise exc
  File "/home/wzkariampuzha/anaconda3/envs/fastapi/lib/python3.6/site-packages/starlette/middleware/errors.py", line 162, in __call__
    await self.app(scope, receive, _send)
  File "/home/wzkariampuzha/anaconda3/envs/fastapi/lib/python3.6/site-packages/starlette/exceptions.py", line 93, in __call__
    raise exc
  File "/home/wzkariampuzha/anaconda3/envs/fastapi/lib/python3.6/site-packages/starlette/exceptions.py", line 82, in __call__
    await self.app(scope, receive, sender)
  File "/home/wzkariampuzha/anaconda3/envs/fastapi/lib/python3.6/site-packages/fastapi/middleware/asyncexitstack.py", line 21, in __call__
    raise e
  File "/home/wzkariampuzha/anaconda3/envs/fastapi/lib/python3.6/site-packages/fastapi/middleware/asyncexitstack.py", line 18, in __call__
    await self.app(scope, receive, send)
  File "/home/wzkariampuzha/anaconda3/envs/fastapi/lib/python3.6/site-packages/starlette/routing.py", line 670, in __call__
    await route.handle(scope, receive, send)
  File "/home/wzkariampuzha/anaconda3/envs/fastapi/lib/python3.6/site-packages/starlette/routing.py", line 266, in handle
    await self.app(scope, receive, send)
  File "/home/wzkariampuzha/anaconda3/envs/fastapi/lib/python3.6/site-packages/starlette/routing.py", line 65, in app
    response = await func(request)
  File "/home/wzkariampuzha/anaconda3/envs/fastapi/lib/python3.6/site-packages/fastapi/routing.py", line 228, in app
    dependant=dependant, values=values, is_coroutine=is_coroutine
  File "/home/wzkariampuzha/anaconda3/envs/fastapi/lib/python3.6/site-packages/fastapi/routing.py", line 160, in run_endpoint_function
    return await dependant.call(**values)
  File "./app.py", line 246, in get_rare_disease_epidemiology_abstracts
    return API_search_classification(search_term, maxResults, filtering, GARD_Search, epi_classify)
NameError: name 'maxResults' is not defined
INFO:     68.77.56.191:61949 - "GET /getEpiAbsRD/term%3D1?max_results=50&filtering=none HTTP/1.1" 500 Internal Server Error
ERROR:    Exception in ASGI application
Traceback (most recent call last):
  File "/home/wzkariampuzha/anaconda3/envs/fastapi/lib/python3.6/site-packages/uvicorn/protocols/http/h11_impl.py", line 373, in run_asgi
    result = await app(self.scope, self.receive, self.send)
  File "/home/wzkariampuzha/anaconda3/envs/fastapi/lib/python3.6/site-packages/uvicorn/middleware/proxy_headers.py", line 75, in __call__
    return await self.app(scope, receive, send)
  File "/home/wzkariampuzha/anaconda3/envs/fastapi/lib/python3.6/site-packages/fastapi/applications.py", line 269, in __call__
    await super().__call__(scope, receive, send)
  File "/home/wzkariampuzha/anaconda3/envs/fastapi/lib/python3.6/site-packages/starlette/applications.py", line 124, in __call__
    await self.middleware_stack(scope, receive, send)
  File "/home/wzkariampuzha/anaconda3/envs/fastapi/lib/python3.6/site-packages/starlette/middleware/errors.py", line 184, in __call__
    raise exc
  File "/home/wzkariampuzha/anaconda3/envs/fastapi/lib/python3.6/site-packages/starlette/middleware/errors.py", line 162, in __call__
    await self.app(scope, receive, _send)
  File "/home/wzkariampuzha/anaconda3/envs/fastapi/lib/python3.6/site-packages/starlette/exceptions.py", line 93, in __call__
    raise exc
  File "/home/wzkariampuzha/anaconda3/envs/fastapi/lib/python3.6/site-packages/starlette/exceptions.py", line 82, in __call__
    await self.app(scope, receive, sender)
  File "/home/wzkariampuzha/anaconda3/envs/fastapi/lib/python3.6/site-packages/fastapi/middleware/asyncexitstack.py", line 21, in __call__
    raise e
  File "/home/wzkariampuzha/anaconda3/envs/fastapi/lib/python3.6/site-packages/fastapi/middleware/asyncexitstack.py", line 18, in __call__
    await self.app(scope, receive, send)
  File "/home/wzkariampuzha/anaconda3/envs/fastapi/lib/python3.6/site-packages/starlette/routing.py", line 670, in __call__
    await route.handle(scope, receive, send)
  File "/home/wzkariampuzha/anaconda3/envs/fastapi/lib/python3.6/site-packages/starlette/routing.py", line 266, in handle
    await self.app(scope, receive, send)
  File "/home/wzkariampuzha/anaconda3/envs/fastapi/lib/python3.6/site-packages/starlette/routing.py", line 65, in app
    response = await func(request)
  File "/home/wzkariampuzha/anaconda3/envs/fastapi/lib/python3.6/site-packages/fastapi/routing.py", line 228, in app
    dependant=dependant, values=values, is_coroutine=is_coroutine
  File "/home/wzkariampuzha/anaconda3/envs/fastapi/lib/python3.6/site-packages/fastapi/routing.py", line 160, in run_endpoint_function
    return await dependant.call(**values)
  File "./app.py", line 246, in get_rare_disease_epidemiology_abstracts
    return API_search_classification(search_term, maxResults, filtering, GARD_Search, epi_classify)
NameError: name 'maxResults' is not defined
2022-05-25 18:39:52.863 ERROR   uvicorn.error: Exception in ASGI application
Traceback (most recent call last):
  File "/home/wzkariampuzha/anaconda3/envs/fastapi/lib/python3.6/site-packages/uvicorn/protocols/http/h11_impl.py", line 373, in run_asgi
    result = await app(self.scope, self.receive, self.send)
  File "/home/wzkariampuzha/anaconda3/envs/fastapi/lib/python3.6/site-packages/uvicorn/middleware/proxy_headers.py", line 75, in __call__
    return await self.app(scope, receive, send)
  File "/home/wzkariampuzha/anaconda3/envs/fastapi/lib/python3.6/site-packages/fastapi/applications.py", line 269, in __call__
    await super().__call__(scope, receive, send)
  File "/home/wzkariampuzha/anaconda3/envs/fastapi/lib/python3.6/site-packages/starlette/applications.py", line 124, in __call__
    await self.middleware_stack(scope, receive, send)
  File "/home/wzkariampuzha/anaconda3/envs/fastapi/lib/python3.6/site-packages/starlette/middleware/errors.py", line 184, in __call__
    raise exc
  File "/home/wzkariampuzha/anaconda3/envs/fastapi/lib/python3.6/site-packages/starlette/middleware/errors.py", line 162, in __call__
    await self.app(scope, receive, _send)
  File "/home/wzkariampuzha/anaconda3/envs/fastapi/lib/python3.6/site-packages/starlette/exceptions.py", line 93, in __call__
    raise exc
  File "/home/wzkariampuzha/anaconda3/envs/fastapi/lib/python3.6/site-packages/starlette/exceptions.py", line 82, in __call__
    await self.app(scope, receive, sender)
  File "/home/wzkariampuzha/anaconda3/envs/fastapi/lib/python3.6/site-packages/fastapi/middleware/asyncexitstack.py", line 21, in __call__
    raise e
  File "/home/wzkariampuzha/anaconda3/envs/fastapi/lib/python3.6/site-packages/fastapi/middleware/asyncexitstack.py", line 18, in __call__
    await self.app(scope, receive, send)
  File "/home/wzkariampuzha/anaconda3/envs/fastapi/lib/python3.6/site-packages/starlette/routing.py", line 670, in __call__
    await route.handle(scope, receive, send)
  File "/home/wzkariampuzha/anaconda3/envs/fastapi/lib/python3.6/site-packages/starlette/routing.py", line 266, in handle
    await self.app(scope, receive, send)
  File "/home/wzkariampuzha/anaconda3/envs/fastapi/lib/python3.6/site-packages/starlette/routing.py", line 65, in app
    response = await func(request)
  File "/home/wzkariampuzha/anaconda3/envs/fastapi/lib/python3.6/site-packages/fastapi/routing.py", line 228, in app
    dependant=dependant, values=values, is_coroutine=is_coroutine
  File "/home/wzkariampuzha/anaconda3/envs/fastapi/lib/python3.6/site-packages/fastapi/routing.py", line 160, in run_endpoint_function
    return await dependant.call(**values)
  File "./app.py", line 246, in get_rare_disease_epidemiology_abstracts
    return API_search_classification(search_term, maxResults, filtering, GARD_Search, epi_classify)
NameError: name 'maxResults' is not defined
***** Running Prediction *****
  Num examples = 11
  Batch size = 8
SEARCH TERM MATCHED TO GARD DICTIONARY. SEARCHING FOR:  ['growth restriction-aminoaciduria-cholestasis-iron overload-lactic acidosis-early death syndrome', 'growth retardation, aminoaciduria, cholestasis, iron overload, lactic acidosis and early death', 'growth delay-aminoaciduria-cholestasis-iron overload-lactic acidosis-early death syndrome', 'finnish lactic acidosis with hepatic hemosiderosis', 'finnish lethal neonatal metabolic syndrome', 'gracile syndrome', 'fellman syndrome', 'fellman disease']
Found 50 PMIDs. Gathered 11 Relevant Abstracts.
  0%|          | 0/2 [00:00<?, ?it/s]100%|██████████| 2/2 [00:02<00:00,  1.17s/it]INFO:     68.77.56.191:61950 - "GET /getEpiAbsExtractRD/term%3D1?max_results=50&filtering=strict&extract_diseases=false HTTP/1.1" 200 OK
***** Running Prediction *****
  Num examples = 11
  Batch size = 8
3it [00:50, 20.73s/it]                       4it [00:52, 13.70s/it]SEARCH TERM MATCHED TO GARD DICTIONARY. SEARCHING FOR:  ['growth restriction-aminoaciduria-cholestasis-iron overload-lactic acidosis-early death syndrome', 'growth retardation, aminoaciduria, cholestasis, iron overload, lactic acidosis and early death', 'growth delay-aminoaciduria-cholestasis-iron overload-lactic acidosis-early death syndrome', 'finnish lactic acidosis with hepatic hemosiderosis', 'finnish lethal neonatal metabolic syndrome', 'gracile syndrome', 'fellman syndrome', 'fellman disease']
Found 50 PMIDs. Gathered 11 Relevant Abstracts.
INFO:     68.77.56.191:61954 - "GET /getEpiAbsExtractRD/term%3D1?max_results=50&filtering=strict&extract_diseases=true HTTP/1.1" 200 OK
INFO:     68.77.56.191:61964 - "GET /getEpiAbsRD/term%3D1?max_results=50&filtering=strict HTTP/1.1" 500 Internal Server Error
ERROR:    Exception in ASGI application
Traceback (most recent call last):
  File "/home/wzkariampuzha/anaconda3/envs/fastapi/lib/python3.6/site-packages/uvicorn/protocols/http/h11_impl.py", line 373, in run_asgi
    result = await app(self.scope, self.receive, self.send)
  File "/home/wzkariampuzha/anaconda3/envs/fastapi/lib/python3.6/site-packages/uvicorn/middleware/proxy_headers.py", line 75, in __call__
    return await self.app(scope, receive, send)
  File "/home/wzkariampuzha/anaconda3/envs/fastapi/lib/python3.6/site-packages/fastapi/applications.py", line 269, in __call__
    await super().__call__(scope, receive, send)
  File "/home/wzkariampuzha/anaconda3/envs/fastapi/lib/python3.6/site-packages/starlette/applications.py", line 124, in __call__
    await self.middleware_stack(scope, receive, send)
  File "/home/wzkariampuzha/anaconda3/envs/fastapi/lib/python3.6/site-packages/starlette/middleware/errors.py", line 184, in __call__
    raise exc
  File "/home/wzkariampuzha/anaconda3/envs/fastapi/lib/python3.6/site-packages/starlette/middleware/errors.py", line 162, in __call__
    await self.app(scope, receive, _send)
  File "/home/wzkariampuzha/anaconda3/envs/fastapi/lib/python3.6/site-packages/starlette/exceptions.py", line 93, in __call__
    raise exc
  File "/home/wzkariampuzha/anaconda3/envs/fastapi/lib/python3.6/site-packages/starlette/exceptions.py", line 82, in __call__
    await self.app(scope, receive, sender)
  File "/home/wzkariampuzha/anaconda3/envs/fastapi/lib/python3.6/site-packages/fastapi/middleware/asyncexitstack.py", line 21, in __call__
    raise e
  File "/home/wzkariampuzha/anaconda3/envs/fastapi/lib/python3.6/site-packages/fastapi/middleware/asyncexitstack.py", line 18, in __call__
    await self.app(scope, receive, send)
  File "/home/wzkariampuzha/anaconda3/envs/fastapi/lib/python3.6/site-packages/starlette/routing.py", line 670, in __call__
    await route.handle(scope, receive, send)
  File "/home/wzkariampuzha/anaconda3/envs/fastapi/lib/python3.6/site-packages/starlette/routing.py", line 266, in handle
    await self.app(scope, receive, send)
  File "/home/wzkariampuzha/anaconda3/envs/fastapi/lib/python3.6/site-packages/starlette/routing.py", line 65, in app
    response = await func(request)
  File "/home/wzkariampuzha/anaconda3/envs/fastapi/lib/python3.6/site-packages/fastapi/routing.py", line 228, in app
    dependant=dependant, values=values, is_coroutine=is_coroutine
  File "/home/wzkariampuzha/anaconda3/envs/fastapi/lib/python3.6/site-packages/fastapi/routing.py", line 160, in run_endpoint_function
    return await dependant.call(**values)
  File "./app.py", line 246, in get_rare_disease_epidemiology_abstracts
    return API_search_classification(search_term, maxResults, filtering, GARD_Search, epi_classify)
NameError: name 'maxResults' is not defined
2022-05-25 18:44:19.193 ERROR   uvicorn.error: Exception in ASGI application
Traceback (most recent call last):
  File "/home/wzkariampuzha/anaconda3/envs/fastapi/lib/python3.6/site-packages/uvicorn/protocols/http/h11_impl.py", line 373, in run_asgi
    result = await app(self.scope, self.receive, self.send)
  File "/home/wzkariampuzha/anaconda3/envs/fastapi/lib/python3.6/site-packages/uvicorn/middleware/proxy_headers.py", line 75, in __call__
    return await self.app(scope, receive, send)
  File "/home/wzkariampuzha/anaconda3/envs/fastapi/lib/python3.6/site-packages/fastapi/applications.py", line 269, in __call__
    await super().__call__(scope, receive, send)
  File "/home/wzkariampuzha/anaconda3/envs/fastapi/lib/python3.6/site-packages/starlette/applications.py", line 124, in __call__
    await self.middleware_stack(scope, receive, send)
  File "/home/wzkariampuzha/anaconda3/envs/fastapi/lib/python3.6/site-packages/starlette/middleware/errors.py", line 184, in __call__
    raise exc
  File "/home/wzkariampuzha/anaconda3/envs/fastapi/lib/python3.6/site-packages/starlette/middleware/errors.py", line 162, in __call__
    await self.app(scope, receive, _send)
  File "/home/wzkariampuzha/anaconda3/envs/fastapi/lib/python3.6/site-packages/starlette/exceptions.py", line 93, in __call__
    raise exc
  File "/home/wzkariampuzha/anaconda3/envs/fastapi/lib/python3.6/site-packages/starlette/exceptions.py", line 82, in __call__
    await self.app(scope, receive, sender)
  File "/home/wzkariampuzha/anaconda3/envs/fastapi/lib/python3.6/site-packages/fastapi/middleware/asyncexitstack.py", line 21, in __call__
    raise e
  File "/home/wzkariampuzha/anaconda3/envs/fastapi/lib/python3.6/site-packages/fastapi/middleware/asyncexitstack.py", line 18, in __call__
    await self.app(scope, receive, send)
  File "/home/wzkariampuzha/anaconda3/envs/fastapi/lib/python3.6/site-packages/starlette/routing.py", line 670, in __call__
    await route.handle(scope, receive, send)
  File "/home/wzkariampuzha/anaconda3/envs/fastapi/lib/python3.6/site-packages/starlette/routing.py", line 266, in handle
    await self.app(scope, receive, send)
  File "/home/wzkariampuzha/anaconda3/envs/fastapi/lib/python3.6/site-packages/starlette/routing.py", line 65, in app
    response = await func(request)
  File "/home/wzkariampuzha/anaconda3/envs/fastapi/lib/python3.6/site-packages/fastapi/routing.py", line 228, in app
    dependant=dependant, values=values, is_coroutine=is_coroutine
  File "/home/wzkariampuzha/anaconda3/envs/fastapi/lib/python3.6/site-packages/fastapi/routing.py", line 160, in run_endpoint_function
    return await dependant.call(**values)
  File "./app.py", line 246, in get_rare_disease_epidemiology_abstracts
    return API_search_classification(search_term, maxResults, filtering, GARD_Search, epi_classify)
NameError: name 'maxResults' is not defined
INFO:     68.77.56.191:61967 - "GET /getEpiAbsRD/term%3DFellman%20syndrome?max_results=50&filtering=strict HTTP/1.1" 500 Internal Server Error
ERROR:    Exception in ASGI application
Traceback (most recent call last):
  File "/home/wzkariampuzha/anaconda3/envs/fastapi/lib/python3.6/site-packages/uvicorn/protocols/http/h11_impl.py", line 373, in run_asgi
    result = await app(self.scope, self.receive, self.send)
  File "/home/wzkariampuzha/anaconda3/envs/fastapi/lib/python3.6/site-packages/uvicorn/middleware/proxy_headers.py", line 75, in __call__
    return await self.app(scope, receive, send)
  File "/home/wzkariampuzha/anaconda3/envs/fastapi/lib/python3.6/site-packages/fastapi/applications.py", line 269, in __call__
    await super().__call__(scope, receive, send)
  File "/home/wzkariampuzha/anaconda3/envs/fastapi/lib/python3.6/site-packages/starlette/applications.py", line 124, in __call__
    await self.middleware_stack(scope, receive, send)
  File "/home/wzkariampuzha/anaconda3/envs/fastapi/lib/python3.6/site-packages/starlette/middleware/errors.py", line 184, in __call__
    raise exc
  File "/home/wzkariampuzha/anaconda3/envs/fastapi/lib/python3.6/site-packages/starlette/middleware/errors.py", line 162, in __call__
    await self.app(scope, receive, _send)
  File "/home/wzkariampuzha/anaconda3/envs/fastapi/lib/python3.6/site-packages/starlette/exceptions.py", line 93, in __call__
    raise exc
  File "/home/wzkariampuzha/anaconda3/envs/fastapi/lib/python3.6/site-packages/starlette/exceptions.py", line 82, in __call__
    await self.app(scope, receive, sender)
  File "/home/wzkariampuzha/anaconda3/envs/fastapi/lib/python3.6/site-packages/fastapi/middleware/asyncexitstack.py", line 21, in __call__
    raise e
  File "/home/wzkariampuzha/anaconda3/envs/fastapi/lib/python3.6/site-packages/fastapi/middleware/asyncexitstack.py", line 18, in __call__
    await self.app(scope, receive, send)
  File "/home/wzkariampuzha/anaconda3/envs/fastapi/lib/python3.6/site-packages/starlette/routing.py", line 670, in __call__
    await route.handle(scope, receive, send)
  File "/home/wzkariampuzha/anaconda3/envs/fastapi/lib/python3.6/site-packages/starlette/routing.py", line 266, in handle
    await self.app(scope, receive, send)
  File "/home/wzkariampuzha/anaconda3/envs/fastapi/lib/python3.6/site-packages/starlette/routing.py", line 65, in app
    response = await func(request)
  File "/home/wzkariampuzha/anaconda3/envs/fastapi/lib/python3.6/site-packages/fastapi/routing.py", line 228, in app
    dependant=dependant, values=values, is_coroutine=is_coroutine
  File "/home/wzkariampuzha/anaconda3/envs/fastapi/lib/python3.6/site-packages/fastapi/routing.py", line 160, in run_endpoint_function
    return await dependant.call(**values)
  File "./app.py", line 246, in get_rare_disease_epidemiology_abstracts
    return API_search_classification(search_term, maxResults, filtering, GARD_Search, epi_classify)
NameError: name 'maxResults' is not defined
2022-05-25 18:44:39.432 ERROR   uvicorn.error: Exception in ASGI application
Traceback (most recent call last):
  File "/home/wzkariampuzha/anaconda3/envs/fastapi/lib/python3.6/site-packages/uvicorn/protocols/http/h11_impl.py", line 373, in run_asgi
    result = await app(self.scope, self.receive, self.send)
  File "/home/wzkariampuzha/anaconda3/envs/fastapi/lib/python3.6/site-packages/uvicorn/middleware/proxy_headers.py", line 75, in __call__
    return await self.app(scope, receive, send)
  File "/home/wzkariampuzha/anaconda3/envs/fastapi/lib/python3.6/site-packages/fastapi/applications.py", line 269, in __call__
    await super().__call__(scope, receive, send)
  File "/home/wzkariampuzha/anaconda3/envs/fastapi/lib/python3.6/site-packages/starlette/applications.py", line 124, in __call__
    await self.middleware_stack(scope, receive, send)
  File "/home/wzkariampuzha/anaconda3/envs/fastapi/lib/python3.6/site-packages/starlette/middleware/errors.py", line 184, in __call__
    raise exc
  File "/home/wzkariampuzha/anaconda3/envs/fastapi/lib/python3.6/site-packages/starlette/middleware/errors.py", line 162, in __call__
    await self.app(scope, receive, _send)
  File "/home/wzkariampuzha/anaconda3/envs/fastapi/lib/python3.6/site-packages/starlette/exceptions.py", line 93, in __call__
    raise exc
  File "/home/wzkariampuzha/anaconda3/envs/fastapi/lib/python3.6/site-packages/starlette/exceptions.py", line 82, in __call__
    await self.app(scope, receive, sender)
  File "/home/wzkariampuzha/anaconda3/envs/fastapi/lib/python3.6/site-packages/fastapi/middleware/asyncexitstack.py", line 21, in __call__
    raise e
  File "/home/wzkariampuzha/anaconda3/envs/fastapi/lib/python3.6/site-packages/fastapi/middleware/asyncexitstack.py", line 18, in __call__
    await self.app(scope, receive, send)
  File "/home/wzkariampuzha/anaconda3/envs/fastapi/lib/python3.6/site-packages/starlette/routing.py", line 670, in __call__
    await route.handle(scope, receive, send)
  File "/home/wzkariampuzha/anaconda3/envs/fastapi/lib/python3.6/site-packages/starlette/routing.py", line 266, in handle
    await self.app(scope, receive, send)
  File "/home/wzkariampuzha/anaconda3/envs/fastapi/lib/python3.6/site-packages/starlette/routing.py", line 65, in app
    response = await func(request)
  File "/home/wzkariampuzha/anaconda3/envs/fastapi/lib/python3.6/site-packages/fastapi/routing.py", line 228, in app
    dependant=dependant, values=values, is_coroutine=is_coroutine
  File "/home/wzkariampuzha/anaconda3/envs/fastapi/lib/python3.6/site-packages/fastapi/routing.py", line 160, in run_endpoint_function
    return await dependant.call(**values)
  File "./app.py", line 246, in get_rare_disease_epidemiology_abstracts
    return API_search_classification(search_term, maxResults, filtering, GARD_Search, epi_classify)
NameError: name 'maxResults' is not defined
INFO:     68.77.56.191:61992 - "GET /getEpiAbsRD/term%3DFellman%20syndrome?max_results=50&filtering=strict HTTP/1.1" 500 Internal Server Error
ERROR:    Exception in ASGI application
Traceback (most recent call last):
  File "/home/wzkariampuzha/anaconda3/envs/fastapi/lib/python3.6/site-packages/uvicorn/protocols/http/h11_impl.py", line 373, in run_asgi
    result = await app(self.scope, self.receive, self.send)
  File "/home/wzkariampuzha/anaconda3/envs/fastapi/lib/python3.6/site-packages/uvicorn/middleware/proxy_headers.py", line 75, in __call__
    return await self.app(scope, receive, send)
  File "/home/wzkariampuzha/anaconda3/envs/fastapi/lib/python3.6/site-packages/fastapi/applications.py", line 269, in __call__
    await super().__call__(scope, receive, send)
  File "/home/wzkariampuzha/anaconda3/envs/fastapi/lib/python3.6/site-packages/starlette/applications.py", line 124, in __call__
    await self.middleware_stack(scope, receive, send)
  File "/home/wzkariampuzha/anaconda3/envs/fastapi/lib/python3.6/site-packages/starlette/middleware/errors.py", line 184, in __call__
    raise exc
  File "/home/wzkariampuzha/anaconda3/envs/fastapi/lib/python3.6/site-packages/starlette/middleware/errors.py", line 162, in __call__
    await self.app(scope, receive, _send)
  File "/home/wzkariampuzha/anaconda3/envs/fastapi/lib/python3.6/site-packages/starlette/exceptions.py", line 93, in __call__
    raise exc
  File "/home/wzkariampuzha/anaconda3/envs/fastapi/lib/python3.6/site-packages/starlette/exceptions.py", line 82, in __call__
    await self.app(scope, receive, sender)
  File "/home/wzkariampuzha/anaconda3/envs/fastapi/lib/python3.6/site-packages/fastapi/middleware/asyncexitstack.py", line 21, in __call__
    raise e
  File "/home/wzkariampuzha/anaconda3/envs/fastapi/lib/python3.6/site-packages/fastapi/middleware/asyncexitstack.py", line 18, in __call__
    await self.app(scope, receive, send)
  File "/home/wzkariampuzha/anaconda3/envs/fastapi/lib/python3.6/site-packages/starlette/routing.py", line 670, in __call__
    await route.handle(scope, receive, send)
  File "/home/wzkariampuzha/anaconda3/envs/fastapi/lib/python3.6/site-packages/starlette/routing.py", line 266, in handle
    await self.app(scope, receive, send)
  File "/home/wzkariampuzha/anaconda3/envs/fastapi/lib/python3.6/site-packages/starlette/routing.py", line 65, in app
    response = await func(request)
  File "/home/wzkariampuzha/anaconda3/envs/fastapi/lib/python3.6/site-packages/fastapi/routing.py", line 228, in app
    dependant=dependant, values=values, is_coroutine=is_coroutine
  File "/home/wzkariampuzha/anaconda3/envs/fastapi/lib/python3.6/site-packages/fastapi/routing.py", line 160, in run_endpoint_function
    return await dependant.call(**values)
  File "./app.py", line 246, in get_rare_disease_epidemiology_abstracts
    return API_search_classification(search_term, maxResults, filtering, GARD_Search, epi_classify)
NameError: name 'maxResults' is not defined
2022-05-25 18:45:44.973 ERROR   uvicorn.error: Exception in ASGI application
Traceback (most recent call last):
  File "/home/wzkariampuzha/anaconda3/envs/fastapi/lib/python3.6/site-packages/uvicorn/protocols/http/h11_impl.py", line 373, in run_asgi
    result = await app(self.scope, self.receive, self.send)
  File "/home/wzkariampuzha/anaconda3/envs/fastapi/lib/python3.6/site-packages/uvicorn/middleware/proxy_headers.py", line 75, in __call__
    return await self.app(scope, receive, send)
  File "/home/wzkariampuzha/anaconda3/envs/fastapi/lib/python3.6/site-packages/fastapi/applications.py", line 269, in __call__
    await super().__call__(scope, receive, send)
  File "/home/wzkariampuzha/anaconda3/envs/fastapi/lib/python3.6/site-packages/starlette/applications.py", line 124, in __call__
    await self.middleware_stack(scope, receive, send)
  File "/home/wzkariampuzha/anaconda3/envs/fastapi/lib/python3.6/site-packages/starlette/middleware/errors.py", line 184, in __call__
    raise exc
  File "/home/wzkariampuzha/anaconda3/envs/fastapi/lib/python3.6/site-packages/starlette/middleware/errors.py", line 162, in __call__
    await self.app(scope, receive, _send)
  File "/home/wzkariampuzha/anaconda3/envs/fastapi/lib/python3.6/site-packages/starlette/exceptions.py", line 93, in __call__
    raise exc
  File "/home/wzkariampuzha/anaconda3/envs/fastapi/lib/python3.6/site-packages/starlette/exceptions.py", line 82, in __call__
    await self.app(scope, receive, sender)
  File "/home/wzkariampuzha/anaconda3/envs/fastapi/lib/python3.6/site-packages/fastapi/middleware/asyncexitstack.py", line 21, in __call__
    raise e
  File "/home/wzkariampuzha/anaconda3/envs/fastapi/lib/python3.6/site-packages/fastapi/middleware/asyncexitstack.py", line 18, in __call__
    await self.app(scope, receive, send)
  File "/home/wzkariampuzha/anaconda3/envs/fastapi/lib/python3.6/site-packages/starlette/routing.py", line 670, in __call__
    await route.handle(scope, receive, send)
  File "/home/wzkariampuzha/anaconda3/envs/fastapi/lib/python3.6/site-packages/starlette/routing.py", line 266, in handle
    await self.app(scope, receive, send)
  File "/home/wzkariampuzha/anaconda3/envs/fastapi/lib/python3.6/site-packages/starlette/routing.py", line 65, in app
    response = await func(request)
  File "/home/wzkariampuzha/anaconda3/envs/fastapi/lib/python3.6/site-packages/fastapi/routing.py", line 228, in app
    dependant=dependant, values=values, is_coroutine=is_coroutine
  File "/home/wzkariampuzha/anaconda3/envs/fastapi/lib/python3.6/site-packages/fastapi/routing.py", line 160, in run_endpoint_function
    return await dependant.call(**values)
  File "./app.py", line 246, in get_rare_disease_epidemiology_abstracts
    return API_search_classification(search_term, maxResults, filtering, GARD_Search, epi_classify)
NameError: name 'maxResults' is not defined
INFO:     68.77.56.191:61993 - "GET /favicon.ico HTTP/1.1" 404 Not Found
INFO:     68.77.56.191:62014 - "POST /postEpiClassifyText/ HTTP/1.1" 200 OK
INFO:     69.250.73.75:50447 - "GET /docs HTTP/1.1" 200 OK
INFO:     69.250.73.75:50447 - "GET /openapi.json HTTP/1.1" 200 OK
INFO:     69.250.73.75:50448 - "GET /docs HTTP/1.1" 200 OK
INFO:     69.250.73.75:50448 - "GET /openapi.json HTTP/1.1" 200 OK
INFO:     68.77.56.191:62211 - "GET /docs HTTP/1.1" 200 OK
INFO:     68.77.56.191:62211 - "GET /openapi.json HTTP/1.1" 200 OK
INFO:     108.18.115.68:50744 - "GET /docs HTTP/1.1" 200 OK
INFO:     108.18.115.68:50744 - "GET /openapi.json HTTP/1.1" 200 OK
INFO:     72.69.19.165:63073 - "GET /docs HTTP/1.1" 200 OK
INFO:     72.69.19.165:63073 - "GET /openapi.json HTTP/1.1" 200 OK
INFO:     68.77.56.191:62673 - "GET /docs HTTP/1.1" 200 OK
INFO:     68.77.56.191:62673 - "GET /openapi.json HTTP/1.1" 200 OK
INFO:     172.58.191.240:38490 - "GET /docs HTTP/1.1" 200 OK
INFO:     172.58.191.240:38490 - "GET /openapi.json HTTP/1.1" 200 OK
INFO:     68.77.56.191:62798 - "GET /docs HTTP/1.1" 200 OK
INFO:     68.77.56.191:62798 - "GET /openapi.json HTTP/1.1" 200 OK
SEARCH TERM MATCHED TO GARD DICTIONARY. SEARCHING FOR:  ['growth restriction-aminoaciduria-cholestasis-iron overload-lactic acidosis-early death syndrome', 'growth retardation, aminoaciduria, cholestasis, iron overload, lactic acidosis and early death', 'growth delay-aminoaciduria-cholestasis-iron overload-lactic acidosis-early death syndrome', 'finnish lactic acidosis with hepatic hemosiderosis', 'finnish lethal neonatal metabolic syndrome', 'gracile syndrome', 'fellman syndrome', 'fellman disease']
Found 50 PMIDs. Gathered 11 Relevant Abstracts.
INFO:     68.77.56.191:62797 - "GET /getAbsRD/term%3D1?max_results=50&filtering=strict HTTP/1.1" 200 OK
INFO:     68.77.56.191:62804 - "GET /getEpiAbsRD/term%3D1?max_results=50&filtering=strict HTTP/1.1" 500 Internal Server Error
ERROR:    Exception in ASGI application
Traceback (most recent call last):
  File "/home/wzkariampuzha/anaconda3/envs/fastapi/lib/python3.6/site-packages/uvicorn/protocols/http/h11_impl.py", line 373, in run_asgi
    result = await app(self.scope, self.receive, self.send)
  File "/home/wzkariampuzha/anaconda3/envs/fastapi/lib/python3.6/site-packages/uvicorn/middleware/proxy_headers.py", line 75, in __call__
    return await self.app(scope, receive, send)
  File "/home/wzkariampuzha/anaconda3/envs/fastapi/lib/python3.6/site-packages/fastapi/applications.py", line 269, in __call__
    await super().__call__(scope, receive, send)
  File "/home/wzkariampuzha/anaconda3/envs/fastapi/lib/python3.6/site-packages/starlette/applications.py", line 124, in __call__
    await self.middleware_stack(scope, receive, send)
  File "/home/wzkariampuzha/anaconda3/envs/fastapi/lib/python3.6/site-packages/starlette/middleware/errors.py", line 184, in __call__
    raise exc
  File "/home/wzkariampuzha/anaconda3/envs/fastapi/lib/python3.6/site-packages/starlette/middleware/errors.py", line 162, in __call__
    await self.app(scope, receive, _send)
  File "/home/wzkariampuzha/anaconda3/envs/fastapi/lib/python3.6/site-packages/starlette/exceptions.py", line 93, in __call__
    raise exc
  File "/home/wzkariampuzha/anaconda3/envs/fastapi/lib/python3.6/site-packages/starlette/exceptions.py", line 82, in __call__
    await self.app(scope, receive, sender)
  File "/home/wzkariampuzha/anaconda3/envs/fastapi/lib/python3.6/site-packages/fastapi/middleware/asyncexitstack.py", line 21, in __call__
    raise e
  File "/home/wzkariampuzha/anaconda3/envs/fastapi/lib/python3.6/site-packages/fastapi/middleware/asyncexitstack.py", line 18, in __call__
    await self.app(scope, receive, send)
  File "/home/wzkariampuzha/anaconda3/envs/fastapi/lib/python3.6/site-packages/starlette/routing.py", line 670, in __call__
    await route.handle(scope, receive, send)
  File "/home/wzkariampuzha/anaconda3/envs/fastapi/lib/python3.6/site-packages/starlette/routing.py", line 266, in handle
    await self.app(scope, receive, send)
  File "/home/wzkariampuzha/anaconda3/envs/fastapi/lib/python3.6/site-packages/starlette/routing.py", line 65, in app
    response = await func(request)
  File "/home/wzkariampuzha/anaconda3/envs/fastapi/lib/python3.6/site-packages/fastapi/routing.py", line 228, in app
    dependant=dependant, values=values, is_coroutine=is_coroutine
  File "/home/wzkariampuzha/anaconda3/envs/fastapi/lib/python3.6/site-packages/fastapi/routing.py", line 160, in run_endpoint_function
    return await dependant.call(**values)
  File "./app.py", line 246, in get_rare_disease_epidemiology_abstracts
    return API_search_classification(search_term, maxResults, filtering, GARD_Search, epi_classify)
NameError: name 'maxResults' is not defined
2022-05-25 20:56:05.495 ERROR   uvicorn.error: Exception in ASGI application
Traceback (most recent call last):
  File "/home/wzkariampuzha/anaconda3/envs/fastapi/lib/python3.6/site-packages/uvicorn/protocols/http/h11_impl.py", line 373, in run_asgi
    result = await app(self.scope, self.receive, self.send)
  File "/home/wzkariampuzha/anaconda3/envs/fastapi/lib/python3.6/site-packages/uvicorn/middleware/proxy_headers.py", line 75, in __call__
    return await self.app(scope, receive, send)
  File "/home/wzkariampuzha/anaconda3/envs/fastapi/lib/python3.6/site-packages/fastapi/applications.py", line 269, in __call__
    await super().__call__(scope, receive, send)
  File "/home/wzkariampuzha/anaconda3/envs/fastapi/lib/python3.6/site-packages/starlette/applications.py", line 124, in __call__
    await self.middleware_stack(scope, receive, send)
  File "/home/wzkariampuzha/anaconda3/envs/fastapi/lib/python3.6/site-packages/starlette/middleware/errors.py", line 184, in __call__
    raise exc
  File "/home/wzkariampuzha/anaconda3/envs/fastapi/lib/python3.6/site-packages/starlette/middleware/errors.py", line 162, in __call__
    await self.app(scope, receive, _send)
  File "/home/wzkariampuzha/anaconda3/envs/fastapi/lib/python3.6/site-packages/starlette/exceptions.py", line 93, in __call__
    raise exc
  File "/home/wzkariampuzha/anaconda3/envs/fastapi/lib/python3.6/site-packages/starlette/exceptions.py", line 82, in __call__
    await self.app(scope, receive, sender)
  File "/home/wzkariampuzha/anaconda3/envs/fastapi/lib/python3.6/site-packages/fastapi/middleware/asyncexitstack.py", line 21, in __call__
    raise e
  File "/home/wzkariampuzha/anaconda3/envs/fastapi/lib/python3.6/site-packages/fastapi/middleware/asyncexitstack.py", line 18, in __call__
    await self.app(scope, receive, send)
  File "/home/wzkariampuzha/anaconda3/envs/fastapi/lib/python3.6/site-packages/starlette/routing.py", line 670, in __call__
    await route.handle(scope, receive, send)
  File "/home/wzkariampuzha/anaconda3/envs/fastapi/lib/python3.6/site-packages/starlette/routing.py", line 266, in handle
    await self.app(scope, receive, send)
  File "/home/wzkariampuzha/anaconda3/envs/fastapi/lib/python3.6/site-packages/starlette/routing.py", line 65, in app
    response = await func(request)
  File "/home/wzkariampuzha/anaconda3/envs/fastapi/lib/python3.6/site-packages/fastapi/routing.py", line 228, in app
    dependant=dependant, values=values, is_coroutine=is_coroutine
  File "/home/wzkariampuzha/anaconda3/envs/fastapi/lib/python3.6/site-packages/fastapi/routing.py", line 160, in run_endpoint_function
    return await dependant.call(**values)
  File "./app.py", line 246, in get_rare_disease_epidemiology_abstracts
    return API_search_classification(search_term, maxResults, filtering, GARD_Search, epi_classify)
NameError: name 'maxResults' is not defined
INFO:     68.77.56.191:62808 - "GET /getEpiAbsRD/term%3D1?max_results=50&filtering=strict HTTP/1.1" 500 Internal Server Error
ERROR:    Exception in ASGI application
Traceback (most recent call last):
  File "/home/wzkariampuzha/anaconda3/envs/fastapi/lib/python3.6/site-packages/uvicorn/protocols/http/h11_impl.py", line 373, in run_asgi
    result = await app(self.scope, self.receive, self.send)
  File "/home/wzkariampuzha/anaconda3/envs/fastapi/lib/python3.6/site-packages/uvicorn/middleware/proxy_headers.py", line 75, in __call__
    return await self.app(scope, receive, send)
  File "/home/wzkariampuzha/anaconda3/envs/fastapi/lib/python3.6/site-packages/fastapi/applications.py", line 269, in __call__
    await super().__call__(scope, receive, send)
  File "/home/wzkariampuzha/anaconda3/envs/fastapi/lib/python3.6/site-packages/starlette/applications.py", line 124, in __call__
    await self.middleware_stack(scope, receive, send)
  File "/home/wzkariampuzha/anaconda3/envs/fastapi/lib/python3.6/site-packages/starlette/middleware/errors.py", line 184, in __call__
    raise exc
  File "/home/wzkariampuzha/anaconda3/envs/fastapi/lib/python3.6/site-packages/starlette/middleware/errors.py", line 162, in __call__
    await self.app(scope, receive, _send)
  File "/home/wzkariampuzha/anaconda3/envs/fastapi/lib/python3.6/site-packages/starlette/exceptions.py", line 93, in __call__
    raise exc
  File "/home/wzkariampuzha/anaconda3/envs/fastapi/lib/python3.6/site-packages/starlette/exceptions.py", line 82, in __call__
    await self.app(scope, receive, sender)
  File "/home/wzkariampuzha/anaconda3/envs/fastapi/lib/python3.6/site-packages/fastapi/middleware/asyncexitstack.py", line 21, in __call__
    raise e
  File "/home/wzkariampuzha/anaconda3/envs/fastapi/lib/python3.6/site-packages/fastapi/middleware/asyncexitstack.py", line 18, in __call__
    await self.app(scope, receive, send)
  File "/home/wzkariampuzha/anaconda3/envs/fastapi/lib/python3.6/site-packages/starlette/routing.py", line 670, in __call__
    await route.handle(scope, receive, send)
  File "/home/wzkariampuzha/anaconda3/envs/fastapi/lib/python3.6/site-packages/starlette/routing.py", line 266, in handle
    await self.app(scope, receive, send)
  File "/home/wzkariampuzha/anaconda3/envs/fastapi/lib/python3.6/site-packages/starlette/routing.py", line 65, in app
    response = await func(request)
  File "/home/wzkariampuzha/anaconda3/envs/fastapi/lib/python3.6/site-packages/fastapi/routing.py", line 228, in app
    dependant=dependant, values=values, is_coroutine=is_coroutine
  File "/home/wzkariampuzha/anaconda3/envs/fastapi/lib/python3.6/site-packages/fastapi/routing.py", line 160, in run_endpoint_function
    return await dependant.call(**values)
  File "./app.py", line 246, in get_rare_disease_epidemiology_abstracts
    return API_search_classification(search_term, maxResults, filtering, GARD_Search, epi_classify)
NameError: name 'maxResults' is not defined
2022-05-25 20:56:56.002 ERROR   uvicorn.error: Exception in ASGI application
Traceback (most recent call last):
  File "/home/wzkariampuzha/anaconda3/envs/fastapi/lib/python3.6/site-packages/uvicorn/protocols/http/h11_impl.py", line 373, in run_asgi
    result = await app(self.scope, self.receive, self.send)
  File "/home/wzkariampuzha/anaconda3/envs/fastapi/lib/python3.6/site-packages/uvicorn/middleware/proxy_headers.py", line 75, in __call__
    return await self.app(scope, receive, send)
  File "/home/wzkariampuzha/anaconda3/envs/fastapi/lib/python3.6/site-packages/fastapi/applications.py", line 269, in __call__
    await super().__call__(scope, receive, send)
  File "/home/wzkariampuzha/anaconda3/envs/fastapi/lib/python3.6/site-packages/starlette/applications.py", line 124, in __call__
    await self.middleware_stack(scope, receive, send)
  File "/home/wzkariampuzha/anaconda3/envs/fastapi/lib/python3.6/site-packages/starlette/middleware/errors.py", line 184, in __call__
    raise exc
  File "/home/wzkariampuzha/anaconda3/envs/fastapi/lib/python3.6/site-packages/starlette/middleware/errors.py", line 162, in __call__
    await self.app(scope, receive, _send)
  File "/home/wzkariampuzha/anaconda3/envs/fastapi/lib/python3.6/site-packages/starlette/exceptions.py", line 93, in __call__
    raise exc
  File "/home/wzkariampuzha/anaconda3/envs/fastapi/lib/python3.6/site-packages/starlette/exceptions.py", line 82, in __call__
    await self.app(scope, receive, sender)
  File "/home/wzkariampuzha/anaconda3/envs/fastapi/lib/python3.6/site-packages/fastapi/middleware/asyncexitstack.py", line 21, in __call__
    raise e
  File "/home/wzkariampuzha/anaconda3/envs/fastapi/lib/python3.6/site-packages/fastapi/middleware/asyncexitstack.py", line 18, in __call__
    await self.app(scope, receive, send)
  File "/home/wzkariampuzha/anaconda3/envs/fastapi/lib/python3.6/site-packages/starlette/routing.py", line 670, in __call__
    await route.handle(scope, receive, send)
  File "/home/wzkariampuzha/anaconda3/envs/fastapi/lib/python3.6/site-packages/starlette/routing.py", line 266, in handle
    await self.app(scope, receive, send)
  File "/home/wzkariampuzha/anaconda3/envs/fastapi/lib/python3.6/site-packages/starlette/routing.py", line 65, in app
    response = await func(request)
  File "/home/wzkariampuzha/anaconda3/envs/fastapi/lib/python3.6/site-packages/fastapi/routing.py", line 228, in app
    dependant=dependant, values=values, is_coroutine=is_coroutine
  File "/home/wzkariampuzha/anaconda3/envs/fastapi/lib/python3.6/site-packages/fastapi/routing.py", line 160, in run_endpoint_function
    return await dependant.call(**values)
  File "./app.py", line 246, in get_rare_disease_epidemiology_abstracts
    return API_search_classification(search_term, maxResults, filtering, GARD_Search, epi_classify)
NameError: name 'maxResults' is not defined
INFO:     47.219.194.90:50251 - "GET /docs HTTP/1.1" 200 OK
INFO:     47.219.194.90:50251 - "GET /openapi.json HTTP/1.1" 200 OK
INFO:     47.219.194.90:50251 - "GET /docs HTTP/1.1" 200 OK
INFO:     47.219.194.90:50251 - "GET /openapi.json HTTP/1.1" 200 OK
INFO:     47.219.194.90:50257 - "GET /getEpiAbsRD/term%3D1?max_results=35&filtering=lenient HTTP/1.1" 500 Internal Server Error
ERROR:    Exception in ASGI application
Traceback (most recent call last):
  File "/home/wzkariampuzha/anaconda3/envs/fastapi/lib/python3.6/site-packages/uvicorn/protocols/http/h11_impl.py", line 373, in run_asgi
    result = await app(self.scope, self.receive, self.send)
  File "/home/wzkariampuzha/anaconda3/envs/fastapi/lib/python3.6/site-packages/uvicorn/middleware/proxy_headers.py", line 75, in __call__
    return await self.app(scope, receive, send)
  File "/home/wzkariampuzha/anaconda3/envs/fastapi/lib/python3.6/site-packages/fastapi/applications.py", line 269, in __call__
    await super().__call__(scope, receive, send)
  File "/home/wzkariampuzha/anaconda3/envs/fastapi/lib/python3.6/site-packages/starlette/applications.py", line 124, in __call__
    await self.middleware_stack(scope, receive, send)
  File "/home/wzkariampuzha/anaconda3/envs/fastapi/lib/python3.6/site-packages/starlette/middleware/errors.py", line 184, in __call__
    raise exc
  File "/home/wzkariampuzha/anaconda3/envs/fastapi/lib/python3.6/site-packages/starlette/middleware/errors.py", line 162, in __call__
    await self.app(scope, receive, _send)
  File "/home/wzkariampuzha/anaconda3/envs/fastapi/lib/python3.6/site-packages/starlette/exceptions.py", line 93, in __call__
    raise exc
  File "/home/wzkariampuzha/anaconda3/envs/fastapi/lib/python3.6/site-packages/starlette/exceptions.py", line 82, in __call__
    await self.app(scope, receive, sender)
  File "/home/wzkariampuzha/anaconda3/envs/fastapi/lib/python3.6/site-packages/fastapi/middleware/asyncexitstack.py", line 21, in __call__
    raise e
  File "/home/wzkariampuzha/anaconda3/envs/fastapi/lib/python3.6/site-packages/fastapi/middleware/asyncexitstack.py", line 18, in __call__
    await self.app(scope, receive, send)
  File "/home/wzkariampuzha/anaconda3/envs/fastapi/lib/python3.6/site-packages/starlette/routing.py", line 670, in __call__
    await route.handle(scope, receive, send)
  File "/home/wzkariampuzha/anaconda3/envs/fastapi/lib/python3.6/site-packages/starlette/routing.py", line 266, in handle
    await self.app(scope, receive, send)
  File "/home/wzkariampuzha/anaconda3/envs/fastapi/lib/python3.6/site-packages/starlette/routing.py", line 65, in app
    response = await func(request)
  File "/home/wzkariampuzha/anaconda3/envs/fastapi/lib/python3.6/site-packages/fastapi/routing.py", line 228, in app
    dependant=dependant, values=values, is_coroutine=is_coroutine
  File "/home/wzkariampuzha/anaconda3/envs/fastapi/lib/python3.6/site-packages/fastapi/routing.py", line 160, in run_endpoint_function
    return await dependant.call(**values)
  File "./app.py", line 246, in get_rare_disease_epidemiology_abstracts
    return API_search_classification(search_term, maxResults, filtering, GARD_Search, epi_classify)
NameError: name 'maxResults' is not defined
2022-05-25 21:33:44.456 ERROR   uvicorn.error: Exception in ASGI application
Traceback (most recent call last):
  File "/home/wzkariampuzha/anaconda3/envs/fastapi/lib/python3.6/site-packages/uvicorn/protocols/http/h11_impl.py", line 373, in run_asgi
    result = await app(self.scope, self.receive, self.send)
  File "/home/wzkariampuzha/anaconda3/envs/fastapi/lib/python3.6/site-packages/uvicorn/middleware/proxy_headers.py", line 75, in __call__
    return await self.app(scope, receive, send)
  File "/home/wzkariampuzha/anaconda3/envs/fastapi/lib/python3.6/site-packages/fastapi/applications.py", line 269, in __call__
    await super().__call__(scope, receive, send)
  File "/home/wzkariampuzha/anaconda3/envs/fastapi/lib/python3.6/site-packages/starlette/applications.py", line 124, in __call__
    await self.middleware_stack(scope, receive, send)
  File "/home/wzkariampuzha/anaconda3/envs/fastapi/lib/python3.6/site-packages/starlette/middleware/errors.py", line 184, in __call__
    raise exc
  File "/home/wzkariampuzha/anaconda3/envs/fastapi/lib/python3.6/site-packages/starlette/middleware/errors.py", line 162, in __call__
    await self.app(scope, receive, _send)
  File "/home/wzkariampuzha/anaconda3/envs/fastapi/lib/python3.6/site-packages/starlette/exceptions.py", line 93, in __call__
    raise exc
  File "/home/wzkariampuzha/anaconda3/envs/fastapi/lib/python3.6/site-packages/starlette/exceptions.py", line 82, in __call__
    await self.app(scope, receive, sender)
  File "/home/wzkariampuzha/anaconda3/envs/fastapi/lib/python3.6/site-packages/fastapi/middleware/asyncexitstack.py", line 21, in __call__
    raise e
  File "/home/wzkariampuzha/anaconda3/envs/fastapi/lib/python3.6/site-packages/fastapi/middleware/asyncexitstack.py", line 18, in __call__
    await self.app(scope, receive, send)
  File "/home/wzkariampuzha/anaconda3/envs/fastapi/lib/python3.6/site-packages/starlette/routing.py", line 670, in __call__
    await route.handle(scope, receive, send)
  File "/home/wzkariampuzha/anaconda3/envs/fastapi/lib/python3.6/site-packages/starlette/routing.py", line 266, in handle
    await self.app(scope, receive, send)
  File "/home/wzkariampuzha/anaconda3/envs/fastapi/lib/python3.6/site-packages/starlette/routing.py", line 65, in app
    response = await func(request)
  File "/home/wzkariampuzha/anaconda3/envs/fastapi/lib/python3.6/site-packages/fastapi/routing.py", line 228, in app
    dependant=dependant, values=values, is_coroutine=is_coroutine
  File "/home/wzkariampuzha/anaconda3/envs/fastapi/lib/python3.6/site-packages/fastapi/routing.py", line 160, in run_endpoint_function
    return await dependant.call(**values)
  File "./app.py", line 246, in get_rare_disease_epidemiology_abstracts
    return API_search_classification(search_term, maxResults, filtering, GARD_Search, epi_classify)
NameError: name 'maxResults' is not defined
/home/wzkariampuzha/anaconda3/envs/fastapi/lib/python3.6/multiprocessing/semaphore_tracker.py:143: UserWarning: semaphore_tracker: There appear to be 1 leaked semaphores to clean up at shutdown
  len(cache))
2022-06-06 21:00:24.433 WARNING tensorflow: SavedModel saved prior to TF 2.5 detected when loading Keras model. Please ensure that you are saving the model with model.save() or tf.keras.models.save_model(), *NOT* tf.saved_model.save(). To confirm, there should be a file named "keras_metadata.pb" in the SavedModel directory.
INFO:     Started server process [23388]
2022-06-06 21:00:38.668 INFO    uvicorn.error: Started server process [23388]
INFO:     Waiting for application startup.
2022-06-06 21:00:38.668 INFO    uvicorn.error: Waiting for application startup.
INFO:     Application startup complete.
2022-06-06 21:00:38.668 INFO    uvicorn.error: Application startup complete.
INFO:     Uvicorn running on https://10.9.1.108:8000 (Press CTRL+C to quit)
2022-06-06 21:00:38.669 INFO    uvicorn.error: Uvicorn running on https://10.9.1.108:8000 (Press CTRL+C to quit)
INFO:     128.231.234.28:32629 - "GET /docs HTTP/1.1" 200 OK
INFO:     128.231.234.28:32629 - "GET /openapi.json HTTP/1.1" 200 OK
INFO:     128.231.234.28:60793 - "GET / HTTP/1.1" 200 OK
INFO:     128.231.234.28:60793 - "GET / HTTP/1.1" 200 OK
INFO:     35.233.205.204:51244 - "POST /postEpiClassifyText/ HTTP/1.1" 200 OK
INFO:     35.233.205.204:51278 - "POST /postEpiExtractText HTTP/1.1" 307 Temporary Redirect
***** Running Prediction *****
  Num examples = 13
  Batch size = 8
  0%|          | 0/2 [00:00<?, ?it/s]100%|██████████| 2/2 [00:02<00:00,  1.17s/it]INFO:     35.233.205.204:51278 - "POST /postEpiExtractText/ HTTP/1.1" 200 OK
INFO:     35.233.205.204:51320 - "POST /postAbsBatch HTTP/1.1" 307 Temporary Redirect
SEARCH TERM MATCHED TO GARD DICTIONARY. SEARCHING FOR:  ['growth restriction-aminoaciduria-cholestasis-iron overload-lactic acidosis-early death syndrome', 'growth retardation, aminoaciduria, cholestasis, iron overload, lactic acidosis and early death', 'growth delay-aminoaciduria-cholestasis-iron overload-lactic acidosis-early death syndrome', 'finnish lactic acidosis with hepatic hemosiderosis', 'finnish lethal neonatal metabolic syndrome', 'gracile syndrome', 'fellman syndrome', 'fellman disease']
Found 20 PMIDs. Gathered 4 Relevant Abstracts.
SEARCH TERM MATCHED TO GARD DICTIONARY. SEARCHING FOR:  ['phenylalanine hydroxylase deficiency', 'oligophrenia phenylpyruvica', 'phenylketonuria', 'folling disease']
Found 20 PMIDs. Gathered 18 Relevant Abstracts.
SEARCH TERM MATCHED TO GARD DICTIONARY. SEARCHING FOR:  ['cystic fibrosis', 'mucoviscidosis']
Found 20 PMIDs. Gathered 14 Relevant Abstracts.
SEARCH TERM MATCHED TO GARD DICTIONARY. SEARCHING FOR:  ['geographic helicoid peripapillary choroidopathy (ghpc)', 'geographic serpiginous choroiditis', 'peripapillary choriopathy', 'serpiginous choroidopathy', 'serpiginous choroiditis', 'geographic choroiditis']
Found 25 PMIDs. Gathered 14 Relevant Abstracts.
INFO:     35.233.205.204:51320 - "POST /postAbsBatch/ HTTP/1.1" 200 OK
INFO:     162.142.125.212:51908 - "GET / HTTP/1.1" 200 OK
INFO:     162.142.125.212:60526 - "GET / HTTP/1.1" 200 OK
INFO:     162.142.125.212:34158 - "PRI %2A HTTP/2.0" 404 Not Found
WARNING:  Invalid HTTP request received.
Traceback (most recent call last):
  File "/home/wzkariampuzha/anaconda3/envs/fastapi/lib/python3.6/site-packages/starlette/exceptions.py", line 82, in __call__
    await self.app(scope, receive, sender)
  File "/home/wzkariampuzha/anaconda3/envs/fastapi/lib/python3.6/site-packages/fastapi/middleware/asyncexitstack.py", line 21, in __call__
    raise e
  File "/home/wzkariampuzha/anaconda3/envs/fastapi/lib/python3.6/site-packages/fastapi/middleware/asyncexitstack.py", line 18, in __call__
    await self.app(scope, receive, send)
  File "/home/wzkariampuzha/anaconda3/envs/fastapi/lib/python3.6/site-packages/starlette/routing.py", line 699, in __call__
    await self.default(scope, receive, send)
  File "/home/wzkariampuzha/anaconda3/envs/fastapi/lib/python3.6/site-packages/starlette/routing.py", line 593, in not_found
    raise HTTPException(status_code=404)
starlette.exceptions.HTTPException

During handling of the above exception, another exception occurred:

Traceback (most recent call last):
  File "/home/wzkariampuzha/anaconda3/envs/fastapi/lib/python3.6/site-packages/uvicorn/protocols/http/h11_impl.py", line 136, in handle_events
    event = self.conn.next_event()
  File "/home/wzkariampuzha/anaconda3/envs/fastapi/lib/python3.6/site-packages/h11/_connection.py", line 485, in next_event
    exc._reraise_as_remote_protocol_error()
  File "/home/wzkariampuzha/anaconda3/envs/fastapi/lib/python3.6/site-packages/h11/_util.py", line 77, in _reraise_as_remote_protocol_error
    raise self
  File "/home/wzkariampuzha/anaconda3/envs/fastapi/lib/python3.6/site-packages/h11/_connection.py", line 467, in next_event
    event = self._extract_next_receive_event()
  File "/home/wzkariampuzha/anaconda3/envs/fastapi/lib/python3.6/site-packages/h11/_connection.py", line 409, in _extract_next_receive_event
    event = self._reader(self._receive_buffer)
  File "/home/wzkariampuzha/anaconda3/envs/fastapi/lib/python3.6/site-packages/h11/_readers.py", line 86, in maybe_read_from_IDLE_client
    request_line_re, lines[0], "illegal request line: {!r}", lines[0]
  File "/home/wzkariampuzha/anaconda3/envs/fastapi/lib/python3.6/site-packages/h11/_util.py", line 91, in validate
    raise LocalProtocolError(msg)
h11._util.RemoteProtocolError: illegal request line: bytearray(b'SM')
2022-06-07 01:59:58.943 WARNING uvicorn.error: Invalid HTTP request received.
Traceback (most recent call last):
  File "/home/wzkariampuzha/anaconda3/envs/fastapi/lib/python3.6/site-packages/starlette/exceptions.py", line 82, in __call__
    await self.app(scope, receive, sender)
  File "/home/wzkariampuzha/anaconda3/envs/fastapi/lib/python3.6/site-packages/fastapi/middleware/asyncexitstack.py", line 21, in __call__
    raise e
  File "/home/wzkariampuzha/anaconda3/envs/fastapi/lib/python3.6/site-packages/fastapi/middleware/asyncexitstack.py", line 18, in __call__
    await self.app(scope, receive, send)
  File "/home/wzkariampuzha/anaconda3/envs/fastapi/lib/python3.6/site-packages/starlette/routing.py", line 699, in __call__
    await self.default(scope, receive, send)
  File "/home/wzkariampuzha/anaconda3/envs/fastapi/lib/python3.6/site-packages/starlette/routing.py", line 593, in not_found
    raise HTTPException(status_code=404)
starlette.exceptions.HTTPException

During handling of the above exception, another exception occurred:

Traceback (most recent call last):
  File "/home/wzkariampuzha/anaconda3/envs/fastapi/lib/python3.6/site-packages/uvicorn/protocols/http/h11_impl.py", line 136, in handle_events
    event = self.conn.next_event()
  File "/home/wzkariampuzha/anaconda3/envs/fastapi/lib/python3.6/site-packages/h11/_connection.py", line 485, in next_event
    exc._reraise_as_remote_protocol_error()
  File "/home/wzkariampuzha/anaconda3/envs/fastapi/lib/python3.6/site-packages/h11/_util.py", line 77, in _reraise_as_remote_protocol_error
    raise self
  File "/home/wzkariampuzha/anaconda3/envs/fastapi/lib/python3.6/site-packages/h11/_connection.py", line 467, in next_event
    event = self._extract_next_receive_event()
  File "/home/wzkariampuzha/anaconda3/envs/fastapi/lib/python3.6/site-packages/h11/_connection.py", line 409, in _extract_next_receive_event
    event = self._reader(self._receive_buffer)
  File "/home/wzkariampuzha/anaconda3/envs/fastapi/lib/python3.6/site-packages/h11/_readers.py", line 86, in maybe_read_from_IDLE_client
    request_line_re, lines[0], "illegal request line: {!r}", lines[0]
  File "/home/wzkariampuzha/anaconda3/envs/fastapi/lib/python3.6/site-packages/h11/_util.py", line 91, in validate
    raise LocalProtocolError(msg)
h11._util.RemoteProtocolError: illegal request line: bytearray(b'SM')
INFO:     167.94.138.46:59598 - "GET / HTTP/1.1" 200 OK
INFO:     167.94.138.46:58434 - "GET / HTTP/1.1" 200 OK
INFO:     167.94.138.46:60434 - "PRI %2A HTTP/2.0" 404 Not Found
WARNING:  Invalid HTTP request received.
Traceback (most recent call last):
  File "/home/wzkariampuzha/anaconda3/envs/fastapi/lib/python3.6/site-packages/starlette/exceptions.py", line 82, in __call__
    await self.app(scope, receive, sender)
  File "/home/wzkariampuzha/anaconda3/envs/fastapi/lib/python3.6/site-packages/fastapi/middleware/asyncexitstack.py", line 21, in __call__
    raise e
  File "/home/wzkariampuzha/anaconda3/envs/fastapi/lib/python3.6/site-packages/fastapi/middleware/asyncexitstack.py", line 18, in __call__
    await self.app(scope, receive, send)
  File "/home/wzkariampuzha/anaconda3/envs/fastapi/lib/python3.6/site-packages/starlette/routing.py", line 699, in __call__
    await self.default(scope, receive, send)
  File "/home/wzkariampuzha/anaconda3/envs/fastapi/lib/python3.6/site-packages/starlette/routing.py", line 593, in not_found
    raise HTTPException(status_code=404)
starlette.exceptions.HTTPException

During handling of the above exception, another exception occurred:

Traceback (most recent call last):
  File "/home/wzkariampuzha/anaconda3/envs/fastapi/lib/python3.6/site-packages/uvicorn/protocols/http/h11_impl.py", line 136, in handle_events
    event = self.conn.next_event()
  File "/home/wzkariampuzha/anaconda3/envs/fastapi/lib/python3.6/site-packages/h11/_connection.py", line 485, in next_event
    exc._reraise_as_remote_protocol_error()
  File "/home/wzkariampuzha/anaconda3/envs/fastapi/lib/python3.6/site-packages/h11/_util.py", line 77, in _reraise_as_remote_protocol_error
    raise self
  File "/home/wzkariampuzha/anaconda3/envs/fastapi/lib/python3.6/site-packages/h11/_connection.py", line 467, in next_event
    event = self._extract_next_receive_event()
  File "/home/wzkariampuzha/anaconda3/envs/fastapi/lib/python3.6/site-packages/h11/_connection.py", line 409, in _extract_next_receive_event
    event = self._reader(self._receive_buffer)
  File "/home/wzkariampuzha/anaconda3/envs/fastapi/lib/python3.6/site-packages/h11/_readers.py", line 86, in maybe_read_from_IDLE_client
    request_line_re, lines[0], "illegal request line: {!r}", lines[0]
  File "/home/wzkariampuzha/anaconda3/envs/fastapi/lib/python3.6/site-packages/h11/_util.py", line 91, in validate
    raise LocalProtocolError(msg)
h11._util.RemoteProtocolError: illegal request line: bytearray(b'SM')
2022-06-07 10:19:27.945 WARNING uvicorn.error: Invalid HTTP request received.
Traceback (most recent call last):
  File "/home/wzkariampuzha/anaconda3/envs/fastapi/lib/python3.6/site-packages/starlette/exceptions.py", line 82, in __call__
    await self.app(scope, receive, sender)
  File "/home/wzkariampuzha/anaconda3/envs/fastapi/lib/python3.6/site-packages/fastapi/middleware/asyncexitstack.py", line 21, in __call__
    raise e
  File "/home/wzkariampuzha/anaconda3/envs/fastapi/lib/python3.6/site-packages/fastapi/middleware/asyncexitstack.py", line 18, in __call__
    await self.app(scope, receive, send)
  File "/home/wzkariampuzha/anaconda3/envs/fastapi/lib/python3.6/site-packages/starlette/routing.py", line 699, in __call__
    await self.default(scope, receive, send)
  File "/home/wzkariampuzha/anaconda3/envs/fastapi/lib/python3.6/site-packages/starlette/routing.py", line 593, in not_found
    raise HTTPException(status_code=404)
starlette.exceptions.HTTPException

During handling of the above exception, another exception occurred:

Traceback (most recent call last):
  File "/home/wzkariampuzha/anaconda3/envs/fastapi/lib/python3.6/site-packages/uvicorn/protocols/http/h11_impl.py", line 136, in handle_events
    event = self.conn.next_event()
  File "/home/wzkariampuzha/anaconda3/envs/fastapi/lib/python3.6/site-packages/h11/_connection.py", line 485, in next_event
    exc._reraise_as_remote_protocol_error()
  File "/home/wzkariampuzha/anaconda3/envs/fastapi/lib/python3.6/site-packages/h11/_util.py", line 77, in _reraise_as_remote_protocol_error
    raise self
  File "/home/wzkariampuzha/anaconda3/envs/fastapi/lib/python3.6/site-packages/h11/_connection.py", line 467, in next_event
    event = self._extract_next_receive_event()
  File "/home/wzkariampuzha/anaconda3/envs/fastapi/lib/python3.6/site-packages/h11/_connection.py", line 409, in _extract_next_receive_event
    event = self._reader(self._receive_buffer)
  File "/home/wzkariampuzha/anaconda3/envs/fastapi/lib/python3.6/site-packages/h11/_readers.py", line 86, in maybe_read_from_IDLE_client
    request_line_re, lines[0], "illegal request line: {!r}", lines[0]
  File "/home/wzkariampuzha/anaconda3/envs/fastapi/lib/python3.6/site-packages/h11/_util.py", line 91, in validate
    raise LocalProtocolError(msg)
h11._util.RemoteProtocolError: illegal request line: bytearray(b'SM')
INFO:     167.248.133.63:34496 - "GET / HTTP/1.1" 200 OK
INFO:     167.248.133.63:56234 - "GET / HTTP/1.1" 200 OK
INFO:     167.248.133.63:56992 - "PRI %2A HTTP/2.0" 404 Not Found
WARNING:  Invalid HTTP request received.
Traceback (most recent call last):
  File "/home/wzkariampuzha/anaconda3/envs/fastapi/lib/python3.6/site-packages/starlette/exceptions.py", line 82, in __call__
    await self.app(scope, receive, sender)
  File "/home/wzkariampuzha/anaconda3/envs/fastapi/lib/python3.6/site-packages/fastapi/middleware/asyncexitstack.py", line 21, in __call__
    raise e
  File "/home/wzkariampuzha/anaconda3/envs/fastapi/lib/python3.6/site-packages/fastapi/middleware/asyncexitstack.py", line 18, in __call__
    await self.app(scope, receive, send)
  File "/home/wzkariampuzha/anaconda3/envs/fastapi/lib/python3.6/site-packages/starlette/routing.py", line 699, in __call__
    await self.default(scope, receive, send)
  File "/home/wzkariampuzha/anaconda3/envs/fastapi/lib/python3.6/site-packages/starlette/routing.py", line 593, in not_found
    raise HTTPException(status_code=404)
starlette.exceptions.HTTPException

During handling of the above exception, another exception occurred:

Traceback (most recent call last):
  File "/home/wzkariampuzha/anaconda3/envs/fastapi/lib/python3.6/site-packages/uvicorn/protocols/http/h11_impl.py", line 136, in handle_events
    event = self.conn.next_event()
  File "/home/wzkariampuzha/anaconda3/envs/fastapi/lib/python3.6/site-packages/h11/_connection.py", line 485, in next_event
    exc._reraise_as_remote_protocol_error()
  File "/home/wzkariampuzha/anaconda3/envs/fastapi/lib/python3.6/site-packages/h11/_util.py", line 77, in _reraise_as_remote_protocol_error
    raise self
  File "/home/wzkariampuzha/anaconda3/envs/fastapi/lib/python3.6/site-packages/h11/_connection.py", line 467, in next_event
    event = self._extract_next_receive_event()
  File "/home/wzkariampuzha/anaconda3/envs/fastapi/lib/python3.6/site-packages/h11/_connection.py", line 409, in _extract_next_receive_event
    event = self._reader(self._receive_buffer)
  File "/home/wzkariampuzha/anaconda3/envs/fastapi/lib/python3.6/site-packages/h11/_readers.py", line 86, in maybe_read_from_IDLE_client
    request_line_re, lines[0], "illegal request line: {!r}", lines[0]
  File "/home/wzkariampuzha/anaconda3/envs/fastapi/lib/python3.6/site-packages/h11/_util.py", line 91, in validate
    raise LocalProtocolError(msg)
h11._util.RemoteProtocolError: illegal request line: bytearray(b'SM')
2022-06-08 00:25:56.688 WARNING uvicorn.error: Invalid HTTP request received.
Traceback (most recent call last):
  File "/home/wzkariampuzha/anaconda3/envs/fastapi/lib/python3.6/site-packages/starlette/exceptions.py", line 82, in __call__
    await self.app(scope, receive, sender)
  File "/home/wzkariampuzha/anaconda3/envs/fastapi/lib/python3.6/site-packages/fastapi/middleware/asyncexitstack.py", line 21, in __call__
    raise e
  File "/home/wzkariampuzha/anaconda3/envs/fastapi/lib/python3.6/site-packages/fastapi/middleware/asyncexitstack.py", line 18, in __call__
    await self.app(scope, receive, send)
  File "/home/wzkariampuzha/anaconda3/envs/fastapi/lib/python3.6/site-packages/starlette/routing.py", line 699, in __call__
    await self.default(scope, receive, send)
  File "/home/wzkariampuzha/anaconda3/envs/fastapi/lib/python3.6/site-packages/starlette/routing.py", line 593, in not_found
    raise HTTPException(status_code=404)
starlette.exceptions.HTTPException

During handling of the above exception, another exception occurred:

Traceback (most recent call last):
  File "/home/wzkariampuzha/anaconda3/envs/fastapi/lib/python3.6/site-packages/uvicorn/protocols/http/h11_impl.py", line 136, in handle_events
    event = self.conn.next_event()
  File "/home/wzkariampuzha/anaconda3/envs/fastapi/lib/python3.6/site-packages/h11/_connection.py", line 485, in next_event
    exc._reraise_as_remote_protocol_error()
  File "/home/wzkariampuzha/anaconda3/envs/fastapi/lib/python3.6/site-packages/h11/_util.py", line 77, in _reraise_as_remote_protocol_error
    raise self
  File "/home/wzkariampuzha/anaconda3/envs/fastapi/lib/python3.6/site-packages/h11/_connection.py", line 467, in next_event
    event = self._extract_next_receive_event()
  File "/home/wzkariampuzha/anaconda3/envs/fastapi/lib/python3.6/site-packages/h11/_connection.py", line 409, in _extract_next_receive_event
    event = self._reader(self._receive_buffer)
  File "/home/wzkariampuzha/anaconda3/envs/fastapi/lib/python3.6/site-packages/h11/_readers.py", line 86, in maybe_read_from_IDLE_client
    request_line_re, lines[0], "illegal request line: {!r}", lines[0]
  File "/home/wzkariampuzha/anaconda3/envs/fastapi/lib/python3.6/site-packages/h11/_util.py", line 91, in validate
    raise LocalProtocolError(msg)
h11._util.RemoteProtocolError: illegal request line: bytearray(b'SM')
INFO:     162.142.125.219:60508 - "GET / HTTP/1.1" 200 OK
INFO:     162.142.125.219:37600 - "GET / HTTP/1.1" 200 OK
INFO:     162.142.125.219:40300 - "PRI %2A HTTP/2.0" 404 Not Found
WARNING:  Invalid HTTP request received.
Traceback (most recent call last):
  File "/home/wzkariampuzha/anaconda3/envs/fastapi/lib/python3.6/site-packages/starlette/exceptions.py", line 82, in __call__
    await self.app(scope, receive, sender)
  File "/home/wzkariampuzha/anaconda3/envs/fastapi/lib/python3.6/site-packages/fastapi/middleware/asyncexitstack.py", line 21, in __call__
    raise e
  File "/home/wzkariampuzha/anaconda3/envs/fastapi/lib/python3.6/site-packages/fastapi/middleware/asyncexitstack.py", line 18, in __call__
    await self.app(scope, receive, send)
  File "/home/wzkariampuzha/anaconda3/envs/fastapi/lib/python3.6/site-packages/starlette/routing.py", line 699, in __call__
    await self.default(scope, receive, send)
  File "/home/wzkariampuzha/anaconda3/envs/fastapi/lib/python3.6/site-packages/starlette/routing.py", line 593, in not_found
    raise HTTPException(status_code=404)
starlette.exceptions.HTTPException

During handling of the above exception, another exception occurred:

Traceback (most recent call last):
  File "/home/wzkariampuzha/anaconda3/envs/fastapi/lib/python3.6/site-packages/uvicorn/protocols/http/h11_impl.py", line 136, in handle_events
    event = self.conn.next_event()
  File "/home/wzkariampuzha/anaconda3/envs/fastapi/lib/python3.6/site-packages/h11/_connection.py", line 485, in next_event
    exc._reraise_as_remote_protocol_error()
  File "/home/wzkariampuzha/anaconda3/envs/fastapi/lib/python3.6/site-packages/h11/_util.py", line 77, in _reraise_as_remote_protocol_error
    raise self
  File "/home/wzkariampuzha/anaconda3/envs/fastapi/lib/python3.6/site-packages/h11/_connection.py", line 467, in next_event
    event = self._extract_next_receive_event()
  File "/home/wzkariampuzha/anaconda3/envs/fastapi/lib/python3.6/site-packages/h11/_connection.py", line 409, in _extract_next_receive_event
    event = self._reader(self._receive_buffer)
  File "/home/wzkariampuzha/anaconda3/envs/fastapi/lib/python3.6/site-packages/h11/_readers.py", line 86, in maybe_read_from_IDLE_client
    request_line_re, lines[0], "illegal request line: {!r}", lines[0]
  File "/home/wzkariampuzha/anaconda3/envs/fastapi/lib/python3.6/site-packages/h11/_util.py", line 91, in validate
    raise LocalProtocolError(msg)
h11._util.RemoteProtocolError: illegal request line: bytearray(b'SM')
2022-06-08 07:24:55.246 WARNING uvicorn.error: Invalid HTTP request received.
Traceback (most recent call last):
  File "/home/wzkariampuzha/anaconda3/envs/fastapi/lib/python3.6/site-packages/starlette/exceptions.py", line 82, in __call__
    await self.app(scope, receive, sender)
  File "/home/wzkariampuzha/anaconda3/envs/fastapi/lib/python3.6/site-packages/fastapi/middleware/asyncexitstack.py", line 21, in __call__
    raise e
  File "/home/wzkariampuzha/anaconda3/envs/fastapi/lib/python3.6/site-packages/fastapi/middleware/asyncexitstack.py", line 18, in __call__
    await self.app(scope, receive, send)
  File "/home/wzkariampuzha/anaconda3/envs/fastapi/lib/python3.6/site-packages/starlette/routing.py", line 699, in __call__
    await self.default(scope, receive, send)
  File "/home/wzkariampuzha/anaconda3/envs/fastapi/lib/python3.6/site-packages/starlette/routing.py", line 593, in not_found
    raise HTTPException(status_code=404)
starlette.exceptions.HTTPException

During handling of the above exception, another exception occurred:

Traceback (most recent call last):
  File "/home/wzkariampuzha/anaconda3/envs/fastapi/lib/python3.6/site-packages/uvicorn/protocols/http/h11_impl.py", line 136, in handle_events
    event = self.conn.next_event()
  File "/home/wzkariampuzha/anaconda3/envs/fastapi/lib/python3.6/site-packages/h11/_connection.py", line 485, in next_event
    exc._reraise_as_remote_protocol_error()
  File "/home/wzkariampuzha/anaconda3/envs/fastapi/lib/python3.6/site-packages/h11/_util.py", line 77, in _reraise_as_remote_protocol_error
    raise self
  File "/home/wzkariampuzha/anaconda3/envs/fastapi/lib/python3.6/site-packages/h11/_connection.py", line 467, in next_event
    event = self._extract_next_receive_event()
  File "/home/wzkariampuzha/anaconda3/envs/fastapi/lib/python3.6/site-packages/h11/_connection.py", line 409, in _extract_next_receive_event
    event = self._reader(self._receive_buffer)
  File "/home/wzkariampuzha/anaconda3/envs/fastapi/lib/python3.6/site-packages/h11/_readers.py", line 86, in maybe_read_from_IDLE_client
    request_line_re, lines[0], "illegal request line: {!r}", lines[0]
  File "/home/wzkariampuzha/anaconda3/envs/fastapi/lib/python3.6/site-packages/h11/_util.py", line 91, in validate
    raise LocalProtocolError(msg)
h11._util.RemoteProtocolError: illegal request line: bytearray(b'SM')
INFO:     192.241.219.159:35184 - "GET / HTTP/1.1" 200 OK
INFO:     47.219.10.126:49534 - "GET /docs HTTP/1.1" 200 OK
INFO:     47.219.10.126:49534 - "GET /openapi.json HTTP/1.1" 200 OK
INFO:     40.77.167.10:14912 - "GET /docs HTTP/1.1" 200 OK
INFO:     104.180.137.126:61211 - "GET /docs HTTP/1.1" 200 OK
INFO:     104.180.137.126:61211 - "GET /openapi.json HTTP/1.1" 200 OK
INFO:     73.207.102.233:52091 - "GET /docs HTTP/1.1" 200 OK
INFO:     73.207.102.233:52091 - "GET /openapi.json HTTP/1.1" 200 OK
INFO:     104.180.137.126:61235 - "GET /docs HTTP/1.1" 200 OK
INFO:     104.180.137.126:61235 - "GET /openapi.json HTTP/1.1" 200 OK
INFO:     104.180.137.126:61235 - "GET / HTTP/1.1" 200 OK
INFO:     104.180.137.126:61235 - "GET /favicon.ico HTTP/1.1" 404 Not Found
INFO:     104.180.137.126:61235 - "GET / HTTP/1.1" 200 OK
INFO:     73.207.102.233:52388 - "GET /docs HTTP/1.1" 200 OK
INFO:     73.207.102.233:52388 - "GET /openapi.json HTTP/1.1" 200 OK
INFO:     104.180.137.126:62216 - "GET /docs HTTP/1.1" 200 OK
INFO:     104.180.137.126:62216 - "GET /openapi.json HTTP/1.1" 200 OK
INFO:     162.142.125.222:34588 - "GET / HTTP/1.1" 200 OK
INFO:     162.142.125.222:46904 - "GET / HTTP/1.1" 200 OK
INFO:     162.142.125.222:50014 - "PRI %2A HTTP/2.0" 404 Not Found
WARNING:  Invalid HTTP request received.
Traceback (most recent call last):
  File "/home/wzkariampuzha/anaconda3/envs/fastapi/lib/python3.6/site-packages/starlette/exceptions.py", line 82, in __call__
    await self.app(scope, receive, sender)
  File "/home/wzkariampuzha/anaconda3/envs/fastapi/lib/python3.6/site-packages/fastapi/middleware/asyncexitstack.py", line 21, in __call__
    raise e
  File "/home/wzkariampuzha/anaconda3/envs/fastapi/lib/python3.6/site-packages/fastapi/middleware/asyncexitstack.py", line 18, in __call__
    await self.app(scope, receive, send)
  File "/home/wzkariampuzha/anaconda3/envs/fastapi/lib/python3.6/site-packages/starlette/routing.py", line 699, in __call__
    await self.default(scope, receive, send)
  File "/home/wzkariampuzha/anaconda3/envs/fastapi/lib/python3.6/site-packages/starlette/routing.py", line 593, in not_found
    raise HTTPException(status_code=404)
starlette.exceptions.HTTPException

During handling of the above exception, another exception occurred:

Traceback (most recent call last):
  File "/home/wzkariampuzha/anaconda3/envs/fastapi/lib/python3.6/site-packages/uvicorn/protocols/http/h11_impl.py", line 136, in handle_events
    event = self.conn.next_event()
  File "/home/wzkariampuzha/anaconda3/envs/fastapi/lib/python3.6/site-packages/h11/_connection.py", line 485, in next_event
    exc._reraise_as_remote_protocol_error()
  File "/home/wzkariampuzha/anaconda3/envs/fastapi/lib/python3.6/site-packages/h11/_util.py", line 77, in _reraise_as_remote_protocol_error
    raise self
  File "/home/wzkariampuzha/anaconda3/envs/fastapi/lib/python3.6/site-packages/h11/_connection.py", line 467, in next_event
    event = self._extract_next_receive_event()
  File "/home/wzkariampuzha/anaconda3/envs/fastapi/lib/python3.6/site-packages/h11/_connection.py", line 409, in _extract_next_receive_event
    event = self._reader(self._receive_buffer)
  File "/home/wzkariampuzha/anaconda3/envs/fastapi/lib/python3.6/site-packages/h11/_readers.py", line 86, in maybe_read_from_IDLE_client
    request_line_re, lines[0], "illegal request line: {!r}", lines[0]
  File "/home/wzkariampuzha/anaconda3/envs/fastapi/lib/python3.6/site-packages/h11/_util.py", line 91, in validate
    raise LocalProtocolError(msg)
h11._util.RemoteProtocolError: illegal request line: bytearray(b'SM')
2022-06-08 19:29:48.043 WARNING uvicorn.error: Invalid HTTP request received.
Traceback (most recent call last):
  File "/home/wzkariampuzha/anaconda3/envs/fastapi/lib/python3.6/site-packages/starlette/exceptions.py", line 82, in __call__
    await self.app(scope, receive, sender)
  File "/home/wzkariampuzha/anaconda3/envs/fastapi/lib/python3.6/site-packages/fastapi/middleware/asyncexitstack.py", line 21, in __call__
    raise e
  File "/home/wzkariampuzha/anaconda3/envs/fastapi/lib/python3.6/site-packages/fastapi/middleware/asyncexitstack.py", line 18, in __call__
    await self.app(scope, receive, send)
  File "/home/wzkariampuzha/anaconda3/envs/fastapi/lib/python3.6/site-packages/starlette/routing.py", line 699, in __call__
    await self.default(scope, receive, send)
  File "/home/wzkariampuzha/anaconda3/envs/fastapi/lib/python3.6/site-packages/starlette/routing.py", line 593, in not_found
    raise HTTPException(status_code=404)
starlette.exceptions.HTTPException

During handling of the above exception, another exception occurred:

Traceback (most recent call last):
  File "/home/wzkariampuzha/anaconda3/envs/fastapi/lib/python3.6/site-packages/uvicorn/protocols/http/h11_impl.py", line 136, in handle_events
    event = self.conn.next_event()
  File "/home/wzkariampuzha/anaconda3/envs/fastapi/lib/python3.6/site-packages/h11/_connection.py", line 485, in next_event
    exc._reraise_as_remote_protocol_error()
  File "/home/wzkariampuzha/anaconda3/envs/fastapi/lib/python3.6/site-packages/h11/_util.py", line 77, in _reraise_as_remote_protocol_error
    raise self
  File "/home/wzkariampuzha/anaconda3/envs/fastapi/lib/python3.6/site-packages/h11/_connection.py", line 467, in next_event
    event = self._extract_next_receive_event()
  File "/home/wzkariampuzha/anaconda3/envs/fastapi/lib/python3.6/site-packages/h11/_connection.py", line 409, in _extract_next_receive_event
    event = self._reader(self._receive_buffer)
  File "/home/wzkariampuzha/anaconda3/envs/fastapi/lib/python3.6/site-packages/h11/_readers.py", line 86, in maybe_read_from_IDLE_client
    request_line_re, lines[0], "illegal request line: {!r}", lines[0]
  File "/home/wzkariampuzha/anaconda3/envs/fastapi/lib/python3.6/site-packages/h11/_util.py", line 91, in validate
    raise LocalProtocolError(msg)
h11._util.RemoteProtocolError: illegal request line: bytearray(b'SM')
INFO:     167.94.145.59:45170 - "GET / HTTP/1.1" 200 OK
INFO:     167.94.145.59:52522 - "GET / HTTP/1.1" 200 OK
INFO:     167.94.145.59:60144 - "PRI %2A HTTP/2.0" 404 Not Found
WARNING:  Invalid HTTP request received.
Traceback (most recent call last):
  File "/home/wzkariampuzha/anaconda3/envs/fastapi/lib/python3.6/site-packages/starlette/exceptions.py", line 82, in __call__
    await self.app(scope, receive, sender)
  File "/home/wzkariampuzha/anaconda3/envs/fastapi/lib/python3.6/site-packages/fastapi/middleware/asyncexitstack.py", line 21, in __call__
    raise e
  File "/home/wzkariampuzha/anaconda3/envs/fastapi/lib/python3.6/site-packages/fastapi/middleware/asyncexitstack.py", line 18, in __call__
    await self.app(scope, receive, send)
  File "/home/wzkariampuzha/anaconda3/envs/fastapi/lib/python3.6/site-packages/starlette/routing.py", line 699, in __call__
    await self.default(scope, receive, send)
  File "/home/wzkariampuzha/anaconda3/envs/fastapi/lib/python3.6/site-packages/starlette/routing.py", line 593, in not_found
    raise HTTPException(status_code=404)
starlette.exceptions.HTTPException

During handling of the above exception, another exception occurred:

Traceback (most recent call last):
  File "/home/wzkariampuzha/anaconda3/envs/fastapi/lib/python3.6/site-packages/uvicorn/protocols/http/h11_impl.py", line 136, in handle_events
    event = self.conn.next_event()
  File "/home/wzkariampuzha/anaconda3/envs/fastapi/lib/python3.6/site-packages/h11/_connection.py", line 485, in next_event
    exc._reraise_as_remote_protocol_error()
  File "/home/wzkariampuzha/anaconda3/envs/fastapi/lib/python3.6/site-packages/h11/_util.py", line 77, in _reraise_as_remote_protocol_error
    raise self
  File "/home/wzkariampuzha/anaconda3/envs/fastapi/lib/python3.6/site-packages/h11/_connection.py", line 467, in next_event
    event = self._extract_next_receive_event()
  File "/home/wzkariampuzha/anaconda3/envs/fastapi/lib/python3.6/site-packages/h11/_connection.py", line 409, in _extract_next_receive_event
    event = self._reader(self._receive_buffer)
  File "/home/wzkariampuzha/anaconda3/envs/fastapi/lib/python3.6/site-packages/h11/_readers.py", line 86, in maybe_read_from_IDLE_client
    request_line_re, lines[0], "illegal request line: {!r}", lines[0]
  File "/home/wzkariampuzha/anaconda3/envs/fastapi/lib/python3.6/site-packages/h11/_util.py", line 91, in validate
    raise LocalProtocolError(msg)
h11._util.RemoteProtocolError: illegal request line: bytearray(b'SM')
2022-06-08 21:18:05.799 WARNING uvicorn.error: Invalid HTTP request received.
Traceback (most recent call last):
  File "/home/wzkariampuzha/anaconda3/envs/fastapi/lib/python3.6/site-packages/starlette/exceptions.py", line 82, in __call__
    await self.app(scope, receive, sender)
  File "/home/wzkariampuzha/anaconda3/envs/fastapi/lib/python3.6/site-packages/fastapi/middleware/asyncexitstack.py", line 21, in __call__
    raise e
  File "/home/wzkariampuzha/anaconda3/envs/fastapi/lib/python3.6/site-packages/fastapi/middleware/asyncexitstack.py", line 18, in __call__
    await self.app(scope, receive, send)
  File "/home/wzkariampuzha/anaconda3/envs/fastapi/lib/python3.6/site-packages/starlette/routing.py", line 699, in __call__
    await self.default(scope, receive, send)
  File "/home/wzkariampuzha/anaconda3/envs/fastapi/lib/python3.6/site-packages/starlette/routing.py", line 593, in not_found
    raise HTTPException(status_code=404)
starlette.exceptions.HTTPException

During handling of the above exception, another exception occurred:

Traceback (most recent call last):
  File "/home/wzkariampuzha/anaconda3/envs/fastapi/lib/python3.6/site-packages/uvicorn/protocols/http/h11_impl.py", line 136, in handle_events
    event = self.conn.next_event()
  File "/home/wzkariampuzha/anaconda3/envs/fastapi/lib/python3.6/site-packages/h11/_connection.py", line 485, in next_event
    exc._reraise_as_remote_protocol_error()
  File "/home/wzkariampuzha/anaconda3/envs/fastapi/lib/python3.6/site-packages/h11/_util.py", line 77, in _reraise_as_remote_protocol_error
    raise self
  File "/home/wzkariampuzha/anaconda3/envs/fastapi/lib/python3.6/site-packages/h11/_connection.py", line 467, in next_event
    event = self._extract_next_receive_event()
  File "/home/wzkariampuzha/anaconda3/envs/fastapi/lib/python3.6/site-packages/h11/_connection.py", line 409, in _extract_next_receive_event
    event = self._reader(self._receive_buffer)
  File "/home/wzkariampuzha/anaconda3/envs/fastapi/lib/python3.6/site-packages/h11/_readers.py", line 86, in maybe_read_from_IDLE_client
    request_line_re, lines[0], "illegal request line: {!r}", lines[0]
  File "/home/wzkariampuzha/anaconda3/envs/fastapi/lib/python3.6/site-packages/h11/_util.py", line 91, in validate
    raise LocalProtocolError(msg)
h11._util.RemoteProtocolError: illegal request line: bytearray(b'SM')
INFO:     167.94.146.57:49070 - "GET / HTTP/1.1" 200 OK
INFO:     167.94.146.57:54832 - "GET / HTTP/1.1" 200 OK
INFO:     167.94.146.57:34188 - "PRI %2A HTTP/2.0" 404 Not Found
WARNING:  Invalid HTTP request received.
Traceback (most recent call last):
  File "/home/wzkariampuzha/anaconda3/envs/fastapi/lib/python3.6/site-packages/starlette/exceptions.py", line 82, in __call__
    await self.app(scope, receive, sender)
  File "/home/wzkariampuzha/anaconda3/envs/fastapi/lib/python3.6/site-packages/fastapi/middleware/asyncexitstack.py", line 21, in __call__
    raise e
  File "/home/wzkariampuzha/anaconda3/envs/fastapi/lib/python3.6/site-packages/fastapi/middleware/asyncexitstack.py", line 18, in __call__
    await self.app(scope, receive, send)
  File "/home/wzkariampuzha/anaconda3/envs/fastapi/lib/python3.6/site-packages/starlette/routing.py", line 699, in __call__
    await self.default(scope, receive, send)
  File "/home/wzkariampuzha/anaconda3/envs/fastapi/lib/python3.6/site-packages/starlette/routing.py", line 593, in not_found
    raise HTTPException(status_code=404)
starlette.exceptions.HTTPException

During handling of the above exception, another exception occurred:

Traceback (most recent call last):
  File "/home/wzkariampuzha/anaconda3/envs/fastapi/lib/python3.6/site-packages/uvicorn/protocols/http/h11_impl.py", line 136, in handle_events
    event = self.conn.next_event()
  File "/home/wzkariampuzha/anaconda3/envs/fastapi/lib/python3.6/site-packages/h11/_connection.py", line 485, in next_event
    exc._reraise_as_remote_protocol_error()
  File "/home/wzkariampuzha/anaconda3/envs/fastapi/lib/python3.6/site-packages/h11/_util.py", line 77, in _reraise_as_remote_protocol_error
    raise self
  File "/home/wzkariampuzha/anaconda3/envs/fastapi/lib/python3.6/site-packages/h11/_connection.py", line 467, in next_event
    event = self._extract_next_receive_event()
  File "/home/wzkariampuzha/anaconda3/envs/fastapi/lib/python3.6/site-packages/h11/_connection.py", line 409, in _extract_next_receive_event
    event = self._reader(self._receive_buffer)
  File "/home/wzkariampuzha/anaconda3/envs/fastapi/lib/python3.6/site-packages/h11/_readers.py", line 86, in maybe_read_from_IDLE_client
    request_line_re, lines[0], "illegal request line: {!r}", lines[0]
  File "/home/wzkariampuzha/anaconda3/envs/fastapi/lib/python3.6/site-packages/h11/_util.py", line 91, in validate
    raise LocalProtocolError(msg)
h11._util.RemoteProtocolError: illegal request line: bytearray(b'SM')
2022-06-09 08:54:15.498 WARNING uvicorn.error: Invalid HTTP request received.
Traceback (most recent call last):
  File "/home/wzkariampuzha/anaconda3/envs/fastapi/lib/python3.6/site-packages/starlette/exceptions.py", line 82, in __call__
    await self.app(scope, receive, sender)
  File "/home/wzkariampuzha/anaconda3/envs/fastapi/lib/python3.6/site-packages/fastapi/middleware/asyncexitstack.py", line 21, in __call__
    raise e
  File "/home/wzkariampuzha/anaconda3/envs/fastapi/lib/python3.6/site-packages/fastapi/middleware/asyncexitstack.py", line 18, in __call__
    await self.app(scope, receive, send)
  File "/home/wzkariampuzha/anaconda3/envs/fastapi/lib/python3.6/site-packages/starlette/routing.py", line 699, in __call__
    await self.default(scope, receive, send)
  File "/home/wzkariampuzha/anaconda3/envs/fastapi/lib/python3.6/site-packages/starlette/routing.py", line 593, in not_found
    raise HTTPException(status_code=404)
starlette.exceptions.HTTPException

During handling of the above exception, another exception occurred:

Traceback (most recent call last):
  File "/home/wzkariampuzha/anaconda3/envs/fastapi/lib/python3.6/site-packages/uvicorn/protocols/http/h11_impl.py", line 136, in handle_events
    event = self.conn.next_event()
  File "/home/wzkariampuzha/anaconda3/envs/fastapi/lib/python3.6/site-packages/h11/_connection.py", line 485, in next_event
    exc._reraise_as_remote_protocol_error()
  File "/home/wzkariampuzha/anaconda3/envs/fastapi/lib/python3.6/site-packages/h11/_util.py", line 77, in _reraise_as_remote_protocol_error
    raise self
  File "/home/wzkariampuzha/anaconda3/envs/fastapi/lib/python3.6/site-packages/h11/_connection.py", line 467, in next_event
    event = self._extract_next_receive_event()
  File "/home/wzkariampuzha/anaconda3/envs/fastapi/lib/python3.6/site-packages/h11/_connection.py", line 409, in _extract_next_receive_event
    event = self._reader(self._receive_buffer)
  File "/home/wzkariampuzha/anaconda3/envs/fastapi/lib/python3.6/site-packages/h11/_readers.py", line 86, in maybe_read_from_IDLE_client
    request_line_re, lines[0], "illegal request line: {!r}", lines[0]
  File "/home/wzkariampuzha/anaconda3/envs/fastapi/lib/python3.6/site-packages/h11/_util.py", line 91, in validate
    raise LocalProtocolError(msg)
h11._util.RemoteProtocolError: illegal request line: bytearray(b'SM')
INFO:     73.207.102.233:49949 - "GET /openapi.json HTTP/1.1" 200 OK
INFO:     73.207.102.233:54658 - "GET / HTTP/1.1" 200 OK
INFO:     73.207.102.233:54658 - "GET / HTTP/1.1" 200 OK
INFO:     73.207.102.233:55531 - "GET /docs HTTP/1.1" 200 OK
INFO:     73.207.102.233:55531 - "GET /openapi.json HTTP/1.1" 200 OK
INFO:     192.241.209.85:50598 - "GET / HTTP/1.1" 200 OK
INFO:     162.142.125.221:54092 - "GET / HTTP/1.1" 200 OK
INFO:     162.142.125.221:39890 - "GET / HTTP/1.1" 200 OK
INFO:     162.142.125.221:43346 - "PRI %2A HTTP/2.0" 404 Not Found
WARNING:  Invalid HTTP request received.
Traceback (most recent call last):
  File "/home/wzkariampuzha/anaconda3/envs/fastapi/lib/python3.6/site-packages/starlette/exceptions.py", line 82, in __call__
    await self.app(scope, receive, sender)
  File "/home/wzkariampuzha/anaconda3/envs/fastapi/lib/python3.6/site-packages/fastapi/middleware/asyncexitstack.py", line 21, in __call__
    raise e
  File "/home/wzkariampuzha/anaconda3/envs/fastapi/lib/python3.6/site-packages/fastapi/middleware/asyncexitstack.py", line 18, in __call__
    await self.app(scope, receive, send)
  File "/home/wzkariampuzha/anaconda3/envs/fastapi/lib/python3.6/site-packages/starlette/routing.py", line 699, in __call__
    await self.default(scope, receive, send)
  File "/home/wzkariampuzha/anaconda3/envs/fastapi/lib/python3.6/site-packages/starlette/routing.py", line 593, in not_found
    raise HTTPException(status_code=404)
starlette.exceptions.HTTPException

During handling of the above exception, another exception occurred:

Traceback (most recent call last):
  File "/home/wzkariampuzha/anaconda3/envs/fastapi/lib/python3.6/site-packages/uvicorn/protocols/http/h11_impl.py", line 136, in handle_events
    event = self.conn.next_event()
  File "/home/wzkariampuzha/anaconda3/envs/fastapi/lib/python3.6/site-packages/h11/_connection.py", line 485, in next_event
    exc._reraise_as_remote_protocol_error()
  File "/home/wzkariampuzha/anaconda3/envs/fastapi/lib/python3.6/site-packages/h11/_util.py", line 77, in _reraise_as_remote_protocol_error
    raise self
  File "/home/wzkariampuzha/anaconda3/envs/fastapi/lib/python3.6/site-packages/h11/_connection.py", line 467, in next_event
    event = self._extract_next_receive_event()
  File "/home/wzkariampuzha/anaconda3/envs/fastapi/lib/python3.6/site-packages/h11/_connection.py", line 409, in _extract_next_receive_event
    event = self._reader(self._receive_buffer)
  File "/home/wzkariampuzha/anaconda3/envs/fastapi/lib/python3.6/site-packages/h11/_readers.py", line 86, in maybe_read_from_IDLE_client
    request_line_re, lines[0], "illegal request line: {!r}", lines[0]
  File "/home/wzkariampuzha/anaconda3/envs/fastapi/lib/python3.6/site-packages/h11/_util.py", line 91, in validate
    raise LocalProtocolError(msg)
h11._util.RemoteProtocolError: illegal request line: bytearray(b'SM')
2022-06-10 00:54:07.358 WARNING uvicorn.error: Invalid HTTP request received.
Traceback (most recent call last):
  File "/home/wzkariampuzha/anaconda3/envs/fastapi/lib/python3.6/site-packages/starlette/exceptions.py", line 82, in __call__
    await self.app(scope, receive, sender)
  File "/home/wzkariampuzha/anaconda3/envs/fastapi/lib/python3.6/site-packages/fastapi/middleware/asyncexitstack.py", line 21, in __call__
    raise e
  File "/home/wzkariampuzha/anaconda3/envs/fastapi/lib/python3.6/site-packages/fastapi/middleware/asyncexitstack.py", line 18, in __call__
    await self.app(scope, receive, send)
  File "/home/wzkariampuzha/anaconda3/envs/fastapi/lib/python3.6/site-packages/starlette/routing.py", line 699, in __call__
    await self.default(scope, receive, send)
  File "/home/wzkariampuzha/anaconda3/envs/fastapi/lib/python3.6/site-packages/starlette/routing.py", line 593, in not_found
    raise HTTPException(status_code=404)
starlette.exceptions.HTTPException

During handling of the above exception, another exception occurred:

Traceback (most recent call last):
  File "/home/wzkariampuzha/anaconda3/envs/fastapi/lib/python3.6/site-packages/uvicorn/protocols/http/h11_impl.py", line 136, in handle_events
    event = self.conn.next_event()
  File "/home/wzkariampuzha/anaconda3/envs/fastapi/lib/python3.6/site-packages/h11/_connection.py", line 485, in next_event
    exc._reraise_as_remote_protocol_error()
  File "/home/wzkariampuzha/anaconda3/envs/fastapi/lib/python3.6/site-packages/h11/_util.py", line 77, in _reraise_as_remote_protocol_error
    raise self
  File "/home/wzkariampuzha/anaconda3/envs/fastapi/lib/python3.6/site-packages/h11/_connection.py", line 467, in next_event
    event = self._extract_next_receive_event()
  File "/home/wzkariampuzha/anaconda3/envs/fastapi/lib/python3.6/site-packages/h11/_connection.py", line 409, in _extract_next_receive_event
    event = self._reader(self._receive_buffer)
  File "/home/wzkariampuzha/anaconda3/envs/fastapi/lib/python3.6/site-packages/h11/_readers.py", line 86, in maybe_read_from_IDLE_client
    request_line_re, lines[0], "illegal request line: {!r}", lines[0]
  File "/home/wzkariampuzha/anaconda3/envs/fastapi/lib/python3.6/site-packages/h11/_util.py", line 91, in validate
    raise LocalProtocolError(msg)
h11._util.RemoteProtocolError: illegal request line: bytearray(b'SM')
INFO:     47.219.10.126:50053 - "GET /docs HTTP/1.1" 200 OK
INFO:     47.219.10.126:50053 - "GET /openapi.json HTTP/1.1" 200 OK
INFO:     73.207.102.233:50207 - "GET /openapi.json HTTP/1.1" 200 OK
INFO:     73.207.102.233:58577 - "GET /docs HTTP/1.1" 200 OK
INFO:     73.207.102.233:58577 - "GET /openapi.json HTTP/1.1" 200 OK
INFO:     47.219.10.126:51835 - "GET /docs HTTP/1.1" 200 OK
INFO:     47.219.10.126:51835 - "GET /openapi.json HTTP/1.1" 200 OK
INFO:     167.94.138.45:54050 - "GET / HTTP/1.1" 200 OK
INFO:     167.94.138.45:50464 - "GET / HTTP/1.1" 200 OK
INFO:     167.94.138.45:52552 - "PRI %2A HTTP/2.0" 404 Not Found
WARNING:  Invalid HTTP request received.
Traceback (most recent call last):
  File "/home/wzkariampuzha/anaconda3/envs/fastapi/lib/python3.6/site-packages/starlette/exceptions.py", line 82, in __call__
    await self.app(scope, receive, sender)
  File "/home/wzkariampuzha/anaconda3/envs/fastapi/lib/python3.6/site-packages/fastapi/middleware/asyncexitstack.py", line 21, in __call__
    raise e
  File "/home/wzkariampuzha/anaconda3/envs/fastapi/lib/python3.6/site-packages/fastapi/middleware/asyncexitstack.py", line 18, in __call__
    await self.app(scope, receive, send)
  File "/home/wzkariampuzha/anaconda3/envs/fastapi/lib/python3.6/site-packages/starlette/routing.py", line 699, in __call__
    await self.default(scope, receive, send)
  File "/home/wzkariampuzha/anaconda3/envs/fastapi/lib/python3.6/site-packages/starlette/routing.py", line 593, in not_found
    raise HTTPException(status_code=404)
starlette.exceptions.HTTPException

During handling of the above exception, another exception occurred:

Traceback (most recent call last):
  File "/home/wzkariampuzha/anaconda3/envs/fastapi/lib/python3.6/site-packages/uvicorn/protocols/http/h11_impl.py", line 136, in handle_events
    event = self.conn.next_event()
  File "/home/wzkariampuzha/anaconda3/envs/fastapi/lib/python3.6/site-packages/h11/_connection.py", line 485, in next_event
    exc._reraise_as_remote_protocol_error()
  File "/home/wzkariampuzha/anaconda3/envs/fastapi/lib/python3.6/site-packages/h11/_util.py", line 77, in _reraise_as_remote_protocol_error
    raise self
  File "/home/wzkariampuzha/anaconda3/envs/fastapi/lib/python3.6/site-packages/h11/_connection.py", line 467, in next_event
    event = self._extract_next_receive_event()
  File "/home/wzkariampuzha/anaconda3/envs/fastapi/lib/python3.6/site-packages/h11/_connection.py", line 409, in _extract_next_receive_event
    event = self._reader(self._receive_buffer)
  File "/home/wzkariampuzha/anaconda3/envs/fastapi/lib/python3.6/site-packages/h11/_readers.py", line 86, in maybe_read_from_IDLE_client
    request_line_re, lines[0], "illegal request line: {!r}", lines[0]
  File "/home/wzkariampuzha/anaconda3/envs/fastapi/lib/python3.6/site-packages/h11/_util.py", line 91, in validate
    raise LocalProtocolError(msg)
h11._util.RemoteProtocolError: illegal request line: bytearray(b'SM')
2022-06-11 02:40:09.157 WARNING uvicorn.error: Invalid HTTP request received.
Traceback (most recent call last):
  File "/home/wzkariampuzha/anaconda3/envs/fastapi/lib/python3.6/site-packages/starlette/exceptions.py", line 82, in __call__
    await self.app(scope, receive, sender)
  File "/home/wzkariampuzha/anaconda3/envs/fastapi/lib/python3.6/site-packages/fastapi/middleware/asyncexitstack.py", line 21, in __call__
    raise e
  File "/home/wzkariampuzha/anaconda3/envs/fastapi/lib/python3.6/site-packages/fastapi/middleware/asyncexitstack.py", line 18, in __call__
    await self.app(scope, receive, send)
  File "/home/wzkariampuzha/anaconda3/envs/fastapi/lib/python3.6/site-packages/starlette/routing.py", line 699, in __call__
    await self.default(scope, receive, send)
  File "/home/wzkariampuzha/anaconda3/envs/fastapi/lib/python3.6/site-packages/starlette/routing.py", line 593, in not_found
    raise HTTPException(status_code=404)
starlette.exceptions.HTTPException

During handling of the above exception, another exception occurred:

Traceback (most recent call last):
  File "/home/wzkariampuzha/anaconda3/envs/fastapi/lib/python3.6/site-packages/uvicorn/protocols/http/h11_impl.py", line 136, in handle_events
    event = self.conn.next_event()
  File "/home/wzkariampuzha/anaconda3/envs/fastapi/lib/python3.6/site-packages/h11/_connection.py", line 485, in next_event
    exc._reraise_as_remote_protocol_error()
  File "/home/wzkariampuzha/anaconda3/envs/fastapi/lib/python3.6/site-packages/h11/_util.py", line 77, in _reraise_as_remote_protocol_error
    raise self
  File "/home/wzkariampuzha/anaconda3/envs/fastapi/lib/python3.6/site-packages/h11/_connection.py", line 467, in next_event
    event = self._extract_next_receive_event()
  File "/home/wzkariampuzha/anaconda3/envs/fastapi/lib/python3.6/site-packages/h11/_connection.py", line 409, in _extract_next_receive_event
    event = self._reader(self._receive_buffer)
  File "/home/wzkariampuzha/anaconda3/envs/fastapi/lib/python3.6/site-packages/h11/_readers.py", line 86, in maybe_read_from_IDLE_client
    request_line_re, lines[0], "illegal request line: {!r}", lines[0]
  File "/home/wzkariampuzha/anaconda3/envs/fastapi/lib/python3.6/site-packages/h11/_util.py", line 91, in validate
    raise LocalProtocolError(msg)
h11._util.RemoteProtocolError: illegal request line: bytearray(b'SM')
WARNING:  Invalid HTTP request received.
Traceback (most recent call last):
  File "/home/wzkariampuzha/anaconda3/envs/fastapi/lib/python3.6/site-packages/uvicorn/protocols/http/h11_impl.py", line 136, in handle_events
    event = self.conn.next_event()
  File "/home/wzkariampuzha/anaconda3/envs/fastapi/lib/python3.6/site-packages/h11/_connection.py", line 485, in next_event
    exc._reraise_as_remote_protocol_error()
  File "/home/wzkariampuzha/anaconda3/envs/fastapi/lib/python3.6/site-packages/h11/_util.py", line 77, in _reraise_as_remote_protocol_error
    raise self
  File "/home/wzkariampuzha/anaconda3/envs/fastapi/lib/python3.6/site-packages/h11/_connection.py", line 467, in next_event
    event = self._extract_next_receive_event()
  File "/home/wzkariampuzha/anaconda3/envs/fastapi/lib/python3.6/site-packages/h11/_connection.py", line 409, in _extract_next_receive_event
    event = self._reader(self._receive_buffer)
  File "/home/wzkariampuzha/anaconda3/envs/fastapi/lib/python3.6/site-packages/h11/_readers.py", line 84, in maybe_read_from_IDLE_client
    raise LocalProtocolError("no request line received")
h11._util.RemoteProtocolError: no request line received
2022-06-11 04:29:09.874 WARNING uvicorn.error: Invalid HTTP request received.
Traceback (most recent call last):
  File "/home/wzkariampuzha/anaconda3/envs/fastapi/lib/python3.6/site-packages/uvicorn/protocols/http/h11_impl.py", line 136, in handle_events
    event = self.conn.next_event()
  File "/home/wzkariampuzha/anaconda3/envs/fastapi/lib/python3.6/site-packages/h11/_connection.py", line 485, in next_event
    exc._reraise_as_remote_protocol_error()
  File "/home/wzkariampuzha/anaconda3/envs/fastapi/lib/python3.6/site-packages/h11/_util.py", line 77, in _reraise_as_remote_protocol_error
    raise self
  File "/home/wzkariampuzha/anaconda3/envs/fastapi/lib/python3.6/site-packages/h11/_connection.py", line 467, in next_event
    event = self._extract_next_receive_event()
  File "/home/wzkariampuzha/anaconda3/envs/fastapi/lib/python3.6/site-packages/h11/_connection.py", line 409, in _extract_next_receive_event
    event = self._reader(self._receive_buffer)
  File "/home/wzkariampuzha/anaconda3/envs/fastapi/lib/python3.6/site-packages/h11/_readers.py", line 84, in maybe_read_from_IDLE_client
    raise LocalProtocolError("no request line received")
h11._util.RemoteProtocolError: no request line received
INFO:     23.225.163.204:37098 - "GET / HTTP/1.1" 200 OK
INFO:     23.225.163.204:38494 - "GET /favicon.ico HTTP/1.1" 404 Not Found
INFO:     23.225.163.204:39298 - "GET /robots.txt HTTP/1.1" 404 Not Found
INFO:     23.225.163.204:40080 - "GET /sitemap.xml HTTP/1.1" 404 Not Found
INFO:     185.180.143.16:55212 - "GET / HTTP/1.1" 200 OK
INFO:     167.248.133.44:43134 - "GET / HTTP/1.1" 200 OK
INFO:     167.248.133.44:53134 - "GET / HTTP/1.1" 200 OK
INFO:     167.248.133.44:54574 - "PRI %2A HTTP/2.0" 404 Not Found
WARNING:  Invalid HTTP request received.
Traceback (most recent call last):
  File "/home/wzkariampuzha/anaconda3/envs/fastapi/lib/python3.6/site-packages/starlette/exceptions.py", line 82, in __call__
    await self.app(scope, receive, sender)
  File "/home/wzkariampuzha/anaconda3/envs/fastapi/lib/python3.6/site-packages/fastapi/middleware/asyncexitstack.py", line 21, in __call__
    raise e
  File "/home/wzkariampuzha/anaconda3/envs/fastapi/lib/python3.6/site-packages/fastapi/middleware/asyncexitstack.py", line 18, in __call__
    await self.app(scope, receive, send)
  File "/home/wzkariampuzha/anaconda3/envs/fastapi/lib/python3.6/site-packages/starlette/routing.py", line 699, in __call__
    await self.default(scope, receive, send)
  File "/home/wzkariampuzha/anaconda3/envs/fastapi/lib/python3.6/site-packages/starlette/routing.py", line 593, in not_found
    raise HTTPException(status_code=404)
starlette.exceptions.HTTPException

During handling of the above exception, another exception occurred:

Traceback (most recent call last):
  File "/home/wzkariampuzha/anaconda3/envs/fastapi/lib/python3.6/site-packages/uvicorn/protocols/http/h11_impl.py", line 136, in handle_events
    event = self.conn.next_event()
  File "/home/wzkariampuzha/anaconda3/envs/fastapi/lib/python3.6/site-packages/h11/_connection.py", line 485, in next_event
    exc._reraise_as_remote_protocol_error()
  File "/home/wzkariampuzha/anaconda3/envs/fastapi/lib/python3.6/site-packages/h11/_util.py", line 77, in _reraise_as_remote_protocol_error
    raise self
  File "/home/wzkariampuzha/anaconda3/envs/fastapi/lib/python3.6/site-packages/h11/_connection.py", line 467, in next_event
    event = self._extract_next_receive_event()
  File "/home/wzkariampuzha/anaconda3/envs/fastapi/lib/python3.6/site-packages/h11/_connection.py", line 409, in _extract_next_receive_event
    event = self._reader(self._receive_buffer)
  File "/home/wzkariampuzha/anaconda3/envs/fastapi/lib/python3.6/site-packages/h11/_readers.py", line 86, in maybe_read_from_IDLE_client
    request_line_re, lines[0], "illegal request line: {!r}", lines[0]
  File "/home/wzkariampuzha/anaconda3/envs/fastapi/lib/python3.6/site-packages/h11/_util.py", line 91, in validate
    raise LocalProtocolError(msg)
h11._util.RemoteProtocolError: illegal request line: bytearray(b'SM')
2022-06-11 12:37:53.685 WARNING uvicorn.error: Invalid HTTP request received.
Traceback (most recent call last):
  File "/home/wzkariampuzha/anaconda3/envs/fastapi/lib/python3.6/site-packages/starlette/exceptions.py", line 82, in __call__
    await self.app(scope, receive, sender)
  File "/home/wzkariampuzha/anaconda3/envs/fastapi/lib/python3.6/site-packages/fastapi/middleware/asyncexitstack.py", line 21, in __call__
    raise e
  File "/home/wzkariampuzha/anaconda3/envs/fastapi/lib/python3.6/site-packages/fastapi/middleware/asyncexitstack.py", line 18, in __call__
    await self.app(scope, receive, send)
  File "/home/wzkariampuzha/anaconda3/envs/fastapi/lib/python3.6/site-packages/starlette/routing.py", line 699, in __call__
    await self.default(scope, receive, send)
  File "/home/wzkariampuzha/anaconda3/envs/fastapi/lib/python3.6/site-packages/starlette/routing.py", line 593, in not_found
    raise HTTPException(status_code=404)
starlette.exceptions.HTTPException

During handling of the above exception, another exception occurred:

Traceback (most recent call last):
  File "/home/wzkariampuzha/anaconda3/envs/fastapi/lib/python3.6/site-packages/uvicorn/protocols/http/h11_impl.py", line 136, in handle_events
    event = self.conn.next_event()
  File "/home/wzkariampuzha/anaconda3/envs/fastapi/lib/python3.6/site-packages/h11/_connection.py", line 485, in next_event
    exc._reraise_as_remote_protocol_error()
  File "/home/wzkariampuzha/anaconda3/envs/fastapi/lib/python3.6/site-packages/h11/_util.py", line 77, in _reraise_as_remote_protocol_error
    raise self
  File "/home/wzkariampuzha/anaconda3/envs/fastapi/lib/python3.6/site-packages/h11/_connection.py", line 467, in next_event
    event = self._extract_next_receive_event()
  File "/home/wzkariampuzha/anaconda3/envs/fastapi/lib/python3.6/site-packages/h11/_connection.py", line 409, in _extract_next_receive_event
    event = self._reader(self._receive_buffer)
  File "/home/wzkariampuzha/anaconda3/envs/fastapi/lib/python3.6/site-packages/h11/_readers.py", line 86, in maybe_read_from_IDLE_client
    request_line_re, lines[0], "illegal request line: {!r}", lines[0]
  File "/home/wzkariampuzha/anaconda3/envs/fastapi/lib/python3.6/site-packages/h11/_util.py", line 91, in validate
    raise LocalProtocolError(msg)
h11._util.RemoteProtocolError: illegal request line: bytearray(b'SM')
INFO:     192.241.213.28:49178 - "GET / HTTP/1.1" 200 OK
INFO:     73.207.102.233:49875 - "GET /openapi.json HTTP/1.1" 200 OK
INFO:     73.207.102.233:49902 - "GET /openapi.json HTTP/1.1" 200 OK
INFO:     68.77.56.191:58484 - "GET /docs HTTP/1.1" 200 OK
INFO:     68.77.56.191:58484 - "GET /openapi.json HTTP/1.1" 200 OK
INFO:     47.219.10.126:51726 - "GET /docs HTTP/1.1" 200 OK
INFO:     47.219.10.126:51726 - "GET /openapi.json HTTP/1.1" 200 OK
INFO:     192.58.125.19:44904 - "GET /docs HTTP/1.1" 200 OK
INFO:     192.58.125.19:44904 - "GET /openapi.json HTTP/1.1" 200 OK
INFO:     63.117.14.69:48296 - "GET /docs HTTP/1.1" 200 OK
INFO:     63.117.14.69:48298 - "GET /openapi.json HTTP/1.1" 200 OK
INFO:     192.241.212.85:58460 - "GET / HTTP/1.1" 200 OK
INFO:     162.142.125.219:33258 - "GET / HTTP/1.1" 200 OK
INFO:     162.142.125.219:45682 - "GET / HTTP/1.1" 200 OK
INFO:     162.142.125.219:47576 - "PRI %2A HTTP/2.0" 404 Not Found
WARNING:  Invalid HTTP request received.
Traceback (most recent call last):
  File "/home/wzkariampuzha/anaconda3/envs/fastapi/lib/python3.6/site-packages/starlette/exceptions.py", line 82, in __call__
    await self.app(scope, receive, sender)
  File "/home/wzkariampuzha/anaconda3/envs/fastapi/lib/python3.6/site-packages/fastapi/middleware/asyncexitstack.py", line 21, in __call__
    raise e
  File "/home/wzkariampuzha/anaconda3/envs/fastapi/lib/python3.6/site-packages/fastapi/middleware/asyncexitstack.py", line 18, in __call__
    await self.app(scope, receive, send)
  File "/home/wzkariampuzha/anaconda3/envs/fastapi/lib/python3.6/site-packages/starlette/routing.py", line 699, in __call__
    await self.default(scope, receive, send)
  File "/home/wzkariampuzha/anaconda3/envs/fastapi/lib/python3.6/site-packages/starlette/routing.py", line 593, in not_found
    raise HTTPException(status_code=404)
starlette.exceptions.HTTPException

During handling of the above exception, another exception occurred:

Traceback (most recent call last):
  File "/home/wzkariampuzha/anaconda3/envs/fastapi/lib/python3.6/site-packages/uvicorn/protocols/http/h11_impl.py", line 136, in handle_events
    event = self.conn.next_event()
  File "/home/wzkariampuzha/anaconda3/envs/fastapi/lib/python3.6/site-packages/h11/_connection.py", line 485, in next_event
    exc._reraise_as_remote_protocol_error()
  File "/home/wzkariampuzha/anaconda3/envs/fastapi/lib/python3.6/site-packages/h11/_util.py", line 77, in _reraise_as_remote_protocol_error
    raise self
  File "/home/wzkariampuzha/anaconda3/envs/fastapi/lib/python3.6/site-packages/h11/_connection.py", line 467, in next_event
    event = self._extract_next_receive_event()
  File "/home/wzkariampuzha/anaconda3/envs/fastapi/lib/python3.6/site-packages/h11/_connection.py", line 409, in _extract_next_receive_event
    event = self._reader(self._receive_buffer)
  File "/home/wzkariampuzha/anaconda3/envs/fastapi/lib/python3.6/site-packages/h11/_readers.py", line 86, in maybe_read_from_IDLE_client
    request_line_re, lines[0], "illegal request line: {!r}", lines[0]
  File "/home/wzkariampuzha/anaconda3/envs/fastapi/lib/python3.6/site-packages/h11/_util.py", line 91, in validate
    raise LocalProtocolError(msg)
h11._util.RemoteProtocolError: illegal request line: bytearray(b'SM')
2022-06-13 18:37:25.384 WARNING uvicorn.error: Invalid HTTP request received.
Traceback (most recent call last):
  File "/home/wzkariampuzha/anaconda3/envs/fastapi/lib/python3.6/site-packages/starlette/exceptions.py", line 82, in __call__
    await self.app(scope, receive, sender)
  File "/home/wzkariampuzha/anaconda3/envs/fastapi/lib/python3.6/site-packages/fastapi/middleware/asyncexitstack.py", line 21, in __call__
    raise e
  File "/home/wzkariampuzha/anaconda3/envs/fastapi/lib/python3.6/site-packages/fastapi/middleware/asyncexitstack.py", line 18, in __call__
    await self.app(scope, receive, send)
  File "/home/wzkariampuzha/anaconda3/envs/fastapi/lib/python3.6/site-packages/starlette/routing.py", line 699, in __call__
    await self.default(scope, receive, send)
  File "/home/wzkariampuzha/anaconda3/envs/fastapi/lib/python3.6/site-packages/starlette/routing.py", line 593, in not_found
    raise HTTPException(status_code=404)
starlette.exceptions.HTTPException

During handling of the above exception, another exception occurred:

Traceback (most recent call last):
  File "/home/wzkariampuzha/anaconda3/envs/fastapi/lib/python3.6/site-packages/uvicorn/protocols/http/h11_impl.py", line 136, in handle_events
    event = self.conn.next_event()
  File "/home/wzkariampuzha/anaconda3/envs/fastapi/lib/python3.6/site-packages/h11/_connection.py", line 485, in next_event
    exc._reraise_as_remote_protocol_error()
  File "/home/wzkariampuzha/anaconda3/envs/fastapi/lib/python3.6/site-packages/h11/_util.py", line 77, in _reraise_as_remote_protocol_error
    raise self
  File "/home/wzkariampuzha/anaconda3/envs/fastapi/lib/python3.6/site-packages/h11/_connection.py", line 467, in next_event
    event = self._extract_next_receive_event()
  File "/home/wzkariampuzha/anaconda3/envs/fastapi/lib/python3.6/site-packages/h11/_connection.py", line 409, in _extract_next_receive_event
    event = self._reader(self._receive_buffer)
  File "/home/wzkariampuzha/anaconda3/envs/fastapi/lib/python3.6/site-packages/h11/_readers.py", line 86, in maybe_read_from_IDLE_client
    request_line_re, lines[0], "illegal request line: {!r}", lines[0]
  File "/home/wzkariampuzha/anaconda3/envs/fastapi/lib/python3.6/site-packages/h11/_util.py", line 91, in validate
    raise LocalProtocolError(msg)
h11._util.RemoteProtocolError: illegal request line: bytearray(b'SM')
INFO:     167.94.138.47:51034 - "GET / HTTP/1.1" 200 OK
INFO:     167.94.138.47:55988 - "GET / HTTP/1.1" 200 OK
INFO:     167.94.138.47:57388 - "PRI %2A HTTP/2.0" 404 Not Found
WARNING:  Invalid HTTP request received.
Traceback (most recent call last):
  File "/home/wzkariampuzha/anaconda3/envs/fastapi/lib/python3.6/site-packages/starlette/exceptions.py", line 82, in __call__
    await self.app(scope, receive, sender)
  File "/home/wzkariampuzha/anaconda3/envs/fastapi/lib/python3.6/site-packages/fastapi/middleware/asyncexitstack.py", line 21, in __call__
    raise e
  File "/home/wzkariampuzha/anaconda3/envs/fastapi/lib/python3.6/site-packages/fastapi/middleware/asyncexitstack.py", line 18, in __call__
    await self.app(scope, receive, send)
  File "/home/wzkariampuzha/anaconda3/envs/fastapi/lib/python3.6/site-packages/starlette/routing.py", line 699, in __call__
    await self.default(scope, receive, send)
  File "/home/wzkariampuzha/anaconda3/envs/fastapi/lib/python3.6/site-packages/starlette/routing.py", line 593, in not_found
    raise HTTPException(status_code=404)
starlette.exceptions.HTTPException

During handling of the above exception, another exception occurred:

Traceback (most recent call last):
  File "/home/wzkariampuzha/anaconda3/envs/fastapi/lib/python3.6/site-packages/uvicorn/protocols/http/h11_impl.py", line 136, in handle_events
    event = self.conn.next_event()
  File "/home/wzkariampuzha/anaconda3/envs/fastapi/lib/python3.6/site-packages/h11/_connection.py", line 485, in next_event
    exc._reraise_as_remote_protocol_error()
  File "/home/wzkariampuzha/anaconda3/envs/fastapi/lib/python3.6/site-packages/h11/_util.py", line 77, in _reraise_as_remote_protocol_error
    raise self
  File "/home/wzkariampuzha/anaconda3/envs/fastapi/lib/python3.6/site-packages/h11/_connection.py", line 467, in next_event
    event = self._extract_next_receive_event()
  File "/home/wzkariampuzha/anaconda3/envs/fastapi/lib/python3.6/site-packages/h11/_connection.py", line 409, in _extract_next_receive_event
    event = self._reader(self._receive_buffer)
  File "/home/wzkariampuzha/anaconda3/envs/fastapi/lib/python3.6/site-packages/h11/_readers.py", line 86, in maybe_read_from_IDLE_client
    request_line_re, lines[0], "illegal request line: {!r}", lines[0]
  File "/home/wzkariampuzha/anaconda3/envs/fastapi/lib/python3.6/site-packages/h11/_util.py", line 91, in validate
    raise LocalProtocolError(msg)
h11._util.RemoteProtocolError: illegal request line: bytearray(b'SM')
2022-06-13 19:43:57.632 WARNING uvicorn.error: Invalid HTTP request received.
Traceback (most recent call last):
  File "/home/wzkariampuzha/anaconda3/envs/fastapi/lib/python3.6/site-packages/starlette/exceptions.py", line 82, in __call__
    await self.app(scope, receive, sender)
  File "/home/wzkariampuzha/anaconda3/envs/fastapi/lib/python3.6/site-packages/fastapi/middleware/asyncexitstack.py", line 21, in __call__
    raise e
  File "/home/wzkariampuzha/anaconda3/envs/fastapi/lib/python3.6/site-packages/fastapi/middleware/asyncexitstack.py", line 18, in __call__
    await self.app(scope, receive, send)
  File "/home/wzkariampuzha/anaconda3/envs/fastapi/lib/python3.6/site-packages/starlette/routing.py", line 699, in __call__
    await self.default(scope, receive, send)
  File "/home/wzkariampuzha/anaconda3/envs/fastapi/lib/python3.6/site-packages/starlette/routing.py", line 593, in not_found
    raise HTTPException(status_code=404)
starlette.exceptions.HTTPException

During handling of the above exception, another exception occurred:

Traceback (most recent call last):
  File "/home/wzkariampuzha/anaconda3/envs/fastapi/lib/python3.6/site-packages/uvicorn/protocols/http/h11_impl.py", line 136, in handle_events
    event = self.conn.next_event()
  File "/home/wzkariampuzha/anaconda3/envs/fastapi/lib/python3.6/site-packages/h11/_connection.py", line 485, in next_event
    exc._reraise_as_remote_protocol_error()
  File "/home/wzkariampuzha/anaconda3/envs/fastapi/lib/python3.6/site-packages/h11/_util.py", line 77, in _reraise_as_remote_protocol_error
    raise self
  File "/home/wzkariampuzha/anaconda3/envs/fastapi/lib/python3.6/site-packages/h11/_connection.py", line 467, in next_event
    event = self._extract_next_receive_event()
  File "/home/wzkariampuzha/anaconda3/envs/fastapi/lib/python3.6/site-packages/h11/_connection.py", line 409, in _extract_next_receive_event
    event = self._reader(self._receive_buffer)
  File "/home/wzkariampuzha/anaconda3/envs/fastapi/lib/python3.6/site-packages/h11/_readers.py", line 86, in maybe_read_from_IDLE_client
    request_line_re, lines[0], "illegal request line: {!r}", lines[0]
  File "/home/wzkariampuzha/anaconda3/envs/fastapi/lib/python3.6/site-packages/h11/_util.py", line 91, in validate
    raise LocalProtocolError(msg)
h11._util.RemoteProtocolError: illegal request line: bytearray(b'SM')
INFO:     162.142.125.221:42206 - "GET / HTTP/1.1" 200 OK
INFO:     162.142.125.221:53644 - "GET / HTTP/1.1" 200 OK
INFO:     162.142.125.221:56330 - "PRI %2A HTTP/2.0" 404 Not Found
WARNING:  Invalid HTTP request received.
Traceback (most recent call last):
  File "/home/wzkariampuzha/anaconda3/envs/fastapi/lib/python3.6/site-packages/starlette/exceptions.py", line 82, in __call__
    await self.app(scope, receive, sender)
  File "/home/wzkariampuzha/anaconda3/envs/fastapi/lib/python3.6/site-packages/fastapi/middleware/asyncexitstack.py", line 21, in __call__
    raise e
  File "/home/wzkariampuzha/anaconda3/envs/fastapi/lib/python3.6/site-packages/fastapi/middleware/asyncexitstack.py", line 18, in __call__
    await self.app(scope, receive, send)
  File "/home/wzkariampuzha/anaconda3/envs/fastapi/lib/python3.6/site-packages/starlette/routing.py", line 699, in __call__
    await self.default(scope, receive, send)
  File "/home/wzkariampuzha/anaconda3/envs/fastapi/lib/python3.6/site-packages/starlette/routing.py", line 593, in not_found
    raise HTTPException(status_code=404)
starlette.exceptions.HTTPException

During handling of the above exception, another exception occurred:

Traceback (most recent call last):
  File "/home/wzkariampuzha/anaconda3/envs/fastapi/lib/python3.6/site-packages/uvicorn/protocols/http/h11_impl.py", line 136, in handle_events
    event = self.conn.next_event()
  File "/home/wzkariampuzha/anaconda3/envs/fastapi/lib/python3.6/site-packages/h11/_connection.py", line 485, in next_event
    exc._reraise_as_remote_protocol_error()
  File "/home/wzkariampuzha/anaconda3/envs/fastapi/lib/python3.6/site-packages/h11/_util.py", line 77, in _reraise_as_remote_protocol_error
    raise self
  File "/home/wzkariampuzha/anaconda3/envs/fastapi/lib/python3.6/site-packages/h11/_connection.py", line 467, in next_event
    event = self._extract_next_receive_event()
  File "/home/wzkariampuzha/anaconda3/envs/fastapi/lib/python3.6/site-packages/h11/_connection.py", line 409, in _extract_next_receive_event
    event = self._reader(self._receive_buffer)
  File "/home/wzkariampuzha/anaconda3/envs/fastapi/lib/python3.6/site-packages/h11/_readers.py", line 86, in maybe_read_from_IDLE_client
    request_line_re, lines[0], "illegal request line: {!r}", lines[0]
  File "/home/wzkariampuzha/anaconda3/envs/fastapi/lib/python3.6/site-packages/h11/_util.py", line 91, in validate
    raise LocalProtocolError(msg)
h11._util.RemoteProtocolError: illegal request line: bytearray(b'SM')
2022-06-13 22:44:55.468 WARNING uvicorn.error: Invalid HTTP request received.
Traceback (most recent call last):
  File "/home/wzkariampuzha/anaconda3/envs/fastapi/lib/python3.6/site-packages/starlette/exceptions.py", line 82, in __call__
    await self.app(scope, receive, sender)
  File "/home/wzkariampuzha/anaconda3/envs/fastapi/lib/python3.6/site-packages/fastapi/middleware/asyncexitstack.py", line 21, in __call__
    raise e
  File "/home/wzkariampuzha/anaconda3/envs/fastapi/lib/python3.6/site-packages/fastapi/middleware/asyncexitstack.py", line 18, in __call__
    await self.app(scope, receive, send)
  File "/home/wzkariampuzha/anaconda3/envs/fastapi/lib/python3.6/site-packages/starlette/routing.py", line 699, in __call__
    await self.default(scope, receive, send)
  File "/home/wzkariampuzha/anaconda3/envs/fastapi/lib/python3.6/site-packages/starlette/routing.py", line 593, in not_found
    raise HTTPException(status_code=404)
starlette.exceptions.HTTPException

During handling of the above exception, another exception occurred:

Traceback (most recent call last):
  File "/home/wzkariampuzha/anaconda3/envs/fastapi/lib/python3.6/site-packages/uvicorn/protocols/http/h11_impl.py", line 136, in handle_events
    event = self.conn.next_event()
  File "/home/wzkariampuzha/anaconda3/envs/fastapi/lib/python3.6/site-packages/h11/_connection.py", line 485, in next_event
    exc._reraise_as_remote_protocol_error()
  File "/home/wzkariampuzha/anaconda3/envs/fastapi/lib/python3.6/site-packages/h11/_util.py", line 77, in _reraise_as_remote_protocol_error
    raise self
  File "/home/wzkariampuzha/anaconda3/envs/fastapi/lib/python3.6/site-packages/h11/_connection.py", line 467, in next_event
    event = self._extract_next_receive_event()
  File "/home/wzkariampuzha/anaconda3/envs/fastapi/lib/python3.6/site-packages/h11/_connection.py", line 409, in _extract_next_receive_event
    event = self._reader(self._receive_buffer)
  File "/home/wzkariampuzha/anaconda3/envs/fastapi/lib/python3.6/site-packages/h11/_readers.py", line 86, in maybe_read_from_IDLE_client
    request_line_re, lines[0], "illegal request line: {!r}", lines[0]
  File "/home/wzkariampuzha/anaconda3/envs/fastapi/lib/python3.6/site-packages/h11/_util.py", line 91, in validate
    raise LocalProtocolError(msg)
h11._util.RemoteProtocolError: illegal request line: bytearray(b'SM')
INFO:     167.94.146.59:52834 - "GET / HTTP/1.1" 200 OK
INFO:     167.94.146.59:60240 - "GET / HTTP/1.1" 200 OK
INFO:     167.94.146.59:39802 - "PRI %2A HTTP/2.0" 404 Not Found
WARNING:  Invalid HTTP request received.
Traceback (most recent call last):
  File "/home/wzkariampuzha/anaconda3/envs/fastapi/lib/python3.6/site-packages/starlette/exceptions.py", line 82, in __call__
    await self.app(scope, receive, sender)
  File "/home/wzkariampuzha/anaconda3/envs/fastapi/lib/python3.6/site-packages/fastapi/middleware/asyncexitstack.py", line 21, in __call__
    raise e
  File "/home/wzkariampuzha/anaconda3/envs/fastapi/lib/python3.6/site-packages/fastapi/middleware/asyncexitstack.py", line 18, in __call__
    await self.app(scope, receive, send)
  File "/home/wzkariampuzha/anaconda3/envs/fastapi/lib/python3.6/site-packages/starlette/routing.py", line 699, in __call__
    await self.default(scope, receive, send)
  File "/home/wzkariampuzha/anaconda3/envs/fastapi/lib/python3.6/site-packages/starlette/routing.py", line 593, in not_found
    raise HTTPException(status_code=404)
starlette.exceptions.HTTPException

During handling of the above exception, another exception occurred:

Traceback (most recent call last):
  File "/home/wzkariampuzha/anaconda3/envs/fastapi/lib/python3.6/site-packages/uvicorn/protocols/http/h11_impl.py", line 136, in handle_events
    event = self.conn.next_event()
  File "/home/wzkariampuzha/anaconda3/envs/fastapi/lib/python3.6/site-packages/h11/_connection.py", line 485, in next_event
    exc._reraise_as_remote_protocol_error()
  File "/home/wzkariampuzha/anaconda3/envs/fastapi/lib/python3.6/site-packages/h11/_util.py", line 77, in _reraise_as_remote_protocol_error
    raise self
  File "/home/wzkariampuzha/anaconda3/envs/fastapi/lib/python3.6/site-packages/h11/_connection.py", line 467, in next_event
    event = self._extract_next_receive_event()
  File "/home/wzkariampuzha/anaconda3/envs/fastapi/lib/python3.6/site-packages/h11/_connection.py", line 409, in _extract_next_receive_event
    event = self._reader(self._receive_buffer)
  File "/home/wzkariampuzha/anaconda3/envs/fastapi/lib/python3.6/site-packages/h11/_readers.py", line 86, in maybe_read_from_IDLE_client
    request_line_re, lines[0], "illegal request line: {!r}", lines[0]
  File "/home/wzkariampuzha/anaconda3/envs/fastapi/lib/python3.6/site-packages/h11/_util.py", line 91, in validate
    raise LocalProtocolError(msg)
h11._util.RemoteProtocolError: illegal request line: bytearray(b'SM')
2022-06-14 08:02:46.443 WARNING uvicorn.error: Invalid HTTP request received.
Traceback (most recent call last):
  File "/home/wzkariampuzha/anaconda3/envs/fastapi/lib/python3.6/site-packages/starlette/exceptions.py", line 82, in __call__
    await self.app(scope, receive, sender)
  File "/home/wzkariampuzha/anaconda3/envs/fastapi/lib/python3.6/site-packages/fastapi/middleware/asyncexitstack.py", line 21, in __call__
    raise e
  File "/home/wzkariampuzha/anaconda3/envs/fastapi/lib/python3.6/site-packages/fastapi/middleware/asyncexitstack.py", line 18, in __call__
    await self.app(scope, receive, send)
  File "/home/wzkariampuzha/anaconda3/envs/fastapi/lib/python3.6/site-packages/starlette/routing.py", line 699, in __call__
    await self.default(scope, receive, send)
  File "/home/wzkariampuzha/anaconda3/envs/fastapi/lib/python3.6/site-packages/starlette/routing.py", line 593, in not_found
    raise HTTPException(status_code=404)
starlette.exceptions.HTTPException

During handling of the above exception, another exception occurred:

Traceback (most recent call last):
  File "/home/wzkariampuzha/anaconda3/envs/fastapi/lib/python3.6/site-packages/uvicorn/protocols/http/h11_impl.py", line 136, in handle_events
    event = self.conn.next_event()
  File "/home/wzkariampuzha/anaconda3/envs/fastapi/lib/python3.6/site-packages/h11/_connection.py", line 485, in next_event
    exc._reraise_as_remote_protocol_error()
  File "/home/wzkariampuzha/anaconda3/envs/fastapi/lib/python3.6/site-packages/h11/_util.py", line 77, in _reraise_as_remote_protocol_error
    raise self
  File "/home/wzkariampuzha/anaconda3/envs/fastapi/lib/python3.6/site-packages/h11/_connection.py", line 467, in next_event
    event = self._extract_next_receive_event()
  File "/home/wzkariampuzha/anaconda3/envs/fastapi/lib/python3.6/site-packages/h11/_connection.py", line 409, in _extract_next_receive_event
    event = self._reader(self._receive_buffer)
  File "/home/wzkariampuzha/anaconda3/envs/fastapi/lib/python3.6/site-packages/h11/_readers.py", line 86, in maybe_read_from_IDLE_client
    request_line_re, lines[0], "illegal request line: {!r}", lines[0]
  File "/home/wzkariampuzha/anaconda3/envs/fastapi/lib/python3.6/site-packages/h11/_util.py", line 91, in validate
    raise LocalProtocolError(msg)
h11._util.RemoteProtocolError: illegal request line: bytearray(b'SM')
INFO:     162.142.125.221:53010 - "GET / HTTP/1.1" 200 OK
INFO:     162.142.125.221:48676 - "GET / HTTP/1.1" 200 OK
INFO:     162.142.125.221:50114 - "PRI %2A HTTP/2.0" 404 Not Found
WARNING:  Invalid HTTP request received.
Traceback (most recent call last):
  File "/home/wzkariampuzha/anaconda3/envs/fastapi/lib/python3.6/site-packages/starlette/exceptions.py", line 82, in __call__
    await self.app(scope, receive, sender)
  File "/home/wzkariampuzha/anaconda3/envs/fastapi/lib/python3.6/site-packages/fastapi/middleware/asyncexitstack.py", line 21, in __call__
    raise e
  File "/home/wzkariampuzha/anaconda3/envs/fastapi/lib/python3.6/site-packages/fastapi/middleware/asyncexitstack.py", line 18, in __call__
    await self.app(scope, receive, send)
  File "/home/wzkariampuzha/anaconda3/envs/fastapi/lib/python3.6/site-packages/starlette/routing.py", line 699, in __call__
    await self.default(scope, receive, send)
  File "/home/wzkariampuzha/anaconda3/envs/fastapi/lib/python3.6/site-packages/starlette/routing.py", line 593, in not_found
    raise HTTPException(status_code=404)
starlette.exceptions.HTTPException

During handling of the above exception, another exception occurred:

Traceback (most recent call last):
  File "/home/wzkariampuzha/anaconda3/envs/fastapi/lib/python3.6/site-packages/uvicorn/protocols/http/h11_impl.py", line 136, in handle_events
    event = self.conn.next_event()
  File "/home/wzkariampuzha/anaconda3/envs/fastapi/lib/python3.6/site-packages/h11/_connection.py", line 485, in next_event
    exc._reraise_as_remote_protocol_error()
  File "/home/wzkariampuzha/anaconda3/envs/fastapi/lib/python3.6/site-packages/h11/_util.py", line 77, in _reraise_as_remote_protocol_error
    raise self
  File "/home/wzkariampuzha/anaconda3/envs/fastapi/lib/python3.6/site-packages/h11/_connection.py", line 467, in next_event
    event = self._extract_next_receive_event()
  File "/home/wzkariampuzha/anaconda3/envs/fastapi/lib/python3.6/site-packages/h11/_connection.py", line 409, in _extract_next_receive_event
    event = self._reader(self._receive_buffer)
  File "/home/wzkariampuzha/anaconda3/envs/fastapi/lib/python3.6/site-packages/h11/_readers.py", line 86, in maybe_read_from_IDLE_client
    request_line_re, lines[0], "illegal request line: {!r}", lines[0]
  File "/home/wzkariampuzha/anaconda3/envs/fastapi/lib/python3.6/site-packages/h11/_util.py", line 91, in validate
    raise LocalProtocolError(msg)
h11._util.RemoteProtocolError: illegal request line: bytearray(b'SM')
2022-06-14 11:54:28.963 WARNING uvicorn.error: Invalid HTTP request received.
Traceback (most recent call last):
  File "/home/wzkariampuzha/anaconda3/envs/fastapi/lib/python3.6/site-packages/starlette/exceptions.py", line 82, in __call__
    await self.app(scope, receive, sender)
  File "/home/wzkariampuzha/anaconda3/envs/fastapi/lib/python3.6/site-packages/fastapi/middleware/asyncexitstack.py", line 21, in __call__
    raise e
  File "/home/wzkariampuzha/anaconda3/envs/fastapi/lib/python3.6/site-packages/fastapi/middleware/asyncexitstack.py", line 18, in __call__
    await self.app(scope, receive, send)
  File "/home/wzkariampuzha/anaconda3/envs/fastapi/lib/python3.6/site-packages/starlette/routing.py", line 699, in __call__
    await self.default(scope, receive, send)
  File "/home/wzkariampuzha/anaconda3/envs/fastapi/lib/python3.6/site-packages/starlette/routing.py", line 593, in not_found
    raise HTTPException(status_code=404)
starlette.exceptions.HTTPException

During handling of the above exception, another exception occurred:

Traceback (most recent call last):
  File "/home/wzkariampuzha/anaconda3/envs/fastapi/lib/python3.6/site-packages/uvicorn/protocols/http/h11_impl.py", line 136, in handle_events
    event = self.conn.next_event()
  File "/home/wzkariampuzha/anaconda3/envs/fastapi/lib/python3.6/site-packages/h11/_connection.py", line 485, in next_event
    exc._reraise_as_remote_protocol_error()
  File "/home/wzkariampuzha/anaconda3/envs/fastapi/lib/python3.6/site-packages/h11/_util.py", line 77, in _reraise_as_remote_protocol_error
    raise self
  File "/home/wzkariampuzha/anaconda3/envs/fastapi/lib/python3.6/site-packages/h11/_connection.py", line 467, in next_event
    event = self._extract_next_receive_event()
  File "/home/wzkariampuzha/anaconda3/envs/fastapi/lib/python3.6/site-packages/h11/_connection.py", line 409, in _extract_next_receive_event
    event = self._reader(self._receive_buffer)
  File "/home/wzkariampuzha/anaconda3/envs/fastapi/lib/python3.6/site-packages/h11/_readers.py", line 86, in maybe_read_from_IDLE_client
    request_line_re, lines[0], "illegal request line: {!r}", lines[0]
  File "/home/wzkariampuzha/anaconda3/envs/fastapi/lib/python3.6/site-packages/h11/_util.py", line 91, in validate
    raise LocalProtocolError(msg)
h11._util.RemoteProtocolError: illegal request line: bytearray(b'SM')
INFO:     47.219.10.126:50141 - "GET /docs HTTP/1.1" 200 OK
INFO:     47.219.10.126:50141 - "GET /openapi.json HTTP/1.1" 200 OK
INFO:     47.219.10.126:50770 - "POST /postEpiClassifyText/ HTTP/1.1" 200 OK
INFO:     47.219.10.126:50772 - "POST /postEpiClassifyText/ HTTP/1.1" 200 OK
INFO:     47.219.10.126:50775 - "POST /postEpiClassifyText/ HTTP/1.1" 200 OK
INFO:     47.219.10.126:50777 - "POST /postEpiClassifyText/ HTTP/1.1" 200 OK
INFO:     47.219.10.126:50779 - "POST /postEpiClassifyText/ HTTP/1.1" 200 OK
INFO:     47.219.10.126:50781 - "POST /postEpiClassifyText/ HTTP/1.1" 200 OK
INFO:     47.219.10.126:50783 - "POST /postEpiClassifyText/ HTTP/1.1" 200 OK
INFO:     47.219.10.126:50786 - "POST /postEpiClassifyText/ HTTP/1.1" 200 OK
INFO:     47.219.10.126:50788 - "POST /postEpiClassifyText/ HTTP/1.1" 200 OK
INFO:     47.219.10.126:50790 - "POST /postEpiClassifyText/ HTTP/1.1" 200 OK
INFO:     47.219.10.126:50793 - "POST /postEpiClassifyText/ HTTP/1.1" 200 OK
INFO:     47.219.10.126:50795 - "POST /postEpiClassifyText/ HTTP/1.1" 200 OK
INFO:     47.219.10.126:50798 - "POST /postEpiClassifyText/ HTTP/1.1" 200 OK
INFO:     47.219.10.126:50800 - "POST /postEpiClassifyText/ HTTP/1.1" 200 OK
INFO:     47.219.10.126:50802 - "POST /postEpiClassifyText/ HTTP/1.1" 200 OK
INFO:     47.219.10.126:50804 - "POST /postEpiClassifyText/ HTTP/1.1" 200 OK
INFO:     47.219.10.126:50806 - "POST /postEpiClassifyText/ HTTP/1.1" 200 OK
INFO:     47.219.10.126:50809 - "POST /postEpiClassifyText/ HTTP/1.1" 200 OK
INFO:     47.219.10.126:50811 - "POST /postEpiClassifyText/ HTTP/1.1" 200 OK
INFO:     47.219.10.126:50836 - "POST /postEpiClassifyText/ HTTP/1.1" 200 OK
INFO:     47.219.10.126:50838 - "POST /postEpiClassifyText/ HTTP/1.1" 200 OK
INFO:     47.219.10.126:50840 - "POST /postEpiClassifyText/ HTTP/1.1" 200 OK
INFO:     47.219.10.126:50842 - "POST /postEpiClassifyText/ HTTP/1.1" 200 OK
INFO:     47.219.10.126:50845 - "POST /postEpiClassifyText/ HTTP/1.1" 200 OK
INFO:     47.219.10.126:50848 - "POST /postEpiClassifyText/ HTTP/1.1" 200 OK
INFO:     47.219.10.126:50852 - "POST /postEpiClassifyText/ HTTP/1.1" 200 OK
INFO:     47.219.10.126:50854 - "POST /postEpiClassifyText/ HTTP/1.1" 200 OK
INFO:     47.219.10.126:50856 - "POST /postEpiClassifyText/ HTTP/1.1" 200 OK
INFO:     47.219.10.126:50858 - "POST /postEpiClassifyText/ HTTP/1.1" 200 OK
INFO:     47.219.10.126:50861 - "POST /postEpiClassifyText/ HTTP/1.1" 200 OK
INFO:     47.219.10.126:50863 - "POST /postEpiClassifyText/ HTTP/1.1" 200 OK
INFO:     47.219.10.126:50866 - "POST /postEpiClassifyText/ HTTP/1.1" 200 OK
INFO:     47.219.10.126:50868 - "POST /postEpiClassifyText/ HTTP/1.1" 200 OK
INFO:     47.219.10.126:50871 - "POST /postEpiClassifyText/ HTTP/1.1" 200 OK
INFO:     47.219.10.126:50873 - "POST /postEpiClassifyText/ HTTP/1.1" 200 OK
INFO:     47.219.10.126:50875 - "POST /postEpiClassifyText/ HTTP/1.1" 200 OK
INFO:     47.219.10.126:50877 - "POST /postEpiClassifyText/ HTTP/1.1" 200 OK
INFO:     47.219.10.126:50883 - "POST /postEpiClassifyText/ HTTP/1.1" 200 OK
INFO:     47.219.10.126:50887 - "POST /postEpiClassifyText/ HTTP/1.1" 200 OK
INFO:     47.219.10.126:50889 - "POST /postEpiClassifyText/ HTTP/1.1" 200 OK
INFO:     47.219.10.126:50891 - "POST /postEpiClassifyText/ HTTP/1.1" 200 OK
INFO:     47.219.10.126:50893 - "POST /postEpiClassifyText/ HTTP/1.1" 200 OK
INFO:     47.219.10.126:50898 - "POST /postEpiClassifyText/ HTTP/1.1" 200 OK
INFO:     47.219.10.126:50900 - "POST /postEpiClassifyText/ HTTP/1.1" 200 OK
INFO:     47.219.10.126:50903 - "POST /postEpiClassifyText/ HTTP/1.1" 200 OK
INFO:     47.219.10.126:50906 - "POST /postEpiClassifyText/ HTTP/1.1" 200 OK
INFO:     47.219.10.126:50908 - "POST /postEpiClassifyText/ HTTP/1.1" 200 OK
INFO:     47.219.10.126:50912 - "POST /postEpiClassifyText/ HTTP/1.1" 200 OK
INFO:     47.219.10.126:50915 - "POST /postEpiClassifyText/ HTTP/1.1" 200 OK
INFO:     47.219.10.126:50918 - "POST /postEpiClassifyText/ HTTP/1.1" 200 OK
INFO:     47.219.10.126:50921 - "POST /postEpiClassifyText/ HTTP/1.1" 200 OK
INFO:     47.219.10.126:50923 - "POST /postEpiClassifyText/ HTTP/1.1" 200 OK
INFO:     47.219.10.126:50925 - "POST /postEpiClassifyText/ HTTP/1.1" 200 OK
INFO:     47.219.10.126:50927 - "POST /postEpiClassifyText/ HTTP/1.1" 200 OK
INFO:     47.219.10.126:50929 - "POST /postEpiClassifyText/ HTTP/1.1" 200 OK
INFO:     47.219.10.126:50931 - "POST /postEpiClassifyText/ HTTP/1.1" 200 OK
INFO:     47.219.10.126:50933 - "POST /postEpiClassifyText/ HTTP/1.1" 200 OK
INFO:     47.219.10.126:50936 - "POST /postEpiClassifyText/ HTTP/1.1" 200 OK
INFO:     47.219.10.126:50938 - "POST /postEpiClassifyText/ HTTP/1.1" 200 OK
INFO:     47.219.10.126:50940 - "POST /postEpiClassifyText/ HTTP/1.1" 200 OK
INFO:     47.219.10.126:50942 - "POST /postEpiClassifyText/ HTTP/1.1" 200 OK
INFO:     47.219.10.126:50944 - "POST /postEpiClassifyText/ HTTP/1.1" 200 OK
INFO:     47.219.10.126:50946 - "POST /postEpiClassifyText/ HTTP/1.1" 200 OK
INFO:     47.219.10.126:50948 - "POST /postEpiClassifyText/ HTTP/1.1" 200 OK
INFO:     47.219.10.126:50950 - "POST /postEpiClassifyText/ HTTP/1.1" 200 OK
INFO:     47.219.10.126:50954 - "POST /postEpiClassifyText/ HTTP/1.1" 200 OK
INFO:     47.219.10.126:50957 - "POST /postEpiClassifyText/ HTTP/1.1" 200 OK
INFO:     47.219.10.126:50965 - "POST /postEpiClassifyText/ HTTP/1.1" 200 OK
INFO:     47.219.10.126:50967 - "POST /postEpiClassifyText/ HTTP/1.1" 200 OK
INFO:     47.219.10.126:50969 - "POST /postEpiClassifyText/ HTTP/1.1" 200 OK
INFO:     47.219.10.126:50971 - "POST /postEpiClassifyText/ HTTP/1.1" 200 OK
INFO:     47.219.10.126:50973 - "POST /postEpiClassifyText/ HTTP/1.1" 200 OK
INFO:     47.219.10.126:50975 - "POST /postEpiClassifyText/ HTTP/1.1" 200 OK
INFO:     47.219.10.126:50977 - "POST /postEpiClassifyText/ HTTP/1.1" 200 OK
INFO:     47.219.10.126:50981 - "POST /postEpiClassifyText/ HTTP/1.1" 200 OK
INFO:     47.219.10.126:50983 - "POST /postEpiClassifyText/ HTTP/1.1" 200 OK
INFO:     47.219.10.126:50986 - "POST /postEpiClassifyText/ HTTP/1.1" 200 OK
INFO:     47.219.10.126:50988 - "POST /postEpiClassifyText/ HTTP/1.1" 200 OK
INFO:     47.219.10.126:50991 - "POST /postEpiClassifyText/ HTTP/1.1" 200 OK
INFO:     47.219.10.126:50993 - "POST /postEpiClassifyText/ HTTP/1.1" 200 OK
INFO:     47.219.10.126:50995 - "POST /postEpiClassifyText/ HTTP/1.1" 200 OK
INFO:     47.219.10.126:50997 - "POST /postEpiClassifyText/ HTTP/1.1" 200 OK
INFO:     47.219.10.126:50999 - "POST /postEpiClassifyText/ HTTP/1.1" 200 OK
INFO:     47.219.10.126:51001 - "POST /postEpiClassifyText/ HTTP/1.1" 200 OK
INFO:     47.219.10.126:51003 - "POST /postEpiClassifyText/ HTTP/1.1" 200 OK
INFO:     47.219.10.126:51005 - "POST /postEpiClassifyText/ HTTP/1.1" 200 OK
INFO:     47.219.10.126:51007 - "POST /postEpiClassifyText/ HTTP/1.1" 200 OK
INFO:     47.219.10.126:51009 - "POST /postEpiClassifyText/ HTTP/1.1" 200 OK
INFO:     47.219.10.126:51011 - "POST /postEpiClassifyText/ HTTP/1.1" 200 OK
INFO:     47.219.10.126:51013 - "POST /postEpiClassifyText/ HTTP/1.1" 200 OK
INFO:     47.219.10.126:51015 - "POST /postEpiClassifyText/ HTTP/1.1" 200 OK
INFO:     47.219.10.126:51017 - "POST /postEpiClassifyText/ HTTP/1.1" 200 OK
INFO:     47.219.10.126:51019 - "POST /postEpiClassifyText/ HTTP/1.1" 200 OK
INFO:     47.219.10.126:51021 - "POST /postEpiClassifyText/ HTTP/1.1" 200 OK
INFO:     47.219.10.126:51023 - "GET /docs HTTP/1.1" 200 OK
INFO:     47.219.10.126:51024 - "POST /postEpiClassifyText/ HTTP/1.1" 200 OK
INFO:     47.219.10.126:51023 - "GET /openapi.json HTTP/1.1" 200 OK
INFO:     47.219.10.126:51027 - "POST /postEpiClassifyText/ HTTP/1.1" 200 OK
INFO:     47.219.10.126:51029 - "POST /postEpiClassifyText/ HTTP/1.1" 200 OK
INFO:     18.215.184.142:35216 - "GET /docs HTTP/1.1" 200 OK
INFO:     47.219.10.126:51031 - "POST /postEpiClassifyText/ HTTP/1.1" 200 OK
INFO:     47.219.10.126:51033 - "POST /postEpiClassifyText/ HTTP/1.1" 200 OK
INFO:     47.219.10.126:51035 - "GET /redoc HTTP/1.1" 200 OK
INFO:     47.219.10.126:51035 - "GET /openapi.json HTTP/1.1" 200 OK
INFO:     47.219.10.126:51036 - "POST /postEpiClassifyText/ HTTP/1.1" 200 OK
INFO:     47.219.10.126:51038 - "POST /postEpiClassifyText/ HTTP/1.1" 200 OK
INFO:     47.219.10.126:51040 - "POST /postEpiClassifyText/ HTTP/1.1" 200 OK
INFO:     3.84.24.178:25670 - "GET /redoc HTTP/1.1" 200 OK
INFO:     47.219.10.126:51042 - "POST /postEpiClassifyText/ HTTP/1.1" 200 OK
INFO:     47.219.10.126:51044 - "POST /postEpiClassifyText/ HTTP/1.1" 200 OK
INFO:     47.219.10.126:51046 - "POST /postEpiClassifyText/ HTTP/1.1" 200 OK
INFO:     47.219.10.126:51048 - "POST /postEpiClassifyText/ HTTP/1.1" 200 OK
INFO:     47.219.10.126:51050 - "POST /postEpiClassifyText/ HTTP/1.1" 200 OK
INFO:     47.219.10.126:51052 - "POST /postEpiClassifyText/ HTTP/1.1" 200 OK
INFO:     47.219.10.126:51054 - "POST /postEpiClassifyText/ HTTP/1.1" 200 OK
INFO:     47.219.10.126:51056 - "POST /postEpiClassifyText/ HTTP/1.1" 200 OK
INFO:     47.219.10.126:51058 - "POST /postEpiClassifyText/ HTTP/1.1" 200 OK
INFO:     47.219.10.126:51060 - "POST /postEpiClassifyText/ HTTP/1.1" 200 OK
INFO:     47.219.10.126:51062 - "POST /postEpiClassifyText/ HTTP/1.1" 200 OK
INFO:     47.219.10.126:51064 - "POST /postEpiClassifyText/ HTTP/1.1" 200 OK
INFO:     47.219.10.126:51066 - "POST /postEpiClassifyText/ HTTP/1.1" 200 OK
INFO:     47.219.10.126:51070 - "POST /postEpiClassifyText/ HTTP/1.1" 200 OK
INFO:     47.219.10.126:51072 - "POST /postEpiClassifyText/ HTTP/1.1" 200 OK
INFO:     47.219.10.126:51074 - "POST /postEpiClassifyText/ HTTP/1.1" 200 OK
INFO:     47.219.10.126:51076 - "POST /postEpiClassifyText/ HTTP/1.1" 200 OK
INFO:     47.219.10.126:51078 - "POST /postEpiClassifyText/ HTTP/1.1" 200 OK
INFO:     47.219.10.126:51081 - "POST /postEpiClassifyText/ HTTP/1.1" 200 OK
INFO:     47.219.10.126:51083 - "POST /postEpiClassifyText/ HTTP/1.1" 200 OK
INFO:     47.219.10.126:51085 - "POST /postEpiClassifyText/ HTTP/1.1" 200 OK
INFO:     47.219.10.126:51087 - "POST /postEpiClassifyText/ HTTP/1.1" 200 OK
INFO:     47.219.10.126:51089 - "POST /postEpiClassifyText/ HTTP/1.1" 200 OK
INFO:     47.219.10.126:51091 - "POST /postEpiClassifyText/ HTTP/1.1" 200 OK
INFO:     47.219.10.126:51094 - "POST /postEpiClassifyText/ HTTP/1.1" 200 OK
INFO:     47.219.10.126:51096 - "POST /postEpiClassifyText/ HTTP/1.1" 200 OK
INFO:     47.219.10.126:51098 - "POST /postEpiClassifyText/ HTTP/1.1" 200 OK
INFO:     47.219.10.126:51100 - "POST /postEpiClassifyText/ HTTP/1.1" 200 OK
INFO:     47.219.10.126:51102 - "POST /postEpiClassifyText/ HTTP/1.1" 200 OK
INFO:     47.219.10.126:51104 - "POST /postEpiClassifyText/ HTTP/1.1" 200 OK
INFO:     47.219.10.126:51106 - "POST /postEpiClassifyText/ HTTP/1.1" 200 OK
INFO:     47.219.10.126:51109 - "POST /postEpiClassifyText/ HTTP/1.1" 200 OK
INFO:     47.219.10.126:51111 - "POST /postEpiClassifyText/ HTTP/1.1" 200 OK
INFO:     47.219.10.126:51113 - "POST /postEpiClassifyText/ HTTP/1.1" 200 OK
INFO:     47.219.10.126:51115 - "POST /postEpiClassifyText/ HTTP/1.1" 200 OK
INFO:     47.219.10.126:51120 - "POST /postEpiClassifyText/ HTTP/1.1" 200 OK
INFO:     47.219.10.126:51123 - "POST /postEpiClassifyText/ HTTP/1.1" 200 OK
INFO:     47.219.10.126:51125 - "POST /postEpiClassifyText/ HTTP/1.1" 200 OK
INFO:     47.219.10.126:51127 - "POST /postEpiClassifyText/ HTTP/1.1" 200 OK
INFO:     47.219.10.126:51129 - "POST /postEpiClassifyText/ HTTP/1.1" 200 OK
INFO:     47.219.10.126:51132 - "POST /postEpiClassifyText/ HTTP/1.1" 200 OK
INFO:     47.219.10.126:51134 - "POST /postEpiClassifyText/ HTTP/1.1" 200 OK
INFO:     47.219.10.126:51139 - "POST /postEpiClassifyText/ HTTP/1.1" 200 OK
INFO:     47.219.10.126:51141 - "POST /postEpiClassifyText/ HTTP/1.1" 200 OK
INFO:     47.219.10.126:51143 - "POST /postEpiClassifyText/ HTTP/1.1" 200 OK
INFO:     47.219.10.126:51145 - "POST /postEpiClassifyText/ HTTP/1.1" 200 OK
INFO:     47.219.10.126:51147 - "POST /postEpiClassifyText/ HTTP/1.1" 200 OK
INFO:     47.219.10.126:51154 - "POST /postEpiClassifyText/ HTTP/1.1" 200 OK
INFO:     47.219.10.126:51157 - "POST /postEpiClassifyText/ HTTP/1.1" 200 OK
INFO:     47.219.10.126:51159 - "POST /postEpiClassifyText/ HTTP/1.1" 200 OK
INFO:     47.219.10.126:51161 - "POST /postEpiClassifyText/ HTTP/1.1" 200 OK
INFO:     47.219.10.126:51164 - "POST /postEpiClassifyText/ HTTP/1.1" 200 OK
INFO:     47.219.10.126:51166 - "POST /postEpiClassifyText/ HTTP/1.1" 200 OK
INFO:     47.219.10.126:51169 - "POST /postEpiClassifyText/ HTTP/1.1" 200 OK
INFO:     47.219.10.126:51172 - "POST /postEpiClassifyText/ HTTP/1.1" 200 OK
INFO:     47.219.10.126:51174 - "POST /postEpiClassifyText/ HTTP/1.1" 200 OK
INFO:     47.219.10.126:51177 - "POST /postEpiClassifyText/ HTTP/1.1" 200 OK
INFO:     47.219.10.126:51186 - "POST /postEpiClassifyText/ HTTP/1.1" 200 OK
INFO:     47.219.10.126:51188 - "POST /postEpiClassifyText/ HTTP/1.1" 200 OK
INFO:     47.219.10.126:51190 - "POST /postEpiClassifyText/ HTTP/1.1" 200 OK
INFO:     47.219.10.126:51192 - "POST /postEpiClassifyText/ HTTP/1.1" 200 OK
INFO:     47.219.10.126:51194 - "POST /postEpiClassifyText/ HTTP/1.1" 200 OK
INFO:     47.219.10.126:51196 - "POST /postEpiClassifyText/ HTTP/1.1" 200 OK
INFO:     47.219.10.126:51201 - "POST /postEpiClassifyText/ HTTP/1.1" 200 OK
INFO:     47.219.10.126:51207 - "POST /postEpiClassifyText/ HTTP/1.1" 200 OK
INFO:     47.219.10.126:51210 - "POST /postEpiClassifyText/ HTTP/1.1" 200 OK
INFO:     47.219.10.126:51212 - "POST /postEpiClassifyText/ HTTP/1.1" 200 OK
INFO:     47.219.10.126:51214 - "POST /postEpiClassifyText/ HTTP/1.1" 200 OK
INFO:     47.219.10.126:51216 - "POST /postEpiClassifyText/ HTTP/1.1" 200 OK
INFO:     47.219.10.126:51218 - "POST /postEpiClassifyText/ HTTP/1.1" 200 OK
INFO:     47.219.10.126:51220 - "POST /postEpiClassifyText/ HTTP/1.1" 200 OK
INFO:     47.219.10.126:51223 - "POST /postEpiClassifyText/ HTTP/1.1" 200 OK
INFO:     47.219.10.126:51225 - "POST /postEpiClassifyText/ HTTP/1.1" 200 OK
INFO:     47.219.10.126:51227 - "POST /postEpiClassifyText/ HTTP/1.1" 200 OK
INFO:     47.219.10.126:51230 - "POST /postEpiClassifyText/ HTTP/1.1" 200 OK
INFO:     47.219.10.126:51232 - "POST /postEpiClassifyText/ HTTP/1.1" 200 OK
INFO:     47.219.10.126:51236 - "POST /postEpiClassifyText/ HTTP/1.1" 200 OK
INFO:     47.219.10.126:51238 - "POST /postEpiClassifyText/ HTTP/1.1" 200 OK
INFO:     47.219.10.126:51240 - "POST /postEpiClassifyText/ HTTP/1.1" 200 OK
INFO:     47.219.10.126:51242 - "POST /postEpiClassifyText/ HTTP/1.1" 200 OK
INFO:     47.219.10.126:51244 - "POST /postEpiClassifyText/ HTTP/1.1" 200 OK
INFO:     47.219.10.126:51246 - "POST /postEpiClassifyText/ HTTP/1.1" 200 OK
INFO:     47.219.10.126:51248 - "POST /postEpiClassifyText/ HTTP/1.1" 200 OK
INFO:     47.219.10.126:51250 - "POST /postEpiClassifyText/ HTTP/1.1" 200 OK
INFO:     47.219.10.126:51252 - "POST /postEpiClassifyText/ HTTP/1.1" 200 OK
INFO:     47.219.10.126:51254 - "POST /postEpiClassifyText/ HTTP/1.1" 200 OK
INFO:     47.219.10.126:51260 - "POST /postEpiClassifyText/ HTTP/1.1" 200 OK
INFO:     47.219.10.126:51262 - "POST /postEpiClassifyText/ HTTP/1.1" 200 OK
INFO:     47.219.10.126:51264 - "POST /postEpiClassifyText/ HTTP/1.1" 200 OK
INFO:     47.219.10.126:51267 - "POST /postEpiClassifyText/ HTTP/1.1" 200 OK
INFO:     47.219.10.126:51272 - "POST /postEpiClassifyText/ HTTP/1.1" 200 OK
INFO:     47.219.10.126:51278 - "POST /postEpiClassifyText/ HTTP/1.1" 200 OK
INFO:     47.219.10.126:51281 - "POST /postEpiClassifyText/ HTTP/1.1" 200 OK
INFO:     47.219.10.126:51284 - "POST /postEpiClassifyText/ HTTP/1.1" 200 OK
INFO:     47.219.10.126:51287 - "POST /postEpiClassifyText/ HTTP/1.1" 200 OK
INFO:     47.219.10.126:51289 - "POST /postEpiClassifyText/ HTTP/1.1" 200 OK
INFO:     47.219.10.126:51291 - "POST /postEpiClassifyText/ HTTP/1.1" 200 OK
INFO:     47.219.10.126:51293 - "POST /postEpiClassifyText/ HTTP/1.1" 200 OK
INFO:     47.219.10.126:51296 - "POST /postEpiClassifyText/ HTTP/1.1" 200 OK
INFO:     47.219.10.126:51300 - "POST /postEpiClassifyText/ HTTP/1.1" 200 OK
INFO:     47.219.10.126:51303 - "POST /postEpiClassifyText/ HTTP/1.1" 200 OK
INFO:     47.219.10.126:51311 - "POST /postEpiClassifyText/ HTTP/1.1" 200 OK
INFO:     47.219.10.126:51313 - "POST /postEpiClassifyText/ HTTP/1.1" 200 OK
INFO:     47.219.10.126:51316 - "POST /postEpiClassifyText/ HTTP/1.1" 200 OK
INFO:     47.219.10.126:51319 - "POST /postEpiClassifyText/ HTTP/1.1" 200 OK
INFO:     47.219.10.126:51323 - "POST /postEpiClassifyText/ HTTP/1.1" 200 OK
INFO:     47.219.10.126:51327 - "POST /postEpiClassifyText/ HTTP/1.1" 200 OK
INFO:     47.219.10.126:51332 - "POST /postEpiClassifyText/ HTTP/1.1" 200 OK
INFO:     47.219.10.126:51334 - "POST /postEpiClassifyText/ HTTP/1.1" 200 OK
INFO:     47.219.10.126:51336 - "POST /postEpiClassifyText/ HTTP/1.1" 200 OK
INFO:     47.219.10.126:51338 - "POST /postEpiClassifyText/ HTTP/1.1" 200 OK
INFO:     47.219.10.126:51340 - "POST /postEpiClassifyText/ HTTP/1.1" 200 OK
INFO:     47.219.10.126:51343 - "POST /postEpiClassifyText/ HTTP/1.1" 200 OK
INFO:     47.219.10.126:51346 - "POST /postEpiClassifyText/ HTTP/1.1" 200 OK
INFO:     47.219.10.126:51352 - "POST /postEpiClassifyText/ HTTP/1.1" 200 OK
INFO:     47.219.10.126:51355 - "POST /postEpiClassifyText/ HTTP/1.1" 200 OK
INFO:     47.219.10.126:51357 - "POST /postEpiClassifyText/ HTTP/1.1" 200 OK
INFO:     47.219.10.126:51359 - "POST /postEpiClassifyText/ HTTP/1.1" 200 OK
INFO:     47.219.10.126:51361 - "POST /postEpiClassifyText/ HTTP/1.1" 200 OK
INFO:     47.219.10.126:51363 - "POST /postEpiClassifyText/ HTTP/1.1" 200 OK
INFO:     47.219.10.126:51365 - "POST /postEpiClassifyText/ HTTP/1.1" 200 OK
INFO:     47.219.10.126:51368 - "POST /postEpiClassifyText/ HTTP/1.1" 200 OK
INFO:     47.219.10.126:51370 - "POST /postEpiClassifyText/ HTTP/1.1" 200 OK
INFO:     47.219.10.126:51372 - "POST /postEpiClassifyText/ HTTP/1.1" 200 OK
INFO:     47.219.10.126:51374 - "POST /postEpiClassifyText/ HTTP/1.1" 200 OK
INFO:     47.219.10.126:51377 - "POST /postEpiClassifyText/ HTTP/1.1" 200 OK
INFO:     47.219.10.126:51379 - "POST /postEpiClassifyText/ HTTP/1.1" 200 OK
INFO:     47.219.10.126:51516 - "GET /docs HTTP/1.1" 200 OK
INFO:     47.219.10.126:51516 - "GET /openapi.json HTTP/1.1" 200 OK
INFO:     47.219.10.126:52909 - "POST /postEpiClassifyText/ HTTP/1.1" 200 OK
INFO:     47.219.10.126:52912 - "POST /postEpiClassifyText/ HTTP/1.1" 200 OK
INFO:     47.219.10.126:52917 - "POST /postEpiClassifyText/ HTTP/1.1" 200 OK
INFO:     47.219.10.126:52920 - "POST /postEpiClassifyText/ HTTP/1.1" 200 OK
INFO:     47.219.10.126:52923 - "POST /postEpiClassifyText/ HTTP/1.1" 200 OK
INFO:     47.219.10.126:52925 - "POST /postEpiClassifyText/ HTTP/1.1" 200 OK
INFO:     47.219.10.126:52928 - "POST /postEpiClassifyText/ HTTP/1.1" 200 OK
INFO:     47.219.10.126:52930 - "POST /postEpiClassifyText/ HTTP/1.1" 200 OK
INFO:     47.219.10.126:53230 - "POST /postEpiClassifyText/ HTTP/1.1" 200 OK
INFO:     47.219.10.126:53233 - "POST /postEpiClassifyText/ HTTP/1.1" 200 OK
INFO:     47.219.10.126:53240 - "POST /postEpiClassifyText/ HTTP/1.1" 200 OK
INFO:     47.219.10.126:53248 - "POST /postEpiClassifyText/ HTTP/1.1" 200 OK
INFO:     47.219.10.126:53257 - "POST /postEpiClassifyText/ HTTP/1.1" 200 OK
INFO:     47.219.10.126:53259 - "POST /postEpiClassifyText/ HTTP/1.1" 200 OK
INFO:     47.219.10.126:53286 - "POST /postEpiClassifyText/ HTTP/1.1" 200 OK
INFO:     47.219.10.126:53291 - "POST /postEpiClassifyText/ HTTP/1.1" 200 OK
INFO:     47.219.10.126:53294 - "POST /postEpiClassifyText/ HTTP/1.1" 200 OK
INFO:     47.219.10.126:53297 - "POST /postEpiClassifyText/ HTTP/1.1" 200 OK
INFO:     47.219.10.126:53383 - "POST /postEpiClassifyText/ HTTP/1.1" 200 OK
INFO:     47.219.10.126:53386 - "POST /postEpiClassifyText/ HTTP/1.1" 200 OK
INFO:     47.219.10.126:53390 - "POST /postEpiClassifyText/ HTTP/1.1" 200 OK
INFO:     47.219.10.126:53393 - "POST /postEpiClassifyText/ HTTP/1.1" 200 OK
INFO:     47.219.10.126:53519 - "POST /postEpiClassifyText/ HTTP/1.1" 200 OK
INFO:     47.219.10.126:53522 - "POST /postEpiClassifyText/ HTTP/1.1" 200 OK
INFO:     47.219.10.126:53525 - "POST /postEpiClassifyText/ HTTP/1.1" 200 OK
INFO:     47.219.10.126:53528 - "POST /postEpiClassifyText/ HTTP/1.1" 200 OK
INFO:     47.219.10.126:53532 - "POST /postEpiClassifyText/ HTTP/1.1" 200 OK
INFO:     47.219.10.126:53534 - "POST /postEpiClassifyText/ HTTP/1.1" 200 OK
INFO:     47.219.10.126:53591 - "POST /postEpiClassifyText/ HTTP/1.1" 200 OK
INFO:     47.219.10.126:53594 - "POST /postEpiClassifyText/ HTTP/1.1" 200 OK
INFO:     47.219.10.126:53597 - "POST /postEpiClassifyText/ HTTP/1.1" 200 OK
INFO:     47.219.10.126:53600 - "POST /postEpiClassifyText/ HTTP/1.1" 200 OK
INFO:     47.219.10.126:53610 - "POST /postEpiClassifyText/ HTTP/1.1" 200 OK
INFO:     47.219.10.126:53613 - "POST /postEpiClassifyText/ HTTP/1.1" 200 OK
INFO:     47.219.10.126:53617 - "POST /postEpiClassifyText/ HTTP/1.1" 200 OK
INFO:     47.219.10.126:53621 - "POST /postEpiClassifyText/ HTTP/1.1" 200 OK
INFO:     47.219.10.126:53623 - "POST /postEpiClassifyText/ HTTP/1.1" 200 OK
INFO:     47.219.10.126:53628 - "POST /postEpiClassifyText/ HTTP/1.1" 200 OK
INFO:     47.219.10.126:53630 - "POST /postEpiClassifyText/ HTTP/1.1" 200 OK
INFO:     47.219.10.126:53632 - "POST /postEpiClassifyText/ HTTP/1.1" 200 OK
INFO:     47.219.10.126:53634 - "POST /postEpiClassifyText/ HTTP/1.1" 200 OK
INFO:     47.219.10.126:53636 - "POST /postEpiClassifyText/ HTTP/1.1" 200 OK
INFO:     47.219.10.126:53638 - "POST /postEpiClassifyText/ HTTP/1.1" 200 OK
INFO:     47.219.10.126:53640 - "POST /postEpiClassifyText/ HTTP/1.1" 200 OK
INFO:     47.219.10.126:53642 - "POST /postEpiClassifyText/ HTTP/1.1" 200 OK
INFO:     47.219.10.126:53644 - "POST /postEpiClassifyText/ HTTP/1.1" 200 OK
INFO:     47.219.10.126:53802 - "POST /postEpiClassifyText/ HTTP/1.1" 200 OK
INFO:     47.219.10.126:53899 - "POST /postEpiClassifyText/ HTTP/1.1" 200 OK
INFO:     47.219.10.126:53907 - "POST /postEpiClassifyText/ HTTP/1.1" 200 OK
INFO:     47.219.10.126:53909 - "POST /postEpiClassifyText/ HTTP/1.1" 200 OK
INFO:     47.219.10.126:53911 - "POST /postEpiClassifyText/ HTTP/1.1" 200 OK
INFO:     47.219.10.126:53913 - "POST /postEpiClassifyText/ HTTP/1.1" 200 OK
INFO:     47.219.10.126:53919 - "POST /postEpiClassifyText/ HTTP/1.1" 200 OK
INFO:     47.219.10.126:53922 - "POST /postEpiClassifyText/ HTTP/1.1" 200 OK
INFO:     47.219.10.126:53925 - "POST /postEpiClassifyText/ HTTP/1.1" 200 OK
INFO:     47.219.10.126:53927 - "POST /postEpiClassifyText/ HTTP/1.1" 200 OK
INFO:     47.219.10.126:53929 - "POST /postEpiClassifyText/ HTTP/1.1" 200 OK
INFO:     47.219.10.126:53931 - "POST /postEpiClassifyText/ HTTP/1.1" 200 OK
INFO:     47.219.10.126:53936 - "POST /postEpiClassifyText/ HTTP/1.1" 200 OK
INFO:     47.219.10.126:53941 - "POST /postEpiClassifyText/ HTTP/1.1" 200 OK
INFO:     47.219.10.126:53947 - "POST /postEpiClassifyText/ HTTP/1.1" 200 OK
INFO:     47.219.10.126:53949 - "POST /postEpiClassifyText/ HTTP/1.1" 200 OK
INFO:     47.219.10.126:53954 - "POST /postEpiClassifyText/ HTTP/1.1" 200 OK
INFO:     47.219.10.126:53958 - "POST /postEpiClassifyText/ HTTP/1.1" 200 OK
INFO:     47.219.10.126:53960 - "POST /postEpiClassifyText/ HTTP/1.1" 200 OK
INFO:     47.219.10.126:53962 - "POST /postEpiClassifyText/ HTTP/1.1" 200 OK
INFO:     47.219.10.126:53964 - "POST /postEpiClassifyText/ HTTP/1.1" 200 OK
INFO:     47.219.10.126:53969 - "POST /postEpiClassifyText/ HTTP/1.1" 200 OK
INFO:     47.219.10.126:53971 - "POST /postEpiClassifyText/ HTTP/1.1" 200 OK
INFO:     47.219.10.126:53975 - "POST /postEpiClassifyText/ HTTP/1.1" 200 OK
INFO:     47.219.10.126:53977 - "POST /postEpiClassifyText/ HTTP/1.1" 200 OK
INFO:     47.219.10.126:53982 - "POST /postEpiClassifyText/ HTTP/1.1" 200 OK
INFO:     47.219.10.126:53986 - "POST /postEpiClassifyText/ HTTP/1.1" 200 OK
INFO:     47.219.10.126:53988 - "POST /postEpiClassifyText/ HTTP/1.1" 200 OK
INFO:     47.219.10.126:53992 - "POST /postEpiClassifyText/ HTTP/1.1" 200 OK
INFO:     47.219.10.126:53994 - "POST /postEpiClassifyText/ HTTP/1.1" 200 OK
INFO:     47.219.10.126:53998 - "POST /postEpiClassifyText/ HTTP/1.1" 200 OK
INFO:     47.219.10.126:54000 - "POST /postEpiClassifyText/ HTTP/1.1" 200 OK
INFO:     47.219.10.126:54005 - "POST /postEpiClassifyText/ HTTP/1.1" 200 OK
INFO:     47.219.10.126:54010 - "POST /postEpiClassifyText/ HTTP/1.1" 200 OK
INFO:     47.219.10.126:54014 - "POST /postEpiClassifyText/ HTTP/1.1" 200 OK
INFO:     47.219.10.126:54017 - "POST /postEpiClassifyText/ HTTP/1.1" 200 OK
INFO:     47.219.10.126:54019 - "POST /postEpiClassifyText/ HTTP/1.1" 200 OK
INFO:     47.219.10.126:54022 - "POST /postEpiClassifyText/ HTTP/1.1" 200 OK
INFO:     47.219.10.126:54025 - "POST /postEpiClassifyText/ HTTP/1.1" 200 OK
INFO:     47.219.10.126:54031 - "POST /postEpiClassifyText/ HTTP/1.1" 200 OK
INFO:     47.219.10.126:54037 - "POST /postEpiClassifyText/ HTTP/1.1" 200 OK
INFO:     47.219.10.126:54039 - "POST /postEpiClassifyText/ HTTP/1.1" 200 OK
INFO:     47.219.10.126:54042 - "POST /postEpiClassifyText/ HTTP/1.1" 200 OK
INFO:     47.219.10.126:54045 - "POST /postEpiClassifyText/ HTTP/1.1" 200 OK
INFO:     47.219.10.126:54049 - "POST /postEpiClassifyText/ HTTP/1.1" 200 OK
INFO:     47.219.10.126:54051 - "POST /postEpiClassifyText/ HTTP/1.1" 200 OK
INFO:     47.219.10.126:54053 - "POST /postEpiClassifyText/ HTTP/1.1" 200 OK
INFO:     47.219.10.126:54057 - "POST /postEpiClassifyText/ HTTP/1.1" 200 OK
INFO:     47.219.10.126:54059 - "POST /postEpiClassifyText/ HTTP/1.1" 200 OK
INFO:     47.219.10.126:54064 - "POST /postEpiClassifyText/ HTTP/1.1" 200 OK
INFO:     47.219.10.126:54066 - "POST /postEpiClassifyText/ HTTP/1.1" 200 OK
INFO:     47.219.10.126:54068 - "POST /postEpiClassifyText/ HTTP/1.1" 200 OK
INFO:     47.219.10.126:54072 - "POST /postEpiClassifyText/ HTTP/1.1" 200 OK
INFO:     47.219.10.126:54074 - "POST /postEpiClassifyText/ HTTP/1.1" 200 OK
INFO:     47.219.10.126:54079 - "POST /postEpiClassifyText/ HTTP/1.1" 200 OK
INFO:     47.219.10.126:54080 - "GET /docs HTTP/1.1" 200 OK
INFO:     47.219.10.126:54080 - "GET /openapi.json HTTP/1.1" 200 OK
INFO:     47.219.10.126:54084 - "POST /postEpiClassifyText/ HTTP/1.1" 200 OK
INFO:     47.219.10.126:54086 - "POST /postEpiClassifyText/ HTTP/1.1" 200 OK
INFO:     47.219.10.126:54088 - "POST /postEpiClassifyText/ HTTP/1.1" 200 OK
INFO:     47.219.10.126:54090 - "POST /postEpiClassifyText/ HTTP/1.1" 200 OK
INFO:     47.219.10.126:54095 - "POST /postEpiClassifyText/ HTTP/1.1" 200 OK
INFO:     47.219.10.126:54097 - "POST /postEpiClassifyText/ HTTP/1.1" 200 OK
INFO:     47.219.10.126:54099 - "POST /postEpiClassifyText/ HTTP/1.1" 200 OK
INFO:     47.219.10.126:54101 - "POST /postEpiClassifyText/ HTTP/1.1" 200 OK
INFO:     47.219.10.126:54103 - "POST /postEpiClassifyText/ HTTP/1.1" 200 OK
INFO:     47.219.10.126:54107 - "POST /postEpiClassifyText/ HTTP/1.1" 200 OK
INFO:     47.219.10.126:54111 - "POST /postEpiClassifyText/ HTTP/1.1" 200 OK
INFO:     47.219.10.126:54113 - "POST /postEpiClassifyText/ HTTP/1.1" 200 OK
INFO:     47.219.10.126:54120 - "POST /postEpiClassifyText/ HTTP/1.1" 200 OK
INFO:     47.219.10.126:54122 - "POST /postEpiClassifyText/ HTTP/1.1" 200 OK
INFO:     47.219.10.126:54127 - "POST /postEpiClassifyText/ HTTP/1.1" 200 OK
INFO:     47.219.10.126:54129 - "POST /postEpiClassifyText/ HTTP/1.1" 200 OK
INFO:     47.219.10.126:54131 - "POST /postEpiClassifyText/ HTTP/1.1" 200 OK
INFO:     47.219.10.126:54133 - "POST /postEpiClassifyText/ HTTP/1.1" 200 OK
INFO:     47.219.10.126:54135 - "POST /postEpiClassifyText/ HTTP/1.1" 200 OK
INFO:     47.219.10.126:54138 - "POST /postEpiClassifyText/ HTTP/1.1" 200 OK
INFO:     47.219.10.126:54144 - "POST /postEpiClassifyText/ HTTP/1.1" 200 OK
INFO:     47.219.10.126:54146 - "POST /postEpiClassifyText/ HTTP/1.1" 200 OK
INFO:     47.219.10.126:54148 - "POST /postEpiClassifyText/ HTTP/1.1" 200 OK
INFO:     47.219.10.126:54150 - "POST /postEpiClassifyText/ HTTP/1.1" 200 OK
INFO:     47.219.10.126:54154 - "POST /postEpiClassifyText/ HTTP/1.1" 200 OK
INFO:     47.219.10.126:54160 - "POST /postEpiClassifyText/ HTTP/1.1" 200 OK
INFO:     47.219.10.126:54162 - "POST /postEpiClassifyText/ HTTP/1.1" 200 OK
INFO:     47.219.10.126:54164 - "POST /postEpiClassifyText/ HTTP/1.1" 200 OK
INFO:     47.219.10.126:54167 - "POST /postEpiClassifyText/ HTTP/1.1" 200 OK
INFO:     47.219.10.126:54171 - "POST /postEpiClassifyText/ HTTP/1.1" 200 OK
INFO:     47.219.10.126:54174 - "POST /postEpiClassifyText/ HTTP/1.1" 200 OK
INFO:     47.219.10.126:54178 - "POST /postEpiClassifyText/ HTTP/1.1" 200 OK
INFO:     47.219.10.126:54180 - "POST /postEpiClassifyText/ HTTP/1.1" 200 OK
INFO:     47.219.10.126:54182 - "POST /postEpiClassifyText/ HTTP/1.1" 200 OK
INFO:     47.219.10.126:54184 - "POST /postEpiClassifyText/ HTTP/1.1" 200 OK
INFO:     47.219.10.126:54186 - "POST /postEpiClassifyText/ HTTP/1.1" 200 OK
INFO:     47.219.10.126:54193 - "POST /postEpiClassifyText/ HTTP/1.1" 200 OK
INFO:     47.219.10.126:54196 - "POST /postEpiClassifyText/ HTTP/1.1" 200 OK
INFO:     47.219.10.126:54200 - "POST /postEpiClassifyText/ HTTP/1.1" 200 OK
INFO:     47.219.10.126:54202 - "POST /postEpiClassifyText/ HTTP/1.1" 200 OK
INFO:     47.219.10.126:54204 - "POST /postEpiClassifyText/ HTTP/1.1" 200 OK
INFO:     47.219.10.126:54208 - "POST /postEpiClassifyText/ HTTP/1.1" 200 OK
INFO:     47.219.10.126:54213 - "POST /postEpiClassifyText/ HTTP/1.1" 200 OK
INFO:     47.219.10.126:54215 - "POST /postEpiClassifyText/ HTTP/1.1" 200 OK
INFO:     47.219.10.126:54217 - "POST /postEpiClassifyText/ HTTP/1.1" 200 OK
INFO:     47.219.10.126:54219 - "POST /postEpiClassifyText/ HTTP/1.1" 200 OK
INFO:     47.219.10.126:54222 - "POST /postEpiClassifyText/ HTTP/1.1" 200 OK
INFO:     47.219.10.126:54228 - "POST /postEpiClassifyText/ HTTP/1.1" 200 OK
INFO:     47.219.10.126:54230 - "POST /postEpiClassifyText/ HTTP/1.1" 200 OK
INFO:     47.219.10.126:54232 - "POST /postEpiClassifyText/ HTTP/1.1" 200 OK
INFO:     47.219.10.126:54234 - "POST /postEpiClassifyText/ HTTP/1.1" 200 OK
INFO:     47.219.10.126:54241 - "POST /postEpiClassifyText/ HTTP/1.1" 200 OK
INFO:     47.219.10.126:54243 - "POST /postEpiClassifyText/ HTTP/1.1" 200 OK
INFO:     47.219.10.126:54245 - "POST /postEpiClassifyText/ HTTP/1.1" 200 OK
INFO:     47.219.10.126:54247 - "POST /postEpiClassifyText/ HTTP/1.1" 200 OK
INFO:     47.219.10.126:54250 - "POST /postEpiClassifyText/ HTTP/1.1" 200 OK
INFO:     47.219.10.126:54257 - "POST /postEpiClassifyText/ HTTP/1.1" 200 OK
INFO:     47.219.10.126:54259 - "POST /postEpiClassifyText/ HTTP/1.1" 200 OK
INFO:     47.219.10.126:54261 - "POST /postEpiClassifyText/ HTTP/1.1" 200 OK
INFO:     47.219.10.126:54263 - "POST /postEpiClassifyText/ HTTP/1.1" 200 OK
INFO:     47.219.10.126:54265 - "POST /postEpiClassifyText/ HTTP/1.1" 200 OK
INFO:     47.219.10.126:54267 - "POST /postEpiClassifyText/ HTTP/1.1" 200 OK
INFO:     47.219.10.126:54272 - "POST /postEpiClassifyText/ HTTP/1.1" 200 OK
INFO:     47.219.10.126:54276 - "POST /postEpiClassifyText/ HTTP/1.1" 200 OK
INFO:     47.219.10.126:54278 - "POST /postEpiClassifyText/ HTTP/1.1" 200 OK
INFO:     47.219.10.126:54280 - "POST /postEpiClassifyText/ HTTP/1.1" 200 OK
INFO:     47.219.10.126:54282 - "POST /postEpiClassifyText/ HTTP/1.1" 200 OK
INFO:     47.219.10.126:54289 - "POST /postEpiClassifyText/ HTTP/1.1" 200 OK
INFO:     47.219.10.126:54291 - "POST /postEpiClassifyText/ HTTP/1.1" 200 OK
INFO:     47.219.10.126:54293 - "POST /postEpiClassifyText/ HTTP/1.1" 200 OK
INFO:     47.219.10.126:54295 - "POST /postEpiClassifyText/ HTTP/1.1" 200 OK
INFO:     47.219.10.126:54299 - "POST /postEpiClassifyText/ HTTP/1.1" 200 OK
INFO:     47.219.10.126:54304 - "POST /postEpiClassifyText/ HTTP/1.1" 200 OK
INFO:     47.219.10.126:54306 - "POST /postEpiClassifyText/ HTTP/1.1" 200 OK
INFO:     47.219.10.126:54308 - "POST /postEpiClassifyText/ HTTP/1.1" 200 OK
INFO:     47.219.10.126:54310 - "POST /postEpiClassifyText/ HTTP/1.1" 200 OK
INFO:     47.219.10.126:54316 - "POST /postEpiClassifyText/ HTTP/1.1" 200 OK
INFO:     47.219.10.126:54318 - "POST /postEpiClassifyText/ HTTP/1.1" 200 OK
INFO:     47.219.10.126:54322 - "POST /postEpiClassifyText/ HTTP/1.1" 200 OK
INFO:     47.219.10.126:54324 - "POST /postEpiClassifyText/ HTTP/1.1" 200 OK
INFO:     47.219.10.126:54327 - "POST /postEpiClassifyText/ HTTP/1.1" 200 OK
INFO:     47.219.10.126:54329 - "POST /postEpiClassifyText/ HTTP/1.1" 200 OK
INFO:     47.219.10.126:54333 - "POST /postEpiClassifyText/ HTTP/1.1" 200 OK
INFO:     47.219.10.126:54335 - "POST /postEpiClassifyText/ HTTP/1.1" 200 OK
INFO:     47.219.10.126:54337 - "POST /postEpiClassifyText/ HTTP/1.1" 200 OK
INFO:     47.219.10.126:54339 - "POST /postEpiClassifyText/ HTTP/1.1" 200 OK
INFO:     47.219.10.126:54341 - "POST /postEpiClassifyText/ HTTP/1.1" 200 OK
INFO:     47.219.10.126:54343 - "POST /postEpiClassifyText/ HTTP/1.1" 200 OK
INFO:     47.219.10.126:54346 - "POST /postEpiClassifyText/ HTTP/1.1" 200 OK
INFO:     47.219.10.126:54353 - "POST /postEpiClassifyText/ HTTP/1.1" 200 OK
INFO:     47.219.10.126:54355 - "POST /postEpiClassifyText/ HTTP/1.1" 200 OK
INFO:     47.219.10.126:54357 - "POST /postEpiClassifyText/ HTTP/1.1" 200 OK
INFO:     47.219.10.126:54359 - "POST /postEpiClassifyText/ HTTP/1.1" 200 OK
INFO:     47.219.10.126:54363 - "POST /postEpiClassifyText/ HTTP/1.1" 200 OK
INFO:     47.219.10.126:54365 - "POST /postEpiClassifyText/ HTTP/1.1" 200 OK
INFO:     47.219.10.126:54367 - "POST /postEpiClassifyText/ HTTP/1.1" 200 OK
INFO:     47.219.10.126:54369 - "POST /postEpiClassifyText/ HTTP/1.1" 200 OK
INFO:     47.219.10.126:54372 - "POST /postEpiClassifyText/ HTTP/1.1" 200 OK
INFO:     47.219.10.126:54374 - "POST /postEpiClassifyText/ HTTP/1.1" 200 OK
INFO:     47.219.10.126:54376 - "POST /postEpiClassifyText/ HTTP/1.1" 200 OK
INFO:     47.219.10.126:54378 - "POST /postEpiClassifyText/ HTTP/1.1" 200 OK
INFO:     47.219.10.126:54380 - "POST /postEpiClassifyText/ HTTP/1.1" 200 OK
INFO:     47.219.10.126:54382 - "POST /postEpiClassifyText/ HTTP/1.1" 200 OK
INFO:     47.219.10.126:54389 - "POST /postEpiClassifyText/ HTTP/1.1" 200 OK
INFO:     47.219.10.126:54391 - "POST /postEpiClassifyText/ HTTP/1.1" 200 OK
INFO:     47.219.10.126:54393 - "POST /postEpiClassifyText/ HTTP/1.1" 200 OK
INFO:     47.219.10.126:54396 - "POST /postEpiClassifyText/ HTTP/1.1" 200 OK
INFO:     47.219.10.126:54398 - "POST /postEpiClassifyText/ HTTP/1.1" 200 OK
INFO:     47.219.10.126:54400 - "POST /postEpiClassifyText/ HTTP/1.1" 200 OK
INFO:     47.219.10.126:54402 - "POST /postEpiClassifyText/ HTTP/1.1" 200 OK
INFO:     47.219.10.126:54404 - "POST /postEpiClassifyText/ HTTP/1.1" 200 OK
INFO:     47.219.10.126:54406 - "POST /postEpiClassifyText/ HTTP/1.1" 200 OK
INFO:     47.219.10.126:54408 - "POST /postEpiClassifyText/ HTTP/1.1" 200 OK
INFO:     47.219.10.126:54410 - "POST /postEpiClassifyText/ HTTP/1.1" 200 OK
INFO:     47.219.10.126:54412 - "POST /postEpiClassifyText/ HTTP/1.1" 200 OK
INFO:     47.219.10.126:54419 - "POST /postEpiClassifyText/ HTTP/1.1" 200 OK
INFO:     47.219.10.126:54421 - "POST /postEpiClassifyText/ HTTP/1.1" 200 OK
INFO:     47.219.10.126:54423 - "POST /postEpiClassifyText/ HTTP/1.1" 200 OK
INFO:     47.219.10.126:54425 - "POST /postEpiClassifyText/ HTTP/1.1" 200 OK
INFO:     47.219.10.126:54428 - "POST /postEpiClassifyText/ HTTP/1.1" 200 OK
INFO:     47.219.10.126:54430 - "POST /postEpiClassifyText/ HTTP/1.1" 200 OK
INFO:     47.219.10.126:54432 - "POST /postEpiClassifyText/ HTTP/1.1" 200 OK
INFO:     47.219.10.126:54434 - "POST /postEpiClassifyText/ HTTP/1.1" 200 OK
INFO:     47.219.10.126:54436 - "POST /postEpiClassifyText/ HTTP/1.1" 200 OK
INFO:     47.219.10.126:54438 - "POST /postEpiClassifyText/ HTTP/1.1" 200 OK
INFO:     47.219.10.126:54440 - "POST /postEpiClassifyText/ HTTP/1.1" 200 OK
INFO:     47.219.10.126:54442 - "POST /postEpiClassifyText/ HTTP/1.1" 200 OK
INFO:     47.219.10.126:54444 - "POST /postEpiClassifyText/ HTTP/1.1" 200 OK
INFO:     47.219.10.126:54454 - "POST /postEpiClassifyText/ HTTP/1.1" 200 OK
INFO:     47.219.10.126:54457 - "POST /postEpiClassifyText/ HTTP/1.1" 200 OK
INFO:     47.219.10.126:54459 - "POST /postEpiClassifyText/ HTTP/1.1" 200 OK
INFO:     47.219.10.126:54461 - "POST /postEpiClassifyText/ HTTP/1.1" 200 OK
INFO:     47.219.10.126:54465 - "POST /postEpiClassifyText/ HTTP/1.1" 200 OK
INFO:     47.219.10.126:54467 - "POST /postEpiClassifyText/ HTTP/1.1" 200 OK
INFO:     47.219.10.126:54469 - "POST /postEpiClassifyText/ HTTP/1.1" 200 OK
INFO:     47.219.10.126:54471 - "POST /postEpiClassifyText/ HTTP/1.1" 200 OK
INFO:     47.219.10.126:54473 - "POST /postEpiClassifyText/ HTTP/1.1" 200 OK
INFO:     47.219.10.126:54475 - "POST /postEpiClassifyText/ HTTP/1.1" 200 OK
INFO:     47.219.10.126:54477 - "POST /postEpiClassifyText/ HTTP/1.1" 200 OK
INFO:     47.219.10.126:54479 - "POST /postEpiClassifyText/ HTTP/1.1" 200 OK
INFO:     47.219.10.126:54481 - "POST /postEpiClassifyText/ HTTP/1.1" 200 OK
INFO:     47.219.10.126:54483 - "POST /postEpiClassifyText/ HTTP/1.1" 200 OK
INFO:     47.219.10.126:54485 - "POST /postEpiClassifyText/ HTTP/1.1" 200 OK
INFO:     47.219.10.126:54492 - "POST /postEpiClassifyText/ HTTP/1.1" 200 OK
INFO:     47.219.10.126:54494 - "POST /postEpiClassifyText/ HTTP/1.1" 200 OK
INFO:     47.219.10.126:54496 - "POST /postEpiClassifyText/ HTTP/1.1" 200 OK
INFO:     47.219.10.126:54498 - "POST /postEpiClassifyText/ HTTP/1.1" 200 OK
INFO:     47.219.10.126:54500 - "POST /postEpiClassifyText/ HTTP/1.1" 200 OK
INFO:     47.219.10.126:54502 - "POST /postEpiClassifyText/ HTTP/1.1" 200 OK
INFO:     47.219.10.126:54504 - "POST /postEpiClassifyText/ HTTP/1.1" 200 OK
INFO:     47.219.10.126:54506 - "POST /postEpiClassifyText/ HTTP/1.1" 200 OK
INFO:     47.219.10.126:54508 - "POST /postEpiClassifyText/ HTTP/1.1" 200 OK
INFO:     47.219.10.126:54510 - "POST /postEpiClassifyText/ HTTP/1.1" 200 OK
INFO:     47.219.10.126:54514 - "POST /postEpiClassifyText/ HTTP/1.1" 200 OK
INFO:     47.219.10.126:54516 - "POST /postEpiClassifyText/ HTTP/1.1" 200 OK
INFO:     47.219.10.126:54518 - "POST /postEpiClassifyText/ HTTP/1.1" 200 OK
INFO:     47.219.10.126:54525 - "POST /postEpiClassifyText/ HTTP/1.1" 200 OK
INFO:     47.219.10.126:54527 - "POST /postEpiClassifyText/ HTTP/1.1" 200 OK
INFO:     47.219.10.126:54529 - "POST /postEpiClassifyText/ HTTP/1.1" 200 OK
INFO:     47.219.10.126:54531 - "POST /postEpiClassifyText/ HTTP/1.1" 200 OK
INFO:     47.219.10.126:54533 - "POST /postEpiClassifyText/ HTTP/1.1" 200 OK
INFO:     47.219.10.126:54537 - "POST /postEpiClassifyText/ HTTP/1.1" 200 OK
INFO:     47.219.10.126:54539 - "POST /postEpiClassifyText/ HTTP/1.1" 200 OK
INFO:     47.219.10.126:54541 - "POST /postEpiClassifyText/ HTTP/1.1" 200 OK
INFO:     47.219.10.126:54543 - "POST /postEpiClassifyText/ HTTP/1.1" 200 OK
INFO:     47.219.10.126:54546 - "POST /postEpiClassifyText/ HTTP/1.1" 200 OK
INFO:     47.219.10.126:54549 - "POST /postEpiClassifyText/ HTTP/1.1" 200 OK
INFO:     47.219.10.126:54551 - "POST /postEpiClassifyText/ HTTP/1.1" 200 OK
INFO:     47.219.10.126:54553 - "POST /postEpiClassifyText/ HTTP/1.1" 200 OK
INFO:     47.219.10.126:54560 - "POST /postEpiClassifyText/ HTTP/1.1" 200 OK
INFO:     47.219.10.126:54562 - "POST /postEpiClassifyText/ HTTP/1.1" 200 OK
INFO:     47.219.10.126:54564 - "POST /postEpiClassifyText/ HTTP/1.1" 200 OK
INFO:     47.219.10.126:54566 - "POST /postEpiClassifyText/ HTTP/1.1" 200 OK
INFO:     47.219.10.126:54568 - "POST /postEpiClassifyText/ HTTP/1.1" 200 OK
INFO:     47.219.10.126:54570 - "POST /postEpiClassifyText/ HTTP/1.1" 200 OK
INFO:     47.219.10.126:54572 - "POST /postEpiClassifyText/ HTTP/1.1" 200 OK
INFO:     47.219.10.126:54574 - "POST /postEpiClassifyText/ HTTP/1.1" 200 OK
INFO:     47.219.10.126:54576 - "POST /postEpiClassifyText/ HTTP/1.1" 200 OK
INFO:     47.219.10.126:54578 - "POST /postEpiClassifyText/ HTTP/1.1" 200 OK
INFO:     47.219.10.126:54580 - "POST /postEpiClassifyText/ HTTP/1.1" 200 OK
INFO:     47.219.10.126:54582 - "POST /postEpiClassifyText/ HTTP/1.1" 200 OK
INFO:     47.219.10.126:54585 - "POST /postEpiClassifyText/ HTTP/1.1" 200 OK
INFO:     47.219.10.126:54587 - "POST /postEpiClassifyText/ HTTP/1.1" 200 OK
INFO:     47.219.10.126:54589 - "POST /postEpiClassifyText/ HTTP/1.1" 200 OK
INFO:     47.219.10.126:54596 - "POST /postEpiClassifyText/ HTTP/1.1" 200 OK
INFO:     47.219.10.126:54598 - "POST /postEpiClassifyText/ HTTP/1.1" 200 OK
INFO:     47.219.10.126:54600 - "POST /postEpiClassifyText/ HTTP/1.1" 200 OK
INFO:     47.219.10.126:54602 - "POST /postEpiClassifyText/ HTTP/1.1" 200 OK
2022-06-14 22:56:06.385 WARNING tensorflow: SavedModel saved prior to TF 2.5 detected when loading Keras model. Please ensure that you are saving the model with model.save() or tf.keras.models.save_model(), *NOT* tf.saved_model.save(). To confirm, there should be a file named "keras_metadata.pb" in the SavedModel directory.
INFO:     47.219.10.126:54606 - "POST /postEpiClassifyText/ HTTP/1.1" 200 OK
INFO:     47.219.10.126:54608 - "POST /postEpiClassifyText/ HTTP/1.1" 200 OK
INFO:     47.219.10.126:54611 - "POST /postEpiClassifyText/ HTTP/1.1" 200 OK
INFO:     47.219.10.126:54613 - "POST /postEpiClassifyText/ HTTP/1.1" 200 OK
INFO:     Started server process [32733]
2022-06-14 22:56:20.093 INFO    uvicorn.error: Started server process [32733]
INFO:     Waiting for application startup.
2022-06-14 22:56:20.094 INFO    uvicorn.error: Waiting for application startup.
INFO:     Application startup complete.
2022-06-14 22:56:20.094 INFO    uvicorn.error: Application startup complete.
ERROR:    [Errno 98] error while attempting to bind on address ('10.9.1.108', 8000): address already in use
2022-06-14 22:56:20.094 ERROR   uvicorn.error: [Errno 98] error while attempting to bind on address ('10.9.1.108', 8000): address already in use
INFO:     Waiting for application shutdown.
2022-06-14 22:56:20.094 INFO    uvicorn.error: Waiting for application shutdown.
INFO:     Application shutdown complete.
2022-06-14 22:56:20.095 INFO    uvicorn.error: Application shutdown complete.
INFO:     47.219.10.126:54617 - "POST /postEpiClassifyText/ HTTP/1.1" 200 OK
INFO:     47.219.10.126:54621 - "POST /postEpiClassifyText/ HTTP/1.1" 200 OK
INFO:     47.219.10.126:54625 - "POST /postEpiClassifyText/ HTTP/1.1" 200 OK
INFO:     47.219.10.126:54627 - "POST /postEpiClassifyText/ HTTP/1.1" 200 OK
INFO:     47.219.10.126:54634 - "POST /postEpiClassifyText/ HTTP/1.1" 200 OK
INFO:     47.219.10.126:54636 - "POST /postEpiClassifyText/ HTTP/1.1" 200 OK
INFO:     47.219.10.126:54638 - "POST /postEpiClassifyText/ HTTP/1.1" 200 OK
INFO:     47.219.10.126:54641 - "POST /postEpiClassifyText/ HTTP/1.1" 200 OK
INFO:     47.219.10.126:54643 - "POST /postEpiClassifyText/ HTTP/1.1" 200 OK
INFO:     47.219.10.126:54645 - "POST /postEpiClassifyText/ HTTP/1.1" 200 OK
INFO:     47.219.10.126:54649 - "POST /postEpiClassifyText/ HTTP/1.1" 200 OK
INFO:     47.219.10.126:54651 - "POST /postEpiClassifyText/ HTTP/1.1" 200 OK
INFO:     47.219.10.126:54653 - "POST /postEpiClassifyText/ HTTP/1.1" 200 OK
INFO:     47.219.10.126:54655 - "POST /postEpiClassifyText/ HTTP/1.1" 200 OK
INFO:     47.219.10.126:54657 - "POST /postEpiClassifyText/ HTTP/1.1" 200 OK
INFO:     47.219.10.126:54661 - "POST /postEpiClassifyText/ HTTP/1.1" 200 OK
INFO:     47.219.10.126:54665 - "POST /postEpiClassifyText/ HTTP/1.1" 200 OK
INFO:     47.219.10.126:54668 - "POST /postEpiClassifyText/ HTTP/1.1" 200 OK
INFO:     47.219.10.126:54678 - "POST /postEpiClassifyText/ HTTP/1.1" 200 OK
INFO:     47.219.10.126:54680 - "POST /postEpiClassifyText/ HTTP/1.1" 200 OK
INFO:     47.219.10.126:54682 - "POST /postEpiClassifyText/ HTTP/1.1" 200 OK
INFO:     47.219.10.126:54687 - "POST /postEpiClassifyText/ HTTP/1.1" 200 OK
INFO:     47.219.10.126:54689 - "POST /postEpiClassifyText/ HTTP/1.1" 200 OK
INFO:     47.219.10.126:54691 - "POST /postEpiClassifyText/ HTTP/1.1" 200 OK
INFO:     47.219.10.126:54693 - "POST /postEpiClassifyText/ HTTP/1.1" 200 OK
INFO:     47.219.10.126:54695 - "POST /postEpiClassifyText/ HTTP/1.1" 200 OK
INFO:     47.219.10.126:54699 - "POST /postEpiClassifyText/ HTTP/1.1" 200 OK
INFO:     47.219.10.126:54701 - "POST /postEpiClassifyText/ HTTP/1.1" 200 OK
INFO:     47.219.10.126:54703 - "POST /postEpiClassifyText/ HTTP/1.1" 200 OK
INFO:     47.219.10.126:54708 - "POST /postEpiClassifyText/ HTTP/1.1" 200 OK
INFO:     47.219.10.126:54711 - "POST /postEpiClassifyText/ HTTP/1.1" 200 OK
INFO:     47.219.10.126:54714 - "POST /postEpiClassifyText/ HTTP/1.1" 200 OK
INFO:     47.219.10.126:54716 - "POST /postEpiClassifyText/ HTTP/1.1" 200 OK
INFO:     47.219.10.126:54718 - "POST /postEpiClassifyText/ HTTP/1.1" 200 OK
INFO:     47.219.10.126:54720 - "POST /postEpiClassifyText/ HTTP/1.1" 200 OK
INFO:     47.219.10.126:54724 - "POST /postEpiClassifyText/ HTTP/1.1" 200 OK
INFO:     47.219.10.126:54726 - "POST /postEpiClassifyText/ HTTP/1.1" 200 OK
INFO:     47.219.10.126:54728 - "POST /postEpiClassifyText/ HTTP/1.1" 200 OK
INFO:     47.219.10.126:54731 - "POST /postEpiClassifyText/ HTTP/1.1" 200 OK
INFO:     47.219.10.126:54735 - "POST /postEpiClassifyText/ HTTP/1.1" 200 OK
INFO:     47.219.10.126:54737 - "POST /postEpiClassifyText/ HTTP/1.1" 200 OK
INFO:     47.219.10.126:54739 - "POST /postEpiClassifyText/ HTTP/1.1" 200 OK
INFO:     47.219.10.126:54744 - "POST /postEpiClassifyText/ HTTP/1.1" 200 OK
INFO:     47.219.10.126:54748 - "POST /postEpiClassifyText/ HTTP/1.1" 200 OK
INFO:     47.219.10.126:54752 - "POST /postEpiClassifyText/ HTTP/1.1" 200 OK
INFO:     47.219.10.126:54754 - "POST /postEpiClassifyText/ HTTP/1.1" 200 OK
INFO:     47.219.10.126:54756 - "POST /postEpiClassifyText/ HTTP/1.1" 200 OK
INFO:     47.219.10.126:54760 - "POST /postEpiClassifyText/ HTTP/1.1" 200 OK
INFO:     47.219.10.126:54762 - "POST /postEpiClassifyText/ HTTP/1.1" 200 OK
INFO:     47.219.10.126:54764 - "POST /postEpiClassifyText/ HTTP/1.1" 200 OK
INFO:     47.219.10.126:54767 - "POST /postEpiClassifyText/ HTTP/1.1" 200 OK
INFO:     47.219.10.126:54770 - "POST /postEpiClassifyText/ HTTP/1.1" 200 OK
INFO:     47.219.10.126:54772 - "POST /postEpiClassifyText/ HTTP/1.1" 200 OK
INFO:     47.219.10.126:54777 - "POST /postEpiClassifyText/ HTTP/1.1" 200 OK
